Workbook

Sheet README
A1: Six South — Chemicals, petrochemicals & fertilisers industry model
A2: Generated 2026-10-29T18:55:56+07:00 by the coverage engine. The engine (scripts/cov_engine.py) is the source of truth; this workbook is a live rendering of it.
A3: Colour key: blue = input or hard-coded history; black = formula; green = link to another sheet.
A4: Drivers: every deck variable these models read. Change one and every ticker tab and the Comps sheet recalculate (forecasts, cash flows, DCF value, base-case value, target, rating).
A5: Scenario (bear/bull) and sensitivity tables need full model re-runs and are engine values.
A6: Paper fund — research for education and process transparency, not investment advice.
A8: Tickers:
A9: TPIA.JK — PT Chandra Asri Pacific Tbk

Sheet Drivers
A1: Driver decks (state/drivers) — edit a blue cell to flow it through every ticker tab
A3: Variable | B3: Key | C3: Unit / status | D3: FY2022A | E3: FY2023A | F3: FY2024A | G3: FY2025A | H3: FY2026E | I3: FY2027E | J3: FY2028E | K3: FY2029E | L3: FY2030E | M3: FY2031E | N3: FY2032E | O3: FY2033E | P3: FY2034E | Q3: FY2035E
A4: IDR per USD | B4: m.usd_idr | C4: IDR/USD · reviewed | D4: 14843.177 | E4: 15228.8 | F4: 15846.238 | G4: 16448.093 | H4: 17570 | I4: 18350 | J4: 18600 | K4: 18850 | L4: 19093.137 | M4: 19186.731 | N4: 19280.784 | O4: 19375.297 | P4: 19470.274 | Q4: 19565.717
A5: Brent crude | B5: d.oil.brent | C5: USD/bbl · reviewed | D5: 98.9663 | E5: 82.1904 | F5: 79.8213 | G5: 68.1015 | H5: 96 | I5: 84 | J5: 80 | K5: 78 | L5: 76.5 | M5: 78.03 | N5: 79.5906 | O5: 81.182412 | P5: 82.80606 | Q5: 84.462181
A7: Cost-of-capital scalars (macro deck)
A8: 10-year Indonesian government bond yield (IDR) | B8: m.rf_idr | C8: 0.0745 | D8: investor.id — "Yield SUN 7,45%, Saatnya Borong atau Tunggu Lebih Tinggi?" (25 Okt 2026 20:58 WIB; deck source S3); corroborated by kalderanews S1 (10Y SUN 7.41%
A9: 10-year US Treasury yield | B9: m.rf_usd | C9: 0.05045 | D9: Yahoo Finance ^TNX (US 10-year Treasury yield)
A10: Indonesia sovereign default spread (Damodaran) | B10: m.default_spread_id | C10: 0.0162 | D10: Damodaran country risk premiums (https://pages.stern.nyu.edu/~adamodar/New_Home_Page/datafile/ctryprem.html), page dated January 5, 2026, read 2026-10-29
A11: Mature-market equity risk premium (Damodaran) | B11: m.erp_mature | C11: 0.0423 | D11: Damodaran country risk premiums (https://pages.stern.nyu.edu/~adamodar/New_Home_Page/datafile/ctryprem.html), page dated January 5, 2026, read 2026-10-29
A12: Indonesia country risk premium (Damodaran) | B12: m.crp_id | C12: 0.0246 | D12: Damodaran country risk premiums (https://pages.stern.nyu.edu/~adamodar/New_Home_Page/datafile/ctryprem.html), page dated January 5, 2026, read 2026-10-29
A13: House pre-tax corporate debt spread over the risk-free | B13: m.debt_spread_corp | C13: 0.02 | D13: SEED house assumption pending the macro desk: 200 bp over the risk-free rate for an average IDX corporate borrower
A14: Indonesia statutory corporate income tax rate | B14: m.tax_rate_id | C14: 0.22 | D14: Law 7/2021 on Harmonisation of Tax Regulations (UU HPP): 22% corporate income tax from fiscal 2022

Sheet Comps
A1: Ticker | B1: Company | C1: Rating | D1: Target (IDR) | E1: Price (IDR) | F1: Exp. 12m TR | G1: Value today | H1: P/E FY+0 | I1: EV/EBITDA FY+0 | J1: Div. yield FY+0
A2: TPIA.JK | B2: PT Chandra Asri Pacific Tbk | C2: ='TPIA'!$C$136 | D2: ='TPIA'!$C$134 | E2: ='TPIA'!$C$77 | F2: ='TPIA'!$C$135 | G2: ='TPIA'!$C$115 | H2: 15.366066 | I2: 8.673428 | J2: 0.006508

Sheet TPIA
A1: PT Chandra Asri Pacific Tbk (TPIA.JK) — Chemicals, petrochemicals & fertilisers
A2: Units: USD m; per-share in USD unless marked IDR. Model asof 2026-10-29 · data 2026-10-27
A4: Line | C4: Scalar | D4: FY2022A | E4: FY2023A | F4: FY2024A | G4: FY2025A | H4: FY2026E | I4: FY2027E | J4: FY2028E | K4: FY2029E | L4: FY2030E | M4: FY2031E | N4: FY2032E | O4: FY2033E | P4: FY2034E | Q4: FY2035E
A6: PARAMETERS
A7: ps_factor | C7: 1
A8: vp_factor | C8: 1
A10: INPUTS (company assumptions)
A11: Revenue growth | B11: a.revenue_growth | H11: 0.52 | I11: 0.03 | J11: 0.03 | K11: 0.03 | L11: 0.03 | M11: 0.03 | N11: 0.03 | O11: 0.03 | P11: 0.03 | Q11: 0.03
A12: Gross margin at base input costs | B12: a.gross_margin | H12: 0.191 | I12: 0.191 | J12: 0.191 | K12: 0.191 | L12: 0.191 | M12: 0.191 | N12: 0.191 | O12: 0.191 | P12: 0.191 | Q12: 0.191
A13: Cost link 1: share of COGS exposed | B13: a.link1_share | C13: 0.6
A14: Cost link 1: pass-through to prices | B14: a.link1_pass | C14: 0.8
A15: SG&A / revenue | B15: a.opex_pct | H15: 0.062 | I15: 0.062 | J15: 0.062 | K15: 0.062 | L15: 0.062 | M15: 0.062 | N15: 0.062 | O15: 0.062 | P15: 0.062 | Q15: 0.062
A16: D&A / revenue | B16: a.da_pct | H16: 0.0307 | I16: 0.0307 | J16: 0.0307 | K16: 0.0307 | L16: 0.0307 | M16: 0.0307 | N16: 0.0307 | O16: 0.0307 | P16: 0.0307 | Q16: 0.0307
A17: Capex / revenue | B17: a.capex_pct | H17: 0.055 | I17: 0.055 | J17: 0.045 | K17: 0.04 | L17: 0.04 | M17: 0.04 | N17: 0.04 | O17: 0.04 | P17: 0.04 | Q17: 0.04
A18: Operating working capital / revenue | B18: a.nwc_pct | H18: 0.1 | I18: 0.09 | J18: 0.09 | K18: 0.09 | L18: 0.09 | M18: 0.09 | N18: 0.09 | O18: 0.09 | P18: 0.09 | Q18: 0.09
A19: Effective tax rate | B19: a.tax_rate | H19: 0.145 | I19: 0.16 | J19: 0.18 | K19: 0.2 | L19: 0.2 | M19: 0.2 | N19: 0.2 | O19: 0.2 | P19: 0.2 | Q19: 0.2
A20: Cost of debt (on opening debt) | B20: a.cost_of_debt | C20: 0.064
A21: Yield on opening cash | B21: a.cash_yield | C21: 0.042
A22: Net new borrowing | B22: a.net_borrowing | H22: 496.707 | I22: 0 | J22: 0 | K22: 0 | L22: 0 | M22: 0 | N22: 0 | O22: 0 | P22: 0 | Q22: 0
A23: Other non-operating items | B23: a.other_nonop | H23: 0 | I23: 0 | J23: 0 | K23: 0 | L23: 0 | M23: 0 | N23: 0 | O23: 0 | P23: 0 | Q23: 0
A24: Minorities' share of net profit | B24: a.minority_pct | H24: 0.24 | I24: 0.24 | J24: 0.24 | K24: 0.24 | L24: 0.24 | M24: 0.24 | N24: 0.24 | O24: 0.24 | P24: 0.24 | Q24: 0.24
A25: Dividend payout | B25: a.payout | H25: 0.1 | I25: 0.1 | J25: 0.1 | K25: 0.1 | L25: 0.1 | M25: 0.1 | N25: 0.1 | O25: 0.1 | P25: 0.1 | Q25: 0.1
A26: Change in share count | B26: a.share_change | H26: 0 | I26: 0 | J26: 0 | K26: 0 | L26: 0 | M26: 0 | N26: 0 | O26: 0 | P26: 0 | Q26: 0
A27: Terminal growth (DCF) | B27: a.terminal_growth | C27: 0.025
A29: MODEL
A30: Revenue | B30: revenue | D30: 2384.591 | E30: 2159.932 | F30: 1785.364 | G30: 7000 | H30: =(G30*(1+H11)) | I30: =(H30*(1+I11)) | J30: =(I30*(1+J11)) | K30: =(J30*(1+K11)) | L30: =(K30*(1+L11)) | M30: =(L30*(1+M11)) | N30: =(M30*(1+N11)) | O30: =(N30*(1+O11)) | ... Q30: =(P30*(1+Q11))
A31: Cost of revenue | B31: cogs | D31: 2395.545 | E31: 2078.102 | F31: 1628.199 | G31: 7062.478 | H31: =((H30*(1-H12))*(1+(($C$13*(1-$C$14))*(IF(Drivers!$G$5=0,0,Drivers!$H$5/Drivers!$G$5)-1)))) | I31: =((I30*(1-I12))*(1+(($C$13*(1-$C$14))*(IF(Drivers!$G$5=0,0,Drivers!$I$5/Drivers!$G$5)-1)))) | J31: =((J30*(1-J12))*(1+(($C$13*(1-$C$14))*(IF(Drivers!$G$5=0,0,Drivers!$J$5/Drivers!$G$5)-1)))) | K31: =((K30*(1-K12))*(1+(($C$13*(1-$C$14))*(IF(Drivers!$G$5=0,0,Drivers!$K$5/Drivers!$G$5)-1)))) | L31: =((L30*(1-L12))*(1+(($C$13*(1-$C$14))*(IF(Drivers!$G$5=0,0,Drivers!$L$5/Drivers!$G$5)-1)))) | M31: =((M30*(1-M12))*(1+(($C$13*(1-$C$14))*(IF(Drivers!$G$5=0,0,Drivers!$M$5/Drivers!$G$5)-1)))) | N31: =((N30*(1-N12))*(1+(($C$13*(1-$C$14))*(IF(Drivers!$G$5=0,0,Drivers!$N$5/Drivers!$G$5)-1)))) | O31: =((O30*(1-O12))*(1+(($C$13*(1-$C$14))*(IF(Drivers!$G$5=0,0,Drivers!$O$5/Drivers!$G$5)-1)))) | P31: =((P30*(1-P12))*(1+(($C$13*(1-$C$14))*(IF(Drivers!$G$5=0,0,Drivers!$P$5/Drivers!$G$5)-1)))) | Q31: =((Q30*(1-Q12))*(1+(($C$13*(1-$C$14))*(IF(Drivers!$G$5=0,0,Drivers!$Q$5/Drivers!$G$5)-1))))
A32: Gross profit | B32: gross_profit | D32: -10.954 | E32: 81.83 | F32: 157.165 | G32: -42.471 | H32: =(H30-H31) | I32: =(I30-I31) | J32: =(J30-J31) | K32: =(K30-K31) | L32: =(L30-L31) | M32: =(M30-M31) | N32: =(N30-N31) | O32: =(O30-O31) | ... Q32: =(Q30-Q31)
A33: SG&A and other opex | B33: opex | D33: 105.266 | E33: 109.705 | F33: 213.897 | G33: 550.227 | H33: =(H30*H15) | I33: =(I30*I15) | J33: =(J30*J15) | K33: =(K30*K15) | L33: =(L30*L15) | M33: =(M30*M15) | N33: =(N30*N15) | O33: =(O30*O15) | ... Q33: =(Q30*Q15)
A34: EBIT | B34: ebit | D34: -116.22 | E34: -27.875 | F34: -56.732 | G34: -592.698 | H34: =(H32-H33) | I34: =(I32-I33) | J34: =(J32-J33) | K34: =(K32-K33) | L34: =(L32-L33) | M34: =(M32-M33) | N34: =(N32-N33) | O34: =(O32-O33) | ... Q34: =(Q32-Q33)
A35: Depreciation & amortisation | B35: da | D35: 2.224 | E35: 2.888 | F35: 114.976 | G35: 203.474 | H35: =(H30*H16) | I35: =(I30*I16) | J35: =(J30*J16) | K35: =(K30*K16) | L35: =(L30*L16) | M35: =(M30*M16) | N35: =(N30*N16) | O35: =(O30*O16) | ... Q35: =(Q30*Q16)
A36: EBITDA | B36: ebitda | D36: -113.996 | E36: -24.987 | F36: 58.244 | G36: -389.224 | H36: =(H34+H35) | I36: =(I34+I35) | J36: =(J34+J35) | K36: =(K34+K35) | L36: =(L34+L35) | M36: =(M34+M35) | N36: =(N34+N35) | O36: =(O34+O35) | ... Q36: =(Q34+Q35)
A37: Interest expense | B37: interest_expense | D37: 70.612 | E37: 115.633 | F37: 135.836 | G37: 238.4 | H37: =(G57*$C$20) | I37: =(H57*$C$20) | J37: =(I57*$C$20) | K37: =(J57*$C$20) | L37: =(K57*$C$20) | M37: =(L57*$C$20) | N37: =(M57*$C$20) | O37: =(N57*$C$20) | ... Q37: =(P57*$C$20)
A38: Interest income | B38: interest_income | E38: 75.508 | F38: 94.974 | G38: 122.376 | H38: =(G56*$C$21) | I38: =(H56*$C$21) | J38: =(I56*$C$21) | K38: =(J56*$C$21) | L38: =(K56*$C$21) | M38: =(L56*$C$21) | N38: =(M56*$C$21) | O38: =(N56*$C$21) | ... Q38: =(P56*$C$21)
A39: Other non-operating | B39: other_nonop | E39: 13.436 | F39: 6.655 | G39: 2002.931 | H39: =H23 | I39: =I23 | J39: =J23 | K39: =K23 | L39: =L23 | M39: =M23 | N39: =N23 | O39: =O23 | ... Q39: =Q23
A40: Profit before tax | B40: pbt | D40: -176.475 | E40: -54.564 | F40: -90.939 | G40: 1294.209 | H40: =(((H34-H37)+H38)+H39) | I40: =(((I34-I37)+I38)+I39) | J40: =(((J34-J37)+J38)+J39) | K40: =(((K34-K37)+K38)+K39) | L40: =(((L34-L37)+L38)+L39) | M40: =(((M34-M37)+M38)+M39) | N40: =(((N34-N37)+N38)+N39) | O40: =(((O34-O37)+O38)+O39) | ... Q40: =(((Q34-Q37)+Q38)+Q39)
A41: Tax | B41: tax | D41: -27.076 | E41: -23.017 | F41: -34.429 | G41: -153.777 | H41: =(MAX(H40,0)*H19) | I41: =(MAX(I40,0)*I19) | J41: =(MAX(J40,0)*J19) | K41: =(MAX(K40,0)*K19) | L41: =(MAX(L40,0)*L19) | M41: =(MAX(M40,0)*M19) | N41: =(MAX(N40,0)*N19) | O41: =(MAX(O40,0)*O19) | ... Q41: =(MAX(Q40,0)*Q19)
A42: Net profit (incl. minorities) | B42: np | D42: -149.399 | E42: -31.547 | F42: -56.51 | G42: 1447.986 | H42: =(H40-H41) | I42: =(I40-I41) | J42: =(J40-J41) | K42: =(K40-K41) | L42: =(L40-L41) | M42: =(M40-M41) | N42: =(N40-N41) | O42: =(O40-O41) | ... Q42: =(Q40-Q41)
A43: Minority interests | B43: minority | D43: 0.139 | E43: 2.029 | F43: 12.1 | G43: 357.895 | H43: =(H42*H24) | I43: =(I42*I24) | J43: =(J42*J24) | K43: =(K42*K24) | L43: =(L42*L24) | M43: =(M42*M24) | N43: =(N42*N24) | O43: =(O42*O24) | ... Q43: =(Q42*Q24)
A44: Net profit to parent | B44: np_parent | D44: -149.538 | E44: -33.576 | F44: -68.61 | G44: 1090.091 | H44: =(H42-H43) | I44: =(I42-I43) | J44: =(J42-J43) | K44: =(K42-K43) | L44: =(L42-L43) | M44: =(M42-M43) | N44: =(N42-N43) | O44: =(O42-O43) | ... Q44: =(Q42-Q43)
...
