Workbook

Sheet README
A1: Six South — Coal producers industry model
A2: Generated 2026-10-30T23:33:13+07:00 by the coverage engine. The engine (scripts/cov_engine.py) is the source of truth; this workbook is a live rendering of it.
A3: Colour key: blue = input or hard-coded history; black = formula; green = link to another sheet.
A4: Drivers: every deck variable these models read. Change one and every ticker tab and the Comps sheet recalculate (forecasts, cash flows, DCF value, base-case value, target, rating).
A5: Scenario (bear/bull) and sensitivity tables need full model re-runs and are engine values.
A6: Paper fund — research for education and process transparency, not investment advice.
A8: Tickers:
A9: AADI.JK — PT Adaro Andalan Indonesia Tbk
A10: ADMR.JK — PT Alamtri Minerals Indonesia Tbk
A11: ARII.JK — PT Atlas Resources Tbk
A12: BOSS.JK — PT. Borneo Olah Sarana Sukses Tbk
A13: BSSR.JK — PT Baramulti Suksessarana Tbk
... A26: SMMT.JK — PT Golden Eagle Energy Tbk

Sheet Drivers
A1: Driver decks (state/drivers) — edit a blue cell to flow it through every ticker tab
A3: Variable | B3: Key | C3: Unit / status | D3: FY2021A | E3: FY2022A | F3: FY2023A | G3: FY2023E | H3: FY2024A | I3: FY2024E | J3: FY2025A | K3: FY2025E | L3: FY2026E | M3: FY2027E | N3: FY2028E | O3: FY2029E | P3: FY2030E | Q3: FY2031E | R3: FY2032E | S3: FY2033E | T3: FY2034E | U3: FY2035E | V3: FY2036E | W3: FY2037E | X3: FY2038E | Y3: FY2039E | Z3: FY2040E | AA3: FY2041E | AB3: FY2042E | AC3: FY2043E | AD3: FY2044E | AE3: FY2045E | AF3: FY2046E | AG3: FY2047E | AH3: FY2048E | AI3: FY2049E | AJ3: FY2050E | AK3: FY2051E | AL3: FY2052E | AM3: FY2053E | AN3: FY2054E | AO3: FY2055E | AP3: FY2056E | AQ3: FY2057E | AR3: FY2058E | AS3: FY2059E | AT3: FY2060E | AU3: FY2061E | AV3: FY2062E | AW3: FY2063E | AX3: FY2064E | AY3: FY2065E | AZ3: FY2066E | BA3: FY2067E | BB3: FY2068E | BC3: FY2069E | BD3: FY2070E | BE3: FY2071E | BF3: FY2072E | BG3: FY2073E | BH3: FY2074E | BI3: FY2075E | BJ3: FY2076E | BK3: FY2077E | BL3: FY2078E | BM3: FY2079E | BN3: FY2080E | BO3: FY2081E | BP3: FY2082E | BQ3: FY2083E | BR3: FY2084E | BS3: FY2085E | BT3: FY2086E | BU3: FY2087E | BV3: FY2088E | BW3: FY2089E | BX3: FY2090E | BY3: FY2091E | BZ3: FY2092E | CA3: FY2093E | CB3: FY2094E | CC3: FY2095E
A4: DMO price cap for coal sold to power plants | B4: d.coal.dmo_cap | C4: USD/t · reviewed | G4: 70 | I4: 70 | K4: 70 | L4: 70 | M4: 70 | N4: 70 | O4: 70 | P4: 70 | Q4: 70 | R4: 70 | S4: 70 | T4: 70 | U4: 70 | V4: 70 | W4: 70 | X4: 70 | Y4: 70 | Z4: 70 | AA4: 70 | AB4: 70 | AC4: 70 | AD4: 70 | AE4: 70 | AF4: 70 | AG4: 70 | AH4: 70 | AI4: 70 | AJ4: 70 | AK4: 70 | AL4: 70 | AM4: 70 | AN4: 70 | AO4: 70 | AP4: 70 | AQ4: 70 | AR4: 70 | AS4: 70 | AT4: 70 | AU4: 70 | AV4: 70 | AW4: 70 | AX4: 70 | AY4: 70 | AZ4: 70 | BA4: 70 | BB4: 70 | BC4: 70 | BD4: 70 | BE4: 70 | BF4: 70 | BG4: 70 | BH4: 70 | BI4: 70 | BJ4: 70 | BK4: 70 | BL4: 70 | BM4: 70 | BN4: 70 | BO4: 70 | BP4: 70 | BQ4: 70 | BR4: 70 | BS4: 70 | BT4: 70 | BU4: 70 | BV4: 70 | BW4: 70 | BX4: 70 | BY4: 70 | BZ4: 70 | CA4: 70 | CB4: 70 | CC4: 70
A5: Harga Batubara Acuan (government reference price) | B5: d.coal.hba | C5: USD/t · reviewed | G5: 105 | I5: 105 | K5: 105 | L5: 118 | M5: 112 | N5: 108 | O5: 105 | P5: 107.1 | Q5: 109.242 | R5: 111.42684 | S5: 113.65538 | T5: 115.92848 | U5: 118.24705 | V5: 120.612 | W5: 123.02424 | X5: 125.48472 | Y5: 127.99441 | Z5: 130.5543 | AA5: 133.16539 | AB5: 135.8287 | AC5: 138.54527 | AD5: 141.31618 | AE5: 144.1425 | AF5: 147.02535 | AG5: 149.96586 | AH5: 152.96517 | AI5: 156.02448 | AJ5: 159.14497 | AK5: 162.32787 | AL5: 165.57442 | AM5: 168.88591 | AN5: 172.26363 | AO5: 175.7089 | AP5: 179.22308 | AQ5: 182.80754 | AR5: 186.46369 | AS5: 190.19297 | AT5: 193.99683 | AU5: 197.87676 | AV5: 201.8343 | AW5: 205.87098 | AX5: 209.9884 | AY5: 214.18817 | AZ5: 218.47193 | BA5: 222.84137 | BB5: 227.2982 | BC5: 231.84416 | BD5: 236.48105 | BE5: 241.21067 | BF5: 246.03488 | BG5: 250.95558 | BH5: 255.97469 | BI5: 261.09419 | BJ5: 266.31607 | BK5: 271.64239 | BL5: 277.07524 | BM5: 282.61674 | BN5: 288.26908 | BO5: 294.03446 | BP5: 299.91515 | BQ5: 305.91345 | BR5: 312.03172 | BS5: 318.27236 | BT5: 324.6378 | BU5: 331.13056 | BV5: 337.75317 | BW5: 344.50823 | BX5: 351.3984 | BY5: 358.42637 | BZ5: 365.59489 | CA5: 372.90679 | CB5: 380.36493 | CC5: 387.97222
A6: Newcastle 6,000 kcal/kg NAR thermal coal | B6: d.coal.newc | C6: USD/t · reviewed | G6: 105 | H6: 136.1 | I6: 105 | J6: 108.4 | K6: 105 | L6: 137 | M6: 118 | N6: 110 | O6: 105 | P6: 107.1 | Q6: 109.242 | R6: 111.42684 | S6: 113.65538 | T6: 115.92848 | U6: 118.24705 | V6: 120.612 | W6: 123.02424 | X6: 125.48472 | Y6: 127.99441 | Z6: 130.5543 | AA6: 133.16539 | AB6: 135.8287 | AC6: 138.54527 | AD6: 141.31618 | AE6: 144.1425 | AF6: 147.02535 | AG6: 149.96586 | AH6: 152.96517 | AI6: 156.02448 | AJ6: 159.14497 | AK6: 162.32787 | AL6: 165.57442 | AM6: 168.88591 | AN6: 172.26363 | AO6: 175.7089 | AP6: 179.22308 | AQ6: 182.80754 | AR6: 186.46369 | AS6: 190.19297 | AT6: 193.99683 | AU6: 197.87676 | AV6: 201.8343 | AW6: 205.87098 | AX6: 209.9884 | AY6: 214.18817 | AZ6: 218.47193 | BA6: 222.84137 | BB6: 227.2982 | BC6: 231.84416 | BD6: 236.48105 | BE6: 241.21067 | BF6: 246.03488 | BG6: 250.95558 | BH6: 255.97469 | BI6: 261.09419 | BJ6: 266.31607 | BK6: 271.64239 | BL6: 277.07524 | BM6: 282.61674 | BN6: 288.26908 | BO6: 294.03446 | BP6: 299.91515 | BQ6: 305.91345 | BR6: 312.03172 | BS6: 318.27236 | BT6: 324.6378 | BU6: 331.13056 | BV6: 337.75317 | BW6: 344.50823 | BX6: 351.3984 | BY6: 358.42637 | BZ6: 365.59489 | CA6: 372.90679 | CB6: 380.36493 | CC6: 387.97222
A7: IDR per USD | B7: m.usd_idr | C7: IDR/USD · reviewed | D7: 14310.54 | E7: 14843.177 | F7: 15228.8 | G7: 19000 | H7: 15846.238 | I7: 19000 | J7: 16448.093 | K7: 19000 | L7: 17570 | M7: 18350 | N7: 18600 | O7: 18850 | P7: 19093.137 | Q7: 19186.731 | R7: 19280.784 | S7: 19375.297 | T7: 19470.274 | U7: 19565.717 | V7: 19661.627 | W7: 19758.008 | X7: 19854.861 | Y7: 19952.188 | Z7: 20049.993 | AA7: 20148.278 | AB7: 20247.044 | AC7: 20346.294 | AD7: 20446.031 | AE7: 20546.256 | AF7: 20646.973 | AG7: 20748.184 | AH7: 20849.891 | AI7: 20952.096 | AJ7: 21054.802 | AK7: 21158.012 | AL7: 21261.728 | AM7: 21365.952 | AN7: 21470.687 | AO7: 21575.936 | AP7: 21681.7 | AQ7: 21787.983 | AR7: 21894.787 | AS7: 22002.114 | AT7: 22109.967 | AU7: 22218.35 | AV7: 22327.263 | AW7: 22436.711 | AX7: 22546.694 | AY7: 22657.217 | AZ7: 22768.282 | BA7: 22879.891 | BB7: 22992.048 | BC7: 23104.754 | BD7: 23218.012 | BE7: 23331.826 | BF7: 23446.198 | BG7: 23561.13 | BH7: 23676.626 | BI7: 23792.688 | BJ7: 23909.319 | BK7: 24026.521 | BL7: 24144.298 | BM7: 24262.653 | BN7: 24381.587 | BO7: 24501.105 | BP7: 24621.208 | BQ7: 24741.901 | BR7: 24863.184 | BS7: 24985.063 | BT7: 25107.539 | BU7: 25230.615 | BV7: 25354.294 | BW7: 25478.58 | BX7: 25603.475 | BY7: 25728.982 | BZ7: 25855.105 | CA7: 25981.845 | CB7: 26109.207 | CC7: 26237.194
A8: Brent crude | B8: d.oil.brent | C8: USD/bbl · reviewed | D8: 70.9538 | E8: 98.9663 | F8: 82.1904 | G8: 75 | H8: 79.8213 | I8: 75 | J8: 68.1015 | K8: 75 | L8: 96 | M8: 84 | N8: 80 | O8: 78 | P8: 76.5 | Q8: 78.03 | R8: 79.5906 | S8: 81.182412 | T8: 82.80606 | U8: 84.462181 | V8: 86.151425 | W8: 87.874454 | X8: 89.631943 | Y8: 91.424581 | Z8: 93.253073 | AA8: 95.118135 | AB8: 97.020497 | AC8: 98.960907 | AD8: 100.94013 | AE8: 102.95893 | AF8: 105.01811 | AG8: 107.11847 | AH8: 109.26084 | AI8: 111.44605 | AJ8: 113.67498 | AK8: 115.94848 | AL8: 118.26744 | AM8: 120.63279 | AN8: 123.04545 | AO8: 125.50636 | AP8: 128.01649 | AQ8: 130.57682 | AR8: 133.18835 | AS8: 135.85212 | AT8: 138.56916 | AU8: 141.34054 | AV8: 144.16736 | AW8: 147.0507 | AX8: 149.99172 | AY8: 152.99155 | AZ8: 156.05138 | BA8: 159.17241 | BB8: 162.35586 | BC8: 165.60297 | BD8: 168.91503 | BE8: 172.29333 | BF8: 175.7392 | BG8: 179.25399 | BH8: 182.83907 | BI8: 186.49585 | BJ8: 190.22576 | BK8: 194.03028 | BL8: 197.91088 | BM8: 201.8691 | BN8: 205.90648 | BO8: 210.02461 | BP8: 214.22511 | BQ8: 218.50961 | BR8: 222.8798 | BS8: 227.3374 | BT8: 231.88414 | BU8: 236.52183 | BV8: 241.25226 | BW8: 246.07731 | BX8: 250.99886 | BY8: 256.01883 | BZ8: 261.13921 | CA8: 266.36199 | CB8: 271.68923 | CC8: 277.12302
A10: Cost-of-capital scalars (macro deck)
A11: 10-year Indonesian government bond yield (IDR) | B11: m.rf_idr | C11: 0.0745 | D11: investor.id — "Yield SUN 7,45%, Saatnya Borong atau Tunggu Lebih Tinggi?" (25 Okt 2026 20:58 WIB; deck source S3); corroborated by kalderanews S1 (10Y SUN 7.41%
A12: 10-year US Treasury yield | B12: m.rf_usd | C12: 0.04989 | D12: Yahoo Finance ^TNX (US 10-year Treasury yield)
A13: Indonesia sovereign default spread (Damodaran) | B13: m.default_spread_id | C13: 0.0162 | D13: Damodaran country risk premiums (https://pages.stern.nyu.edu/~adamodar/New_Home_Page/datafile/ctryprem.html), page dated January 5, 2026, read 2026-10-30
A14: Mature-market equity risk premium (Damodaran) | B14: m.erp_mature | C14: 0.0423 | D14: Damodaran country risk premiums (https://pages.stern.nyu.edu/~adamodar/New_Home_Page/datafile/ctryprem.html), page dated January 5, 2026, read 2026-10-30
A15: Indonesia country risk premium (Damodaran) | B15: m.crp_id | C15: 0.0246 | D15: Damodaran country risk premiums (https://pages.stern.nyu.edu/~adamodar/New_Home_Page/datafile/ctryprem.html), page dated January 5, 2026, read 2026-10-30
A16: House pre-tax corporate debt spread over the risk-free | B16: m.debt_spread_corp | C16: 0.02 | D16: SEED house assumption pending the macro desk: 200 bp over the risk-free rate for an average IDX corporate borrower
A17: Indonesia statutory corporate income tax rate | B17: m.tax_rate_id | C17: 0.22 | D17: Law 7/2021 on Harmonisation of Tax Regulations (UU HPP): 22% corporate income tax from fiscal 2022
A19: Table coal.royalty_iup_high: IUP open-pit coal royalty by HBA band — above 5,200 kcal/kg GAR
B20: 0 | C20: 0.095
B21: 70 | C21: 0.115
B22: 90 | C22: 0.135
A24: Table coal.royalty_iupk: IUPK (ex-PKP2B) coal royalty rate by HBA band
B25: 0 | C25: 0.15
B26: 70 | C26: 0.18
B27: 120 | C27: 0.19
B28: 140 | C28: 0.22
B29: 160 | C29: 0.25
B30: 180 | C30: 0.28

Sheet Comps
A1: Ticker | B1: Company | C1: Rating | D1: Target (IDR) | E1: Price (IDR) | F1: Exp. 12m TR | G1: Value today | H1: P/E FY+0 | I1: EV/EBITDA FY+0 | J1: Div. yield FY+0
A2: AADI.JK | B2: PT Adaro Andalan Indonesia Tbk | C2: ='AADI'!$C$157 | D2: ='AADI'!$C$155 | E2: ='AADI'!$C$102 | F2: ='AADI'!$C$156 | G2: ='AADI'!$C$145 | H2: 3.903612 | I2: 2.2336 | J2: 0.217747
A3: ADMR.JK | B3: PT Alamtri Minerals Indonesia Tbk | C3: ='ADMR'!$C$163 | D3: ='ADMR'!$C$161 | E3: ='ADMR'!$C$102 | F3: ='ADMR'!$C$162 | G3: ='ADMR'!$C$151 | H3: 7.973483 | I3: 6.058408 | J3: 0.043895
A4: ARII.JK | B4: PT Atlas Resources Tbk | C4: ='ARII'!$C$151 | D4: ='ARII'!$C$149 | E4: ='ARII'!$C$102 | F4: ='ARII'!$C$150 | G4: ='ARII'!$C$139 | H4: 5.500113 | I4: 1.41805 | J4: 0
A5: BOSS.JK | B5: PT. Borneo Olah Sarana Sukses Tbk | C5: ='BOSS'!$C$151 | D5: ='BOSS'!$C$149 | E5: ='BOSS'!$C$102 | F5: ='BOSS'!$C$150 | G5: ='BOSS'!$C$139 | J5: 0
A6: BSSR.JK | B6: PT Baramulti Suksessarana Tbk | C6: ='BSSR'!$C$163 | D6: ='BSSR'!$C$161 | E6: ='BSSR'!$C$102 | F6: ='BSSR'!$C$162 | G6: ='BSSR'!$C$151 | H6: 5.839242 | I6: 3.920091 | J6: 0.119879
A7: BUMI.JK | B7: PT Bumi Resources Tbk | C7: ='BUMI'!$C$166 | D7: ='BUMI'!$C$164 | E7: ='BUMI'!$C$102 | F7: ='BUMI'!$C$165 | G7: ='BUMI'!$C$145 | H7: 11.188124 | I7: 3.575106 | J7: 0
A8: BYAN.JK | B8: PT Bayan Resources Tbk. | C8: ='BYAN'!$C$172 | D8: ='BYAN'!$C$170 | E8: ='BYAN'!$C$102 | F8: ='BYAN'!$C$171 | G8: ='BYAN'!$C$151 | H8: 17.228205 | I8: 11.497956 | J8: 0.042372
A9: GEMS.JK | B9: PT Golden Energy Mines Tbk | C9: ='GEMS'!$C$166 | D9: ='GEMS'!$C$164 | E9: ='GEMS'!$C$102 | F9: ='GEMS'!$C$165 | G9: ='GEMS'!$C$145 | H9: 4.149274 | I9: 2.604119 | J9: 0.109176
A10: GTBO.JK | B10: PT Garda Tujuh Buana Tbk | C10: ='GTBO'!$C$151 | D10: ='GTBO'!$C$149 | E10: ='GTBO'!$C$102 | F10: ='GTBO'!$C$150 | G10: ='GTBO'!$C$139 | I10: 7.994147 | J10: 0
A11: IATA.JK | B11: PT MNC Energy Investments Tbk | C11: ='IATA'!$C$157 | D11: ='IATA'!$C$155 | E11: ='IATA'!$C$102 | F11: ='IATA'!$C$156 | G11: ='IATA'!$C$145 | H11: 58.502712 | I11: 20.321764 | J11: 0
A12: INDY.JK | B12: PT. Indika Energy Tbk | C12: ='INDY'!$C$163 | D12: ='INDY'!$C$161 | E12: ='INDY'!$C$102 | F12: ='INDY'!$C$162 | G12: ='INDY'!$C$151 | H12: 5.988004 | I12: 2.649006 | J12: 0.0501
A13: ITMG.JK | B13: PT Indo Tambangraya Megah Tbk | C13: ='ITMG'!$C$163 | D13: ='ITMG'!$C$161 | E13: ='ITMG'!$C$102 | F13: ='ITMG'!$C$162 | G13: ='ITMG'!$C$151 | H13: 5.557101 | I13: 1.715011 | J13: 0.10797
A14: KKGI.JK | B14: PT Resource Alam Indonesia Tbk | C14: ='KKGI'!$C$151 | D14: ='KKGI'!$C$149 | E14: ='KKGI'!$C$102 | F14: ='KKGI'!$C$150 | G14: ='KKGI'!$C$139 | H14: 8.401706 | I14: 1.803794 | J14: 0.040468
A15: MBAP.JK | B15: PT Mitrabara Adiperdana Tbk | C15: ='MBAP'!$C$157 | D15: ='MBAP'!$C$155 | E15: ='MBAP'!$C$102 | F15: ='MBAP'!$C$156 | G15: ='MBAP'!$C$145 | H15: 9.039776 | I15: 1.427961 | J15: 0
A16: MCOL.JK | B16: PT Prima Andalan Mandiri Tbk | C16: ='MCOL'!$C$172 | D16: ='MCOL'!$C$170 | E16: ='MCOL'!$C$102 | F16: ='MCOL'!$C$171 | G16: ='MCOL'!$C$151 | H16: 6.336065 | I16: 2.513936 | J16: 0.089193
A17: PTBA.JK | B17: PT Bukit Asam (Persero) Tbk | C17: ='PTBA'!$C$163 | D17: ='PTBA'!$C$161 | E17: ='PTBA'!$C$102 | F17: ='PTBA'!$C$162 | G17: ='PTBA'!$C$151 | H17: 4.618029 | I17: 2.724873 | J17: 0.129926
A18: SINI.JK | B18: PT Singaraja Putra Tbk | C18: ='SINI'!$C$166 | D18: ='SINI'!$C$164 | E18: ='SINI'!$C$102 | F18: ='SINI'!$C$165 | G18: ='SINI'!$C$145 | I18: 97.625959 | J18: 0
A19: SMMT.JK | B19: PT Golden Eagle Energy Tbk | C19: ='SMMT'!$C$166 | D19: ='SMMT'!$C$164 | E19: ='SMMT'!$C$102 | F19: ='SMMT'!$C$165 | G19: ='SMMT'!$C$145 | H19: 25.343029 | I19: 16.45252 | J19: 0.009865

Sheet AADI
A1: PT Adaro Andalan Indonesia Tbk (AADI.JK) — Coal producers
A2: Units: USD m; per-share in USD unless marked IDR. Model asof 2026-10-30 · data 2026-10-26
A4: Line | C4: Scalar | D4: FY2022A | E4: FY2023A | F4: FY2024A | G4: FY2025A | H4: FY2026E | I4: FY2027E | J4: FY2028E | K4: FY2029E | L4: FY2030E | M4: FY2031E | N4: FY2032E | O4: FY2033E | P4: FY2034E | Q4: FY2035E | R4: FY2036E | S4: FY2037E
A6: PARAMETERS
A7: horizon | C7: 12
A8: ps_factor | C8: 1
A9: reserves | C9: 1000
A10: unit_factor | C10: 1
A11: vp_factor | C11: 1
A13: INPUTS (company assumptions)
A14: Sales volume plan | B14: a.volume | H14: 71.94 | I14: 71.94 | J14: 71.94 | K14: 71.94 | L14: 71.94 | M14: 71.94 | N14: 71.94 | O14: 71.94 | P14: 71.94 | Q14: 71.94 | R14: 71.94 | S14: 71.94
A15: Realised price / benchmark | B15: a.realisation | H15: 0.63 | I15: 0.63 | J15: 0.63 | K15: 0.63 | L15: 0.63 | M15: 0.63 | N15: 0.63 | O15: 0.63 | P15: 0.63 | Q15: 0.63 | R15: 0.63 | S15: 0.63
A16: Share of volume under a price cap (e.g. DMO) | B16: a.capped_share | H16: 0.25 | I16: 0.25 | J16: 0.25 | K16: 0.25 | L16: 0.25 | M16: 0.25 | N16: 0.25 | O16: 0.25 | P16: 0.25 | Q16: 0.25 | R16: 0.25 | S16: 0.25
A17: Strip ratio (bcm per tonne) or cost-intensity factor | B17: a.strip_ratio | H17: 4.35 | I17: 4.35 | J17: 4.35 | K17: 4.35 | L17: 4.35 | M17: 4.35 | N17: 4.35 | O17: 4.35 | P17: 4.35 | Q17: 4.35 | R17: 4.35 | S17: 4.35
A18: Mining cost per bcm (or per unit when intensity is 1) | B18: a.cost_per_bcm | H18: 3 | I18: 3 | J18: 3 | K18: 3 | L18: 3 | M18: 3.06 | N18: 3.1212 | O18: 3.183624 | P18: 3.2472965 | Q18: 3.3122424 | R18: 3.3784873 | S18: 3.446057
A19: Fuel share of mining cost | B19: a.fuel_share | C19: 0.3
A20: Other cash cost per unit (haul, barge, process) | B20: a.other_cost_unit | H20: 26.4 | I20: 26.4 | J20: 26.4 | K20: 26.4 | L20: 26.4 | M20: 26.928 | N20: 27.46656 | O20: 28.015891 | P20: 28.576209 | Q20: 29.147733 | R20: 29.730688 | S20: 30.325302
A21: Royalty rate (flat regimes) | B21: a.royalty_rate | H21: 0.142 | I21: 0.142 | J21: 0.142 | K21: 0.142 | L21: 0.142 | M21: 0.142 | N21: 0.142 | O21: 0.142 | P21: 0.142 | Q21: 0.142 | R21: 0.142 | S21: 0.142
A22: Other revenue | B22: a.other_revenue | H22: 0 | I22: 0 | J22: 0 | K22: 0 | L22: 0 | M22: 0 | N22: 0 | O22: 0 | P22: 0 | Q22: 0 | R22: 0 | S22: 0
A23: Gross margin on other revenue | B23: a.other_margin | C23: 0.1
A24: D&A per unit (reporting currency) | B24: a.da_unit | H24: 1.73 | I24: 1.73 | J24: 1.73 | K24: 1.73 | L24: 1.73 | M24: 1.7646 | N24: 1.799892 | O24: 1.8358898 | P24: 1.8726076 | Q24: 1.9100598 | R24: 1.948261 | S24: 1.9872262
A25: Sustaining capex per unit (reporting currency) | B25: a.capex_unit | H25: 5 | I25: 5 | J25: 5 | K25: 5 | L25: 5 | M25: 5.1 | N25: 5.202 | O25: 5.30604 | P25: 5.4121608 | Q25: 5.520404 | R25: 5.6308121 | S25: 5.7434283
A26: Other capex (expansion projects) | B26: a.capex_other | H26: 0 | I26: 0 | J26: 0 | K26: 0 | L26: 0 | M26: 0 | N26: 0 | O26: 0 | P26: 0 | Q26: 0 | R26: 0 | S26: 0
A27: Operating working capital / revenue | B27: a.nwc_pct | H27: -0.034701 | I27: -0.034701 | J27: -0.034701 | K27: -0.034701 | L27: -0.034701 | M27: -0.034701 | N27: -0.034701 | O27: -0.034701 | P27: -0.034701 | Q27: -0.034701 | R27: -0.034701 | S27: -0.034701
A28: Effective tax rate | B28: a.tax_rate | H28: 0.169858 | I28: 0.169858 | J28: 0.169858 | K28: 0.169858 | L28: 0.169858 | M28: 0.169858 | N28: 0.169858 | O28: 0.169858 | P28: 0.169858 | Q28: 0.169858 | R28: 0.169858 | S28: 0.169858
A29: Cost of debt (on opening debt) | B29: a.cost_of_debt | C29: 0.05544
A30: Yield on opening cash | B30: a.cash_yield | C30: 0.032987
A31: Net new borrowing | B31: a.net_borrowing | H31: 0 | I31: 0 | J31: 0 | K31: 0 | L31: 0 | M31: 0 | N31: 0 | O31: 0 | P31: 0 | Q31: 0 | R31: 0 | S31: 0
A32: Other non-operating items | B32: a.other_nonop | H32: 0 | I32: 0 | J32: 0 | K32: 0 | L32: 0 | M32: 0 | N32: 0 | O32: 0 | P32: 0 | Q32: 0 | R32: 0 | S32: 0
A33: Minorities' share of net profit | B33: a.minority_pct | H33: 0.100896 | I33: 0.100896 | J33: 0.100896 | K33: 0.100896 | L33: 0.100896 | M33: 0.100896 | N33: 0.100896 | O33: 0.100896 | P33: 0.100896 | Q33: 0.100896 | R33: 0.100896 | S33: 0.100896
A34: Dividend payout | B34: a.payout | H34: 0.85 | I34: 0.7 | J34: 0.6 | K34: 0.6 | L34: 0.6 | M34: 0.55 | N34: 0.55 | O34: 0.55 | P34: 0.55 | Q34: 0.55 | R34: 0.55 | S34: 0.55
A35: Change in share count | B35: a.share_change | H35: 0 | I35: 0 | J35: 0 | K35: 0 | L35: 0 | M35: 0 | N35: 0 | O35: 0 | P35: 0 | Q35: 0 | R35: 0 | S35: 0
A36: Terminal growth (DCF) | B36: a.terminal_growth | C36: 0
A37: SG&A / revenue | B37: a.opex_pct | H37: 0.052 | I37: 0.052 | J37: 0.052 | K37: 0.052 | L37: 0.052 | M37: 0.052 | N37: 0.052 | O37: 0.052 | P37: 0.052 | Q37: 0.052 | R37: 0.052 | S37: 0.052
A39: MODEL
A40: Reserves remaining (close) | B40: reserves | G40: 1000 | H40: =MAX((G40-H41),0) | I40: =MAX((H40-I41),0) | J40: =MAX((I40-J41),0) | K40: =MAX((J40-K41),0) | L40: =MAX((K40-L41),0) | M40: =MAX((L40-M41),0) | N40: =MAX((M40-N41),0) | O40: =MAX((N40-O41),0) | ... S40: =MAX((R40-S41),0)
A41: Sales volume | B41: volume | E41: 63.4 | F41: 68.06 | G41: 71.94 | H41: =IF(($C$9>0),MIN(H14,MAX(G40,0)),H14) | I41: =IF(($C$9>0),MIN(I14,MAX(H40,0)),I14) | J41: =IF(($C$9>0),MIN(J14,MAX(I40,0)),J14) | K41: =IF(($C$9>0),MIN(K14,MAX(J40,0)),K14) | L41: =IF(($C$9>0),MIN(L14,MAX(K40,0)),L14) | M41: =IF(($C$9>0),MIN(M14,MAX(L40,0)),M14) | N41: =IF(($C$9>0),MIN(N14,MAX(M40,0)),N14) | O41: =IF(($C$9>0),MIN(O14,MAX(N40,0)),O14) | ... S41: =IF(($C$9>0),MIN(S14,MAX(R40,0)),S14)
A42: Benchmark price | B42: benchmark | H42: =Drivers!$L$6 | I42: =Drivers!$M$6 | J42: =Drivers!$N$6 | K42: =Drivers!$O$6 | L42: =Drivers!$P$6 | M42: =Drivers!$Q$6 | N42: =Drivers!$R$6 | O42: =Drivers!$S$6 | P42: =Drivers!$T$6 | Q42: =Drivers!$U$6 | R42: =Drivers!$V$6 | S42: =Drivers!$W$6
A43: Average selling price | B43: asp | H43: =(((H15*H42)*(1-H16))+(MIN(Drivers!$L$4,(H15*H42))*H16)) | I43: =(((I15*I42)*(1-I16))+(MIN(Drivers!$M$4,(I15*I42))*I16)) | J43: =(((J15*J42)*(1-J16))+(MIN(Drivers!$N$4,(J15*J42))*J16)) | K43: =(((K15*K42)*(1-K16))+(MIN(Drivers!$O$4,(K15*K42))*K16)) | L43: =(((L15*L42)*(1-L16))+(MIN(Drivers!$P$4,(L15*L42))*L16)) | M43: =(((M15*M42)*(1-M16))+(MIN(Drivers!$Q$4,(M15*M42))*M16)) | N43: =(((N15*N42)*(1-N16))+(MIN(Drivers!$R$4,(N15*N42))*N16)) | O43: =(((O15*O42)*(1-O16))+(MIN(Drivers!$S$4,(O15*O42))*O16)) | P43: =(((P15*P42)*(1-P16))+(MIN(Drivers!$T$4,(P15*P42))*P16)) | Q43: =(((Q15*Q42)*(1-Q16))+(MIN(Drivers!$U$4,(Q15*Q42))*Q16)) | R43: =(((R15*R42)*(1-R16))+(MIN(Drivers!$V$4,(R15*R42))*R16)) | S43: =(((S15*S42)*(1-S16))+(MIN(Drivers!$W$4,(S15*S42))*S16))
A44: Realisation vs benchmark | B44: realisation_line | H44: =IF(H42=0,0,H43/H42) | I44: =IF(I42=0,0,I43/I42) | J44: =IF(J42=0,0,J43/J42) | K44: =IF(K42=0,0,K43/K42) | L44: =IF(L42=0,0,L43/L42) | M44: =IF(M42=0,0,M43/M42) | N44: =IF(N42=0,0,N43/N42) | O44: =IF(O42=0,0,O43/O42) | ... S44: =IF(S42=0,0,S43/S42)
...

Sheet ADMR
A1: PT Alamtri Minerals Indonesia Tbk (ADMR.JK) — Coal producers
A2: Units: USD m; per-share in USD unless marked IDR. Model asof 2026-10-30 · data 2026-10-26
A4: Line | C4: Scalar | D4: FY2022A | E4: FY2023A | F4: FY2024A | G4: FY2025A | H4: FY2026E | I4: FY2027E | J4: FY2028E | K4: FY2029E | L4: FY2030E | M4: FY2031E | N4: FY2032E | O4: FY2033E | P4: FY2034E | Q4: FY2035E | R4: FY2036E | S4: FY2037E | T4: FY2038E | U4: FY2039E | V4: FY2040E | W4: FY2041E | X4: FY2042E | Y4: FY2043E | Z4: FY2044E | AA4: FY2045E | AB4: FY2046E | AC4: FY2047E | AD4: FY2048E | AE4: FY2049E | AF4: FY2050E
A6: PARAMETERS
A7: horizon | C7: 25
A8: ps_factor | C8: 1
A9: reserves | C9: 178.1
A10: unit_factor | C10: 1
A11: vp_factor | C11: 1
A13: INPUTS (company assumptions)
A14: Sales volume plan | B14: a.volume | H14: 6.5 | I14: 7.1 | J14: 7.3 | K14: 7.3 | L14: 7.3 | M14: 7.3 | N14: 7.3 | O14: 7.3 | P14: 7.3 | Q14: 7.3 | R14: 7.3 | S14: 7.3 | T14: 7.3 | U14: 7.3 | V14: 7.3 | W14: 7.3 | X14: 7.3 | Y14: 7.3 | Z14: 7.3 | AA14: 7.3 | AB14: 7.3 | AC14: 7.3 | AD14: 7.3 | AE14: 7.3 | AF14: 7.3
A15: Realised price / benchmark | B15: a.realisation | H15: 1.43 | I15: 1.43 | J15: 1.43 | K15: 1.43 | L15: 1.43 | M15: 1.43 | N15: 1.43 | O15: 1.43 | P15: 1.43 | Q15: 1.43 | R15: 1.43 | S15: 1.43 | T15: 1.43 | U15: 1.43 | V15: 1.43 | W15: 1.43 | X15: 1.43 | Y15: 1.43 | Z15: 1.43 | AA15: 1.43 | AB15: 1.43 | AC15: 1.43 | AD15: 1.43 | AE15: 1.43 | AF15: 1.43
A16: Share of volume under a price cap (e.g. DMO) | B16: a.capped_share | H16: 0 | I16: 0 | J16: 0 | K16: 0 | L16: 0 | M16: 0 | N16: 0 | O16: 0 | P16: 0 | Q16: 0 | R16: 0 | S16: 0 | T16: 0 | U16: 0 | V16: 0 | W16: 0 | X16: 0 | Y16: 0 | Z16: 0 | AA16: 0 | AB16: 0 | AC16: 0 | AD16: 0 | AE16: 0 | AF16: 0
A17: Strip ratio (bcm per tonne) or cost-intensity factor | B17: a.strip_ratio | H17: 3.55 | I17: 3.55 | J17: 3.55 | K17: 3.55 | L17: 3.55 | M17: 3.55 | N17: 3.55 | O17: 3.55 | P17: 3.55 | Q17: 3.55 | R17: 3.55 | S17: 3.55 | T17: 3.55 | U17: 3.55 | V17: 3.55 | W17: 3.55 | X17: 3.55 | Y17: 3.55 | Z17: 3.55 | AA17: 3.55 | AB17: 3.55 | AC17: 3.55 | AD17: 3.55 | AE17: 3.55 | AF17: 3.55
A18: Mining cost per bcm (or per unit when intensity is 1) | B18: a.cost_per_bcm | H18: 8 | I18: 8 | J18: 8 | K18: 8 | L18: 8 | M18: 8.16 | N18: 8.3232 | O18: 8.489664 | P18: 8.6594573 | Q18: 8.8326464 | R18: 9.0092994 | S18: 9.1894853 | T18: 9.373275 | U18: 9.5607405 | V18: 9.7519554 | W18: 9.9469945 | X18: 10.145934 | Y18: 10.348853 | Z18: 10.55583 | AA18: 10.766947 | AB18: 10.982286 | AC18: 11.201931 | AD18: 11.42597 | AE18: 11.654489 | AF18: 11.887579
A19: Fuel share of mining cost | B19: a.fuel_share | C19: 0.3
A20: Other cash cost per unit (haul, barge, process) | B20: a.other_cost_unit | H20: 36.8 | I20: 36.8 | J20: 36.8 | K20: 36.8 | L20: 36.8 | M20: 37.536 | N20: 38.28672 | O20: 39.052454 | P20: 39.833503 | Q20: 40.630174 | R20: 41.442777 | S20: 42.271633 | T20: 43.117065 | U20: 43.979407 | V20: 44.858995 | W20: 45.756175 | X20: 46.671298 | Y20: 47.604724 | Z20: 48.556818 | AA20: 49.527955 | AB20: 50.518514 | AC20: 51.528884 | AD20: 52.559462 | AE20: 53.610651 | AF20: 54.682864
A21: Royalty rate (flat regimes) | B21: a.royalty_rate | H21: 0.128 | I21: 0.128 | J21: 0.128 | K21: 0.128 | L21: 0.128 | M21: 0.128 | N21: 0.128 | O21: 0.128 | P21: 0.128 | Q21: 0.128 | R21: 0.128 | S21: 0.128 | T21: 0.128 | U21: 0.128 | V21: 0.128 | W21: 0.128 | X21: 0.128 | Y21: 0.128 | Z21: 0.128 | AA21: 0.128 | AB21: 0.128 | AC21: 0.128 | AD21: 0.128 | AE21: 0.128 | AF21: 0.128
A22: Other revenue | B22: a.other_revenue | H22: 0 | I22: 0 | J22: 0 | K22: 0 | L22: 0 | M22: 0 | N22: 0 | O22: 0 | P22: 0 | Q22: 0 | R22: 0 | S22: 0 | T22: 0 | U22: 0 | V22: 0 | W22: 0 | X22: 0 | Y22: 0 | Z22: 0 | AA22: 0 | AB22: 0 | AC22: 0 | AD22: 0 | AE22: 0 | AF22: 0
A23: Gross margin on other revenue | B23: a.other_margin | C23: 0.1
A24: D&A per unit (reporting currency) | B24: a.da_unit | H24: 7 | I24: 7 | J24: 7 | K24: 7 | L24: 7 | M24: 7.14 | N24: 7.2828 | O24: 7.428456 | P24: 7.5770251 | Q24: 7.7285656 | R24: 7.8831369 | S24: 8.0407997 | T24: 8.2016157 | U24: 8.365648 | V24: 8.5329609 | W24: 8.7036202 | X24: 8.8776926 | Y24: 9.0552464 | Z24: 9.2363513 | AA24: 9.4210784 | AB24: 9.6094999 | AC24: 9.8016899 | AD24: 9.9977237 | AE24: 10.197678 | AF24: 10.401632
A25: Sustaining capex per unit (reporting currency) | B25: a.capex_unit | H25: 7 | I25: 7 | J25: 7 | K25: 7 | L25: 7 | M25: 7.14 | N25: 7.2828 | O25: 7.428456 | P25: 7.5770251 | Q25: 7.7285656 | R25: 7.8831369 | S25: 8.0407997 | T25: 8.2016157 | U25: 8.365648 | V25: 8.5329609 | W25: 8.7036202 | X25: 8.8776926 | Y25: 9.0552464 | Z25: 9.2363513 | AA25: 9.4210784 | AB25: 9.6094999 | AC25: 9.8016899 | AD25: 9.9977237 | AE25: 10.197678 | AF25: 10.401632
A26: Other capex (expansion projects) | B26: a.capex_other | H26: 100 | I26: 0 | J26: 0 | K26: 0 | L26: 0 | M26: 0 | N26: 0 | O26: 0 | P26: 0 | Q26: 0 | R26: 0 | S26: 0 | T26: 0 | U26: 0 | V26: 0 | W26: 0 | X26: 0 | Y26: 0 | Z26: 0 | AA26: 0 | AB26: 0 | AC26: 0 | AD26: 0 | AE26: 0 | AF26: 29.26
A27: Operating working capital / revenue | B27: a.nwc_pct | H27: -0.014934 | I27: -0.014934 | J27: -0.014934 | K27: -0.014934 | L27: -0.014934 | M27: -0.014934 | N27: -0.014934 | O27: -0.014934 | P27: -0.014934 | Q27: -0.014934 | R27: -0.014934 | S27: -0.014934 | T27: -0.014934 | U27: -0.014934 | V27: -0.014934 | W27: -0.014934 | X27: -0.014934 | Y27: -0.014934 | Z27: -0.014934 | AA27: -0.014934 | AB27: -0.014934 | AC27: -0.014934 | AD27: -0.014934 | AE27: -0.014934 | AF27: -0.014934
A28: Effective tax rate | B28: a.tax_rate | H28: 0.221746 | I28: 0.221746 | J28: 0.221746 | K28: 0.221746 | L28: 0.221746 | M28: 0.221746 | N28: 0.221746 | O28: 0.221746 | P28: 0.221746 | Q28: 0.221746 | R28: 0.221746 | S28: 0.221746 | T28: 0.221746 | U28: 0.221746 | V28: 0.221746 | W28: 0.221746 | X28: 0.221746 | Y28: 0.221746 | Z28: 0.221746 | AA28: 0.221746 | AB28: 0.221746 | AC28: 0.221746 | AD28: 0.221746 | AE28: 0.221746 | AF28: 0.221746
A29: Cost of debt (on opening debt) | B29: a.cost_of_debt | C29: 0.08
A30: Yield on opening cash | B30: a.cash_yield | C30: 0.043065
A31: Net new borrowing | B31: a.net_borrowing | H31: 1136.351 | I31: 0 | J31: 0 | K31: 0 | L31: 0 | M31: 0 | N31: 0 | O31: 0 | P31: 0 | Q31: 0 | R31: 0 | S31: 0 | T31: 0 | U31: 0 | V31: 0 | W31: 0 | X31: 0 | Y31: 0 | Z31: 0 | AA31: 0 | AB31: 0 | AC31: 0 | AD31: 0 | AE31: 0 | AF31: 0
A32: Other non-operating items | B32: a.other_nonop | H32: 0 | I32: 0 | J32: 0 | K32: 0 | L32: 0 | M32: 0 | N32: 0 | O32: 0 | P32: 0 | Q32: 0 | R32: 0 | S32: 0 | T32: 0 | U32: 0 | V32: 0 | W32: 0 | X32: 0 | Y32: 0 | Z32: 0 | AA32: 0 | AB32: 0 | AC32: 0 | AD32: 0 | AE32: 0 | AF32: 0
A33: Minorities' share of net profit | B33: a.minority_pct | H33: 0 | I33: 0 | J33: 0 | K33: 0 | L33: 0 | M33: 0 | N33: 0 | O33: 0 | P33: 0 | Q33: 0 | R33: 0 | S33: 0 | T33: 0 | U33: 0 | V33: 0 | W33: 0 | X33: 0 | Y33: 0 | Z33: 0 | AA33: 0 | AB33: 0 | AC33: 0 | AD33: 0 | AE33: 0 | AF33: 0
A34: Dividend payout | B34: a.payout | H34: 0.35 | I34: 0.35 | J34: 0.35 | K34: 0.35 | L34: 0.35 | M34: 0.35 | N34: 0.35 | O34: 0.35 | P34: 0.35 | Q34: 0.35 | R34: 0.35 | S34: 0.35 | T34: 0.35 | U34: 0.35 | V34: 0.35 | W34: 0.35 | X34: 0.35 | Y34: 0.35 | Z34: 0.35 | AA34: 0.35 | AB34: 0.35 | AC34: 0.35 | AD34: 0.35 | AE34: 0.35 | AF34: 0.35
A35: Change in share count | B35: a.share_change | H35: 0 | I35: 0 | J35: 0 | K35: 0 | L35: 0 | M35: 0 | N35: 0 | O35: 0 | P35: 0 | Q35: 0 | R35: 0 | S35: 0 | T35: 0 | U35: 0 | V35: 0 | W35: 0 | X35: 0 | Y35: 0 | Z35: 0 | AA35: 0 | AB35: 0 | AC35: 0 | AD35: 0 | AE35: 0 | AF35: 0
A36: Terminal growth (DCF) | B36: a.terminal_growth | C36: 0
A37: SG&A / revenue | B37: a.opex_pct | H37: 0.0811 | I37: 0.0811 | J37: 0.0811 | K37: 0.0811 | L37: 0.0811 | M37: 0.0811 | N37: 0.0811 | O37: 0.0811 | P37: 0.0811 | Q37: 0.0811 | R37: 0.0811 | S37: 0.0811 | T37: 0.0811 | U37: 0.0811 | V37: 0.0811 | W37: 0.0811 | X37: 0.0811 | Y37: 0.0811 | Z37: 0.0811 | AA37: 0.0811 | AB37: 0.0811 | AC37: 0.0811 | AD37: 0.0811 | AE37: 0.0811 | AF37: 0.0811
A39: MODEL
A40: Reserves remaining (close) | B40: reserves | G40: 178.1 | H40: =MAX((G40-H41),0) | I40: =MAX((H40-I41),0) | J40: =MAX((I40-J41),0) | K40: =MAX((J40-K41),0) | L40: =MAX((K40-L41),0) | M40: =MAX((L40-M41),0) | N40: =MAX((M40-N41),0) | O40: =MAX((N40-O41),0) | ... AF40: =MAX((AE40-AF41),0)
A41: Sales volume | B41: volume | F41: 5.62 | G41: 6.28 | H41: =IF(($C$9>0),MIN(H14,MAX(G40,0)),H14) | I41: =IF(($C$9>0),MIN(I14,MAX(H40,0)),I14) | J41: =IF(($C$9>0),MIN(J14,MAX(I40,0)),J14) | K41: =IF(($C$9>0),MIN(K14,MAX(J40,0)),K14) | L41: =IF(($C$9>0),MIN(L14,MAX(K40,0)),L14) | M41: =IF(($C$9>0),MIN(M14,MAX(L40,0)),M14) | N41: =IF(($C$9>0),MIN(N14,MAX(M40,0)),N14) | O41: =IF(($C$9>0),MIN(O14,MAX(N40,0)),O14) | ... AF41: =IF(($C$9>0),MIN(AF14,MAX(AE40,0)),AF14)
A42: Benchmark price | B42: benchmark | H42: =Drivers!$L$6 | I42: =Drivers!$M$6 | J42: =Drivers!$N$6 | K42: =Drivers!$O$6 | L42: =Drivers!$P$6 | M42: =Drivers!$Q$6 | N42: =Drivers!$R$6 | O42: =Drivers!$S$6 | P42: =Drivers!$T$6 | Q42: =Drivers!$U$6 | R42: =Drivers!$V$6 | S42: =Drivers!$W$6 | T42: =Drivers!$X$6 | U42: =Drivers!$Y$6 | V42: =Drivers!$Z$6 | W42: =Drivers!$AA$6 | X42: =Drivers!$AB$6 | Y42: =Drivers!$AC$6 | Z42: =Drivers!$AD$6 | AA42: =Drivers!$AE$6 | AB42: =Drivers!$AF$6 | AC42: =Drivers!$AG$6 | AD42: =Drivers!$AH$6 | AE42: =Drivers!$AI$6 | AF42: =Drivers!$AJ$6
A43: Average selling price | B43: asp | H43: =(((H15*H42)*(1-H16))+(MIN(Drivers!$L$4,(H15*H42))*H16)) | I43: =(((I15*I42)*(1-I16))+(MIN(Drivers!$M$4,(I15*I42))*I16)) | J43: =(((J15*J42)*(1-J16))+(MIN(Drivers!$N$4,(J15*J42))*J16)) | K43: =(((K15*K42)*(1-K16))+(MIN(Drivers!$O$4,(K15*K42))*K16)) | L43: =(((L15*L42)*(1-L16))+(MIN(Drivers!$P$4,(L15*L42))*L16)) | M43: =(((M15*M42)*(1-M16))+(MIN(Drivers!$Q$4,(M15*M42))*M16)) | N43: =(((N15*N42)*(1-N16))+(MIN(Drivers!$R$4,(N15*N42))*N16)) | O43: =(((O15*O42)*(1-O16))+(MIN(Drivers!$S$4,(O15*O42))*O16)) | P43: =(((P15*P42)*(1-P16))+(MIN(Drivers!$T$4,(P15*P42))*P16)) | Q43: =(((Q15*Q42)*(1-Q16))+(MIN(Drivers!$U$4,(Q15*Q42))*Q16)) | R43: =(((R15*R42)*(1-R16))+(MIN(Drivers!$V$4,(R15*R42))*R16)) | S43: =(((S15*S42)*(1-S16))+(MIN(Drivers!$W$4,(S15*S42))*S16)) | T43: =(((T15*T42)*(1-T16))+(MIN(Drivers!$X$4,(T15*T42))*T16)) | U43: =(((U15*U42)*(1-U16))+(MIN(Drivers!$Y$4,(U15*U42))*U16)) | V43: =(((V15*V42)*(1-V16))+(MIN(Drivers!$Z$4,(V15*V42))*V16)) | W43: =(((W15*W42)*(1-W16))+(MIN(Drivers!$AA$4,(W15*W42))*W16)) | X43: =(((X15*X42)*(1-X16))+(MIN(Drivers!$AB$4,(X15*X42))*X16)) | Y43: =(((Y15*Y42)*(1-Y16))+(MIN(Drivers!$AC$4,(Y15*Y42))*Y16)) | Z43: =(((Z15*Z42)*(1-Z16))+(MIN(Drivers!$AD$4,(Z15*Z42))*Z16)) | AA43: =(((AA15*AA42)*(1-AA16))+(MIN(Drivers!$AE$4,(AA15*AA42))*AA16)) | AB43: =(((AB15*AB42)*(1-AB16))+(MIN(Drivers!$AF$4,(AB15*AB42))*AB16)) | AC43: =(((AC15*AC42)*(1-AC16))+(MIN(Drivers!$AG$4,(AC15*AC42))*AC16)) | AD43: =(((AD15*AD42)*(1-AD16))+(MIN(Drivers!$AH$4,(AD15*AD42))*AD16)) | AE43: =(((AE15*AE42)*(1-AE16))+(MIN(Drivers!$AI$4,(AE15*AE42))*AE16)) | AF43: =(((AF15*AF42)*(1-AF16))+(MIN(Drivers!$AJ$4,(AF15*AF42))*AF16))
A44: Realisation vs benchmark | B44: realisation_line | H44: =IF(H42=0,0,H43/H42) | I44: =IF(I42=0,0,I43/I42) | J44: =IF(J42=0,0,J43/J42) | K44: =IF(K42=0,0,K43/K42) | L44: =IF(L42=0,0,L43/L42) | M44: =IF(M42=0,0,M43/M42) | N44: =IF(N42=0,0,N43/N42) | O44: =IF(O42=0,0,O43/O42) | ... AF44: =IF(AF42=0,0,AF43/AF42)
...

Sheet ARII
A1: PT Atlas Resources Tbk (ARII.JK) — Coal producers
A2: Units: USD m; per-share in USD unless marked IDR. Model asof 2026-10-30 · data 2026-10-29
A4: Line | C4: Scalar | D4: FY2022A | E4: FY2023A | F4: FY2024A | G4: FY2025A | H4: FY2026E | I4: FY2027E | J4: FY2028E | K4: FY2029E
A6: PARAMETERS
A7: horizon | C7: 4
A8: ps_factor | C8: 1
A9: reserves | C9: 268.43
A10: unit_factor | C10: 1
A11: vp_factor | C11: 1
A13: INPUTS (company assumptions)
A14: Sales volume plan | B14: a.volume | H14: 7.535464 | I14: 7.535464 | J14: 7.535464 | K14: 7.535464
A15: Realised price / benchmark | B15: a.realisation | H15: 0.4453 | I15: 0.4453 | J15: 0.4453 | K15: 0.4453
A16: Share of volume under a price cap (e.g. DMO) | B16: a.capped_share | H16: 0.504 | I16: 0.504 | J16: 0.504 | K16: 0.504
A17: Strip ratio (bcm per tonne) or cost-intensity factor | B17: a.strip_ratio | H17: 6.62 | I17: 6.62 | J17: 6.62 | K17: 6.62
A18: Mining cost per bcm (or per unit when intensity is 1) | B18: a.cost_per_bcm | H18: 2.398 | I18: 2.398 | J18: 2.398 | K18: 2.398
A19: Fuel share of mining cost | B19: a.fuel_share | C19: 0.3
A20: Other cash cost per unit (haul, barge, process) | B20: a.other_cost_unit | H20: 20.56 | I20: 20.56 | J20: 20.56 | K20: 20.56
A21: Royalty rate (flat regimes) | B21: a.royalty_rate | H21: 0.0883 | I21: 0.0883 | J21: 0.0883 | K21: 0.0883
A22: Other revenue | B22: a.other_revenue | H22: 0 | I22: 0 | J22: 0 | K22: 0
A23: Gross margin on other revenue | B23: a.other_margin | C23: 0.1
A24: D&A per unit (reporting currency) | B24: a.da_unit | H24: 4.469 | I24: 4.469 | J24: 4.469 | K24: 4.469
A25: Sustaining capex per unit (reporting currency) | B25: a.capex_unit | H25: 3.975 | I25: 3.975 | J25: 3.975 | K25: 3.975
A26: Other capex (expansion projects) | B26: a.capex_other | H26: 0 | I26: 0 | J26: 0 | K26: 0
A27: Operating working capital / revenue | B27: a.nwc_pct | H27: -0.15894 | I27: -0.15894 | J27: -0.15894 | K27: -0.15894
A28: Effective tax rate | B28: a.tax_rate | H28: 0.356 | I28: 0.356 | J28: 0.356 | K28: 0.356
A29: Cost of debt (on opening debt) | B29: a.cost_of_debt | C29: 0.043895
A30: Yield on opening cash | B30: a.cash_yield | C30: 0.024954
A31: Net new borrowing | B31: a.net_borrowing | H31: 0 | I31: 0 | J31: 0 | K31: 0
A32: Other non-operating items | B32: a.other_nonop | H32: 0 | I32: 0 | J32: 0 | K32: 0
A33: Minorities' share of net profit | B33: a.minority_pct | H33: 0.45 | I33: 0.45 | J33: 0.45 | K33: 0.45
A34: Dividend payout | B34: a.payout | H34: 0 | I34: 0 | J34: 0 | K34: 0
A35: Change in share count | B35: a.share_change | H35: 0 | I35: 0 | J35: 0 | K35: 0
A36: Terminal growth (DCF) | B36: a.terminal_growth | C36: 0
A37: SG&A / revenue | B37: a.opex_pct | H37: 0.08687 | I37: 0.08687 | J37: 0.08687 | K37: 0.08687
A39: MODEL
A40: Reserves remaining (close) | B40: reserves | G40: 268.43 | H40: =MAX((G40-H41),0) | I40: =MAX((H40-I41),0) | J40: =MAX((I40-J41),0) | K40: =MAX((J40-K41),0)
A41: Sales volume | B41: volume | F41: 5.445246 | G41: 7.535464 | H41: =IF(($C$9>0),MIN(H14,MAX(G40,0)),H14) | I41: =IF(($C$9>0),MIN(I14,MAX(H40,0)),I14) | J41: =IF(($C$9>0),MIN(J14,MAX(I40,0)),J14) | K41: =IF(($C$9>0),MIN(K14,MAX(J40,0)),K14)
A42: Benchmark price | B42: benchmark | H42: =Drivers!$L$6 | I42: =Drivers!$M$6 | J42: =Drivers!$N$6 | K42: =Drivers!$O$6
A43: Average selling price | B43: asp | H43: =(((H15*H42)*(1-H16))+(MIN(Drivers!$L$4,(H15*H42))*H16)) | I43: =(((I15*I42)*(1-I16))+(MIN(Drivers!$M$4,(I15*I42))*I16)) | J43: =(((J15*J42)*(1-J16))+(MIN(Drivers!$N$4,(J15*J42))*J16)) | K43: =(((K15*K42)*(1-K16))+(MIN(Drivers!$O$4,(K15*K42))*K16))
A44: Realisation vs benchmark | B44: realisation_line | H44: =IF(H42=0,0,H43/H42) | I44: =IF(I42=0,0,I43/I42) | J44: =IF(J42=0,0,J43/J42) | K44: =IF(K42=0,0,K43/K42)
...

Sheet BOSS
A1: PT. Borneo Olah Sarana Sukses Tbk (BOSS.JK) — Coal producers
A2: Units: IDR bn; per-share in IDR unless marked IDR. Model asof 2026-10-30 · data 2026-10-27
A4: Line | C4: Scalar | D4: FY2021A | E4: FY2022A | F4: FY2023E | G4: FY2024E | H4: FY2025E | I4: FY2026E | J4: FY2027E | K4: FY2028E | L4: FY2029E | M4: FY2030E | N4: FY2031E | O4: FY2032E
A6: PARAMETERS
A7: horizon | C7: 10
A8: ps_factor | C8: 1000
A9: reserves | C9: 10.83
A10: unit_factor | C10: 1
A11: vp_factor | C11: 1
A13: INPUTS (company assumptions)
A14: Sales volume plan | B14: a.volume | F14: 0.0765 | G14: 0.0765 | H14: 0.0765 | I14: 0.15 | J14: 0.4 | K14: 0.48 | L14: 0.48 | M14: 0.48 | N14: 0.48 | O14: 0.48
A15: Realised price / benchmark | B15: a.realisation | F15: 0.93 | G15: 0.93 | H15: 0.93 | I15: 0.93 | J15: 0.93 | K15: 0.93 | L15: 0.93 | M15: 0.93 | N15: 0.93 | O15: 0.93
A16: Share of volume under a price cap (e.g. DMO) | B16: a.capped_share | F16: 0 | G16: 0 | H16: 0 | I16: 0 | J16: 0 | K16: 0 | L16: 0 | M16: 0 | N16: 0 | O16: 0
A17: Strip ratio (bcm per tonne) or cost-intensity factor | B17: a.strip_ratio | F17: 1 | G17: 1 | H17: 1 | I17: 1 | J17: 1 | K17: 1 | L17: 1 | M17: 1 | N17: 1 | O17: 1
A18: Mining cost per bcm (or per unit when intensity is 1) | B18: a.cost_per_bcm | F18: 104.55 | G18: 104.55 | H18: 104.55 | I18: 62.1 | J18: 62.1 | K18: 63.342 | L18: 64.60884 | M18: 65.901017 | N18: 67.219037 | O18: 68.563418
A19: Fuel share of mining cost | B19: a.fuel_share | C19: 0
A20: Other cash cost per unit (haul, barge, process) | B20: a.other_cost_unit | F20: 34.1 | G20: 34.1 | H20: 34.1 | I20: 20.3 | J20: 20.3 | K20: 20.706 | L20: 21.12012 | M20: 21.542522 | N20: 21.973373 | O20: 22.41284
A21: Royalty rate (flat regimes) | B21: a.royalty_rate | F21: 0.121 | G21: 0.121 | H21: 0.121 | I21: 0.121 | J21: 0.121 | K21: 0.121 | L21: 0.121 | M21: 0.121 | N21: 0.121 | O21: 0.121
A22: Other revenue | B22: a.other_revenue | F22: 0 | G22: 0 | H22: 0 | I22: 0 | J22: 0 | K22: 0 | L22: 0 | M22: 0 | N22: 0 | O22: 0
A23: Gross margin on other revenue | B23: a.other_margin | C23: 0.1
A24: D&A per unit (reporting currency) | B24: a.da_unit | F24: 236431 | G24: 236431 | H24: 236431 | I24: 91942 | J24: 91942 | K24: 93780.84 | L24: 95656.457 | M24: 97569.586 | N24: 99520.978 | O24: 101511.4
A25: Sustaining capex per unit (reporting currency) | B25: a.capex_unit | F25: 26664 | G25: 26664 | H25: 26664 | I25: 26664 | J25: 26664 | K25: 27197.28 | L25: 27741.226 | M25: 28296.05 | N25: 28861.971 | O25: 29439.211
A26: Other capex (expansion projects) | B26: a.capex_other | F26: 0 | G26: 0 | H26: 0 | I26: 0 | J26: 0 | K26: 0 | L26: 0 | M26: 0 | N26: 0 | O26: 0
A27: Operating working capital / revenue | B27: a.nwc_pct | F27: -0.1123 | G27: -0.1123 | H27: -0.1123 | I27: -0.1123 | J27: -0.1123 | K27: -0.1123 | L27: -0.1123 | M27: -0.1123 | N27: -0.1123 | O27: -0.1123
A28: Effective tax rate | B28: a.tax_rate | F28: 0.22 | G28: 0.22 | H28: 0.22 | I28: 0.22 | J28: 0.22 | K28: 0.22 | L28: 0.22 | M28: 0.22 | N28: 0.22 | O28: 0.22
A29: Cost of debt (on opening debt) | B29: a.cost_of_debt | C29: 0.1432
A30: Yield on opening cash | B30: a.cash_yield | C30: 0
A31: Net new borrowing | B31: a.net_borrowing | F31: 0 | G31: 0 | H31: 0 | I31: 0 | J31: 0 | K31: 0 | L31: 0 | M31: 0 | N31: 0 | O31: 0
A32: Other non-operating items | B32: a.other_nonop | F32: 0 | G32: 0 | H32: 0 | I32: 0 | J32: 0 | K32: 0 | L32: 0 | M32: 0 | N32: 0 | O32: 0
A33: Minorities' share of net profit | B33: a.minority_pct | F33: 0 | G33: 0 | H33: 0 | I33: 0 | J33: 0 | K33: 0 | L33: 0 | M33: 0 | N33: 0 | O33: 0
A34: Dividend payout | B34: a.payout | F34: 0 | G34: 0 | H34: 0 | I34: 0 | J34: 0 | K34: 0 | L34: 0 | M34: 0 | N34: 0 | O34: 0
A35: Change in share count | B35: a.share_change | F35: 0 | G35: 0 | H35: 0 | I35: 0 | J35: 0 | K35: 0 | L35: 0 | M35: 0 | N35: 0 | O35: 0
A36: Terminal growth (DCF) | B36: a.terminal_growth | C36: 0.04
A37: SG&A / revenue | B37: a.opex_pct | F37: 0.1736 | G37: 0.1736 | H37: 0.1736 | I37: 0.096 | J37: 0.096 | K37: 0.096 | L37: 0.096 | M37: 0.096 | N37: 0.096 | O37: 0.096
A39: MODEL
A40: Reserves remaining (close) | B40: reserves | E40: 10.83 | F40: =MAX((E40-F41),0) | G40: =MAX((F40-G41),0) | H40: =MAX((G40-H41),0) | I40: =MAX((H40-I41),0) | J40: =MAX((I40-J41),0) | K40: =MAX((J40-K41),0) | L40: =MAX((K40-L41),0) | M40: =MAX((L40-M41),0) | ... O40: =MAX((N40-O41),0)
A41: Sales volume | B41: volume | D41: 0.061026 | E41: 0.109322 | F41: =IF(($C$9>0),MIN(F14,MAX(E40,0)),F14) | G41: =IF(($C$9>0),MIN(G14,MAX(F40,0)),G14) | H41: =IF(($C$9>0),MIN(H14,MAX(G40,0)),H14) | I41: =IF(($C$9>0),MIN(I14,MAX(H40,0)),I14) | J41: =IF(($C$9>0),MIN(J14,MAX(I40,0)),J14) | K41: =IF(($C$9>0),MIN(K14,MAX(J40,0)),K14) | L41: =IF(($C$9>0),MIN(L14,MAX(K40,0)),L14) | M41: =IF(($C$9>0),MIN(M14,MAX(L40,0)),M14) | ... O41: =IF(($C$9>0),MIN(O14,MAX(N40,0)),O14)
A42: Benchmark price | B42: benchmark | F42: =Drivers!$G$6 | G42: =Drivers!$I$6 | H42: =Drivers!$K$6 | I42: =Drivers!$L$6 | J42: =Drivers!$M$6 | K42: =Drivers!$N$6 | L42: =Drivers!$O$6 | M42: =Drivers!$P$6 | N42: =Drivers!$Q$6 | O42: =Drivers!$R$6
A43: Average selling price | B43: asp | E43: 175 | F43: =(((F15*F42)*(1-F16))+(MIN(Drivers!$G$4,(F15*F42))*F16)) | G43: =(((G15*G42)*(1-G16))+(MIN(Drivers!$I$4,(G15*G42))*G16)) | H43: =(((H15*H42)*(1-H16))+(MIN(Drivers!$K$4,(H15*H42))*H16)) | I43: =(((I15*I42)*(1-I16))+(MIN(Drivers!$L$4,(I15*I42))*I16)) | J43: =(((J15*J42)*(1-J16))+(MIN(Drivers!$M$4,(J15*J42))*J16)) | K43: =(((K15*K42)*(1-K16))+(MIN(Drivers!$N$4,(K15*K42))*K16)) | L43: =(((L15*L42)*(1-L16))+(MIN(Drivers!$O$4,(L15*L42))*L16)) | M43: =(((M15*M42)*(1-M16))+(MIN(Drivers!$P$4,(M15*M42))*M16)) | N43: =(((N15*N42)*(1-N16))+(MIN(Drivers!$Q$4,(N15*N42))*N16)) | O43: =(((O15*O42)*(1-O16))+(MIN(Drivers!$R$4,(O15*O42))*O16))
A44: Realisation vs benchmark | B44: realisation_line | F44: =IF(F42=0,0,F43/F42) | G44: =IF(G42=0,0,G43/G42) | H44: =IF(H42=0,0,H43/H42) | I44: =IF(I42=0,0,I43/I42) | J44: =IF(J42=0,0,J43/J42) | K44: =IF(K42=0,0,K43/K42) | L44: =IF(L42=0,0,L43/L42) | M44: =IF(M42=0,0,M43/M42) | ... O44: =IF(O42=0,0,O43/O42)
...

Sheet BSSR
A1: PT Baramulti Suksessarana Tbk (BSSR.JK) — Coal producers
A2: Units: USD m; per-share in USD unless marked IDR. Model asof 2026-10-30 · data 2026-10-26
A4: Line | C4: Scalar | D4: FY2022A | E4: FY2023A | F4: FY2024A | G4: FY2025A | H4: FY2026E | I4: FY2027E | J4: FY2028E | K4: FY2029E | L4: FY2030E | M4: FY2031E | N4: FY2032E | O4: FY2033E | P4: FY2034E | Q4: FY2035E
A6: PARAMETERS
A7: horizon | C7: 10
A8: ps_factor | C8: 1
A9: reserves | C9: 0
A10: unit_factor | C10: 1
A11: vp_factor | C11: 1
A13: INPUTS (company assumptions)
A14: Sales volume plan | B14: a.volume | H14: 17 | I14: 17 | J14: 17 | K14: 17 | L14: 17 | M14: 17 | N14: 17 | O14: 17 | P14: 17 | Q14: 17
A15: Realised price / benchmark | B15: a.realisation | H15: 0.369 | I15: 0.369 | J15: 0.369 | K15: 0.369 | L15: 0.369 | M15: 0.369 | N15: 0.369 | O15: 0.369 | P15: 0.369 | Q15: 0.369
A16: Share of volume under a price cap (e.g. DMO) | B16: a.capped_share | H16: 0.3 | I16: 0.3 | J16: 0.3 | K16: 0.3 | L16: 0.3 | M16: 0.3 | N16: 0.3 | O16: 0.3 | P16: 0.3 | Q16: 0.3
A17: Strip ratio (bcm per tonne) or cost-intensity factor | B17: a.strip_ratio | H17: 1 | I17: 1 | J17: 1 | K17: 1 | L17: 1 | M17: 1 | N17: 1 | O17: 1 | P17: 1 | Q17: 1
A18: Mining cost per bcm (or per unit when intensity is 1) | B18: a.cost_per_bcm | H18: 22.26 | I18: 22.26 | J18: 22.26 | K18: 22.26 | L18: 22.26 | M18: 22.7052 | N18: 23.159304 | O18: 23.62249 | P18: 24.09494 | Q18: 24.576839
A19: Fuel share of mining cost | B19: a.fuel_share | C19: 0.3
A20: Other cash cost per unit (haul, barge, process) | B20: a.other_cost_unit | H20: 0 | I20: 0 | J20: 0 | K20: 0 | L20: 0 | M20: 0 | N20: 0 | O20: 0 | P20: 0 | Q20: 0
A21: Royalty rate (flat regimes) | B21: a.royalty_rate | H21: 0.1475 | I21: 0.1475 | J21: 0.1475 | K21: 0.1475 | L21: 0.1475 | M21: 0.1475 | N21: 0.1475 | O21: 0.1475 | P21: 0.1475 | Q21: 0.1475
A22: Other revenue | B22: a.other_revenue | H22: 0 | I22: 0 | J22: 0 | K22: 0 | L22: 0 | M22: 0 | N22: 0 | O22: 0 | P22: 0 | Q22: 0
A23: Gross margin on other revenue | B23: a.other_margin | C23: 0.1
A24: D&A per unit (reporting currency) | B24: a.da_unit | H24: 0.68815 | I24: 0.68815 | J24: 0.68815 | K24: 0.68815 | L24: 0.68815 | M24: 0.701913 | N24: 0.71595126 | O24: 0.73027029 | P24: 0.74487569 | Q24: 0.7597732
A25: Sustaining capex per unit (reporting currency) | B25: a.capex_unit | H25: 1.55 | I25: 1.55 | J25: 1.55 | K25: 1.55 | L25: 1.55 | M25: 1.581 | N25: 1.61262 | O25: 1.6448724 | P25: 1.6777698 | Q25: 1.7113252
A26: Other capex (expansion projects) | B26: a.capex_other | H26: 0 | I26: 0 | J26: 0 | K26: 0 | L26: 0 | M26: 0 | N26: 0 | O26: 0 | P26: 0 | Q26: 0
A27: Operating working capital / revenue | B27: a.nwc_pct | H27: 0.055363 | I27: 0.055363 | J27: 0.055363 | K27: 0.055363 | L27: 0.055363 | M27: 0.055363 | N27: 0.055363 | O27: 0.055363 | P27: 0.055363 | Q27: 0.055363
A28: Effective tax rate | B28: a.tax_rate | H28: 0.231966 | I28: 0.231966 | J28: 0.231966 | K28: 0.231966 | L28: 0.231966 | M28: 0.231966 | N28: 0.231966 | O28: 0.231966 | P28: 0.231966 | Q28: 0.231966
A29: Cost of debt (on opening debt) | B29: a.cost_of_debt | C29: 0.040524
A30: Yield on opening cash | B30: a.cash_yield | C30: 0.042371
A31: Net new borrowing | B31: a.net_borrowing | H31: 0 | I31: 0 | J31: 0 | K31: 0 | L31: 0 | M31: 0 | N31: 0 | O31: 0 | P31: 0 | Q31: 0
A32: Other non-operating items | B32: a.other_nonop | H32: 0 | I32: 0 | J32: 0 | K32: 0 | L32: 0 | M32: 0 | N32: 0 | O32: 0 | P32: 0 | Q32: 0
A33: Minorities' share of net profit | B33: a.minority_pct | H33: 3e-06 | I33: 3e-06 | J33: 3e-06 | K33: 3e-06 | L33: 3e-06 | M33: 3e-06 | N33: 3e-06 | O33: 3e-06 | P33: 3e-06 | Q33: 3e-06
A34: Dividend payout | B34: a.payout | H34: 0.7 | I34: 0.7 | J34: 0.7 | K34: 0.7 | L34: 0.7 | M34: 0.7 | N34: 0.7 | O34: 0.7 | P34: 0.7 | Q34: 0.7
A35: Change in share count | B35: a.share_change | H35: 0 | I35: 0 | J35: 0 | K35: 0 | L35: 0 | M35: 0 | N35: 0 | O35: 0 | P35: 0 | Q35: 0
A36: Terminal growth (DCF) | B36: a.terminal_growth | C36: 0
A37: SG&A / revenue | B37: a.opex_pct | H37: 0.151 | I37: 0.151 | J37: 0.151 | K37: 0.151 | L37: 0.151 | M37: 0.151 | N37: 0.151 | O37: 0.151 | P37: 0.151 | Q37: 0.151
A39: MODEL
A40: Reserves remaining (close) | B40: reserves | H40: =MAX((G40-H41),0) | I40: =MAX((H40-I41),0) | J40: =MAX((I40-J41),0) | K40: =MAX((J40-K41),0) | L40: =MAX((K40-L41),0) | M40: =MAX((L40-M41),0) | N40: =MAX((M40-N41),0) | O40: =MAX((N40-O41),0) | ... Q40: =MAX((P40-Q41),0)
A41: Sales volume | B41: volume | F41: 20.79 | G41: 17.579 | H41: =IF(($C$9>0),MIN(H14,MAX(G40,0)),H14) | I41: =IF(($C$9>0),MIN(I14,MAX(H40,0)),I14) | J41: =IF(($C$9>0),MIN(J14,MAX(I40,0)),J14) | K41: =IF(($C$9>0),MIN(K14,MAX(J40,0)),K14) | L41: =IF(($C$9>0),MIN(L14,MAX(K40,0)),L14) | M41: =IF(($C$9>0),MIN(M14,MAX(L40,0)),M14) | N41: =IF(($C$9>0),MIN(N14,MAX(M40,0)),N14) | O41: =IF(($C$9>0),MIN(O14,MAX(N40,0)),O14) | ... Q41: =IF(($C$9>0),MIN(Q14,MAX(P40,0)),Q14)
A42: Benchmark price | B42: benchmark | H42: =Drivers!$L$6 | I42: =Drivers!$M$6 | J42: =Drivers!$N$6 | K42: =Drivers!$O$6 | L42: =Drivers!$P$6 | M42: =Drivers!$Q$6 | N42: =Drivers!$R$6 | O42: =Drivers!$S$6 | P42: =Drivers!$T$6 | Q42: =Drivers!$U$6
A43: Average selling price | B43: asp | H43: =(((H15*H42)*(1-H16))+(MIN(Drivers!$L$4,(H15*H42))*H16)) | I43: =(((I15*I42)*(1-I16))+(MIN(Drivers!$M$4,(I15*I42))*I16)) | J43: =(((J15*J42)*(1-J16))+(MIN(Drivers!$N$4,(J15*J42))*J16)) | K43: =(((K15*K42)*(1-K16))+(MIN(Drivers!$O$4,(K15*K42))*K16)) | L43: =(((L15*L42)*(1-L16))+(MIN(Drivers!$P$4,(L15*L42))*L16)) | M43: =(((M15*M42)*(1-M16))+(MIN(Drivers!$Q$4,(M15*M42))*M16)) | N43: =(((N15*N42)*(1-N16))+(MIN(Drivers!$R$4,(N15*N42))*N16)) | O43: =(((O15*O42)*(1-O16))+(MIN(Drivers!$S$4,(O15*O42))*O16)) | P43: =(((P15*P42)*(1-P16))+(MIN(Drivers!$T$4,(P15*P42))*P16)) | Q43: =(((Q15*Q42)*(1-Q16))+(MIN(Drivers!$U$4,(Q15*Q42))*Q16))
A44: Realisation vs benchmark | B44: realisation_line | H44: =IF(H42=0,0,H43/H42) | I44: =IF(I42=0,0,I43/I42) | J44: =IF(J42=0,0,J43/J42) | K44: =IF(K42=0,0,K43/K42) | L44: =IF(L42=0,0,L43/L42) | M44: =IF(M42=0,0,M43/M42) | N44: =IF(N42=0,0,N43/N42) | O44: =IF(O42=0,0,O43/O42) | ... Q44: =IF(Q42=0,0,Q43/Q42)
...

Sheet BUMI
A1: PT Bumi Resources Tbk (BUMI.JK) — Coal producers
A2: Units: USD m; per-share in USD unless marked IDR. Model asof 2026-10-30 · data 2026-10-27
A4: Line | C4: Scalar | D4: FY2022A | E4: FY2023A | F4: FY2024A | G4: FY2025A | H4: FY2026E | I4: FY2027E | J4: FY2028E | K4: FY2029E | L4: FY2030E | M4: FY2031E | N4: FY2032E | O4: FY2033E | P4: FY2034E | Q4: FY2035E | R4: FY2036E | S4: FY2037E | T4: FY2038E | U4: FY2039E | V4: FY2040E | W4: FY2041E | X4: FY2042E | Y4: FY2043E | Z4: FY2044E | AA4: FY2045E | AB4: FY2046E | AC4: FY2047E | AD4: FY2048E | AE4: FY2049E | AF4: FY2050E | AG4: FY2051E | AH4: FY2052E | AI4: FY2053E | AJ4: FY2054E | AK4: FY2055E | AL4: FY2056E | AM4: FY2057E | AN4: FY2058E
A6: PARAMETERS
A7: horizon | C7: 33
A8: ps_factor | C8: 1
A9: reserves | C9: 2500
A10: unit_factor | C10: 1
A11: vp_factor | C11: 1
A13: INPUTS (company assumptions)
A14: Sales volume plan | B14: a.volume | H14: 77 | I14: 77 | J14: 77 | K14: 77 | L14: 77 | M14: 77 | N14: 77 | O14: 77 | P14: 77 | Q14: 77 | R14: 77 | S14: 77 | T14: 77 | U14: 77 | V14: 77 | W14: 77 | X14: 77 | Y14: 77 | Z14: 77 | AA14: 77 | AB14: 77 | AC14: 77 | AD14: 77 | AE14: 77 | AF14: 77 | AG14: 77 | AH14: 77 | AI14: 77 | AJ14: 77 | AK14: 77 | AL14: 77 | AM14: 77 | AN14: 77
A15: Realised price / benchmark | B15: a.realisation | H15: 0.5946 | I15: 0.5946 | J15: 0.5946 | K15: 0.5946 | L15: 0.5946 | M15: 0.5946 | N15: 0.5946 | O15: 0.5946 | P15: 0.5946 | Q15: 0.5946 | R15: 0.5946 | S15: 0.5946 | T15: 0.5946 | U15: 0.5946 | V15: 0.5946 | W15: 0.5946 | X15: 0.5946 | Y15: 0.5946 | Z15: 0.5946 | AA15: 0.5946 | AB15: 0.5946 | AC15: 0.5946 | AD15: 0.5946 | AE15: 0.5946 | AF15: 0.5946 | AG15: 0.5946 | AH15: 0.5946 | AI15: 0.5946 | AJ15: 0.5946 | AK15: 0.5946 | AL15: 0.5946 | AM15: 0.5946 | AN15: 0.5946
A16: Share of volume under a price cap (e.g. DMO) | B16: a.capped_share | H16: 0.3 | I16: 0.3 | J16: 0.3 | K16: 0.3 | L16: 0.3 | M16: 0.3 | N16: 0.3 | O16: 0.3 | P16: 0.3 | Q16: 0.3 | R16: 0.3 | S16: 0.3 | T16: 0.3 | U16: 0.3 | V16: 0.3 | W16: 0.3 | X16: 0.3 | Y16: 0.3 | Z16: 0.3 | AA16: 0.3 | AB16: 0.3 | AC16: 0.3 | AD16: 0.3 | AE16: 0.3 | AF16: 0.3 | AG16: 0.3 | AH16: 0.3 | AI16: 0.3 | AJ16: 0.3 | AK16: 0.3 | AL16: 0.3 | AM16: 0.3 | AN16: 0.3
A17: Strip ratio (bcm per tonne) or cost-intensity factor | B17: a.strip_ratio | H17: 8 | I17: 8 | J17: 8 | K17: 8 | L17: 8 | M17: 8 | N17: 8 | O17: 8 | P17: 8 | Q17: 8 | R17: 8 | S17: 8 | T17: 8 | U17: 8 | V17: 8 | W17: 8 | X17: 8 | Y17: 8 | Z17: 8 | AA17: 8 | AB17: 8 | AC17: 8 | AD17: 8 | AE17: 8 | AF17: 8 | AG17: 8 | AH17: 8 | AI17: 8 | AJ17: 8 | AK17: 8 | AL17: 8 | AM17: 8 | AN17: 8
A18: Mining cost per bcm (or per unit when intensity is 1) | B18: a.cost_per_bcm | H18: 2.6 | I18: 2.6 | J18: 2.6 | K18: 2.6 | L18: 2.6 | M18: 2.652 | N18: 2.70504 | O18: 2.7591408 | P18: 2.8143236 | Q18: 2.8706101 | R18: 2.9280223 | S18: 2.9865827 | T18: 3.0463144 | U18: 3.1072407 | V18: 3.1693855 | W18: 3.2327732 | X18: 3.2974287 | Y18: 3.3633772 | Z18: 3.4306448 | AA18: 3.4992577 | AB18: 3.5692428 | AC18: 3.6406277 | AD18: 3.7134402 | AE18: 3.787709 | AF18: 3.8634632 | AG18: 3.9407325 | AH18: 4.0195471 | AI18: 4.0999381 | AJ18: 4.1819368 | AK18: 4.2655756 | AL18: 4.3508871 | AM18: 4.4379048 | AN18: 4.5266629
A19: Fuel share of mining cost | B19: a.fuel_share | C19: 0.3
A20: Other cash cost per unit (haul, barge, process) | B20: a.other_cost_unit | H20: 22.5 | I20: 22.5 | J20: 22.5 | K20: 22.5 | L20: 22.5 | M20: 22.95 | N20: 23.409 | O20: 23.87718 | P20: 24.354724 | Q20: 24.841818 | R20: 25.338654 | S20: 25.845428 | T20: 26.362336 | U20: 26.889583 | V20: 27.427374 | W20: 27.975922 | X20: 28.53544 | Y20: 29.106149 | Z20: 29.688272 | AA20: 30.282038 | AB20: 30.887678 | AC20: 31.505432 | AD20: 32.135541 | AE20: 32.778251 | AF20: 33.433816 | AG20: 34.102493 | AH20: 34.784543 | AI20: 35.480233 | AJ20: 36.189838 | AK20: 36.913635 | AL20: 37.651908 | AM20: 38.404946 | AN20: 39.173045
A21: Royalty rate (flat regimes) | B21: a.royalty_rate | H21: 0.18 | I21: 0.18 | J21: 0.18 | K21: 0.18 | L21: 0.18 | M21: 0.18 | N21: 0.18 | O21: 0.18 | P21: 0.18 | Q21: 0.18 | R21: 0.18 | S21: 0.18 | T21: 0.18 | U21: 0.18 | V21: 0.18 | W21: 0.18 | X21: 0.18 | Y21: 0.18 | Z21: 0.18 | AA21: 0.18 | AB21: 0.18 | AC21: 0.18 | AD21: 0.18 | AE21: 0.18 | AF21: 0.18 | AG21: 0.18 | AH21: 0.18 | AI21: 0.18 | AJ21: 0.18 | AK21: 0.18 | AL21: 0.18 | AM21: 0.18 | AN21: 0.18
A22: Other revenue | B22: a.other_revenue | H22: 0 | I22: 0 | J22: 0 | K22: 0 | L22: 0 | M22: 0 | N22: 0 | O22: 0 | P22: 0 | Q22: 0 | R22: 0 | S22: 0 | T22: 0 | U22: 0 | V22: 0 | W22: 0 | X22: 0 | Y22: 0 | Z22: 0 | AA22: 0 | AB22: 0 | AC22: 0 | AD22: 0 | AE22: 0 | AF22: 0 | AG22: 0 | AH22: 0 | AI22: 0 | AJ22: 0 | AK22: 0 | AL22: 0 | AM22: 0 | AN22: 0
A23: Gross margin on other revenue | B23: a.other_margin | C23: 0.1
A24: D&A per unit (reporting currency) | B24: a.da_unit | H24: 2.24 | I24: 2.24 | J24: 2.24 | K24: 2.24 | L24: 2.24 | M24: 2.2848 | N24: 2.330496 | O24: 2.3771059 | P24: 2.424648 | Q24: 2.473141 | R24: 2.5226038 | S24: 2.5730559 | T24: 2.624517 | U24: 2.6770074 | V24: 2.7305475 | W24: 2.7851585 | X24: 2.8408616 | Y24: 2.8976789 | Z24: 2.9556324 | AA24: 3.0147451 | AB24: 3.07504 | AC24: 3.1365408 | AD24: 3.1992716 | AE24: 3.263257 | AF24: 3.3285222 | AG24: 3.3950926 | AH24: 3.4629945 | AI24: 3.5322544 | AJ24: 3.6028994 | AK24: 3.6749574 | AL24: 3.7484566 | AM24: 3.8234257 | AN24: 3.8998942
A25: Sustaining capex per unit (reporting currency) | B25: a.capex_unit | H25: 2 | I25: 2 | J25: 2 | K25: 2 | L25: 2 | M25: 2.04 | N25: 2.0808 | O25: 2.122416 | P25: 2.1648643 | Q25: 2.2081616 | R25: 2.2523248 | S25: 2.2973713 | T25: 2.3433188 | U25: 2.3901851 | V25: 2.4379888 | W25: 2.4867486 | X25: 2.5364836 | Y25: 2.5872133 | Z25: 2.6389575 | AA25: 2.6917367 | AB25: 2.7455714 | AC25: 2.8004828 | AD25: 2.8564925 | AE25: 2.9136223 | AF25: 2.9718948 | AG25: 3.0313327 | AH25: 3.0919593 | AI25: 3.1537985 | AJ25: 3.2168745 | AK25: 3.281212 | AL25: 3.3468362 | AM25: 3.413773 | AN25: 3.4820484
A26: Other capex (expansion projects) | B26: a.capex_other | H26: 0 | I26: 0 | J26: 0 | K26: 0 | L26: 0 | M26: 0 | N26: 0 | O26: 0 | P26: 0 | Q26: 0 | R26: 0 | S26: 0 | T26: 0 | U26: 0 | V26: 0 | W26: 0 | X26: 0 | Y26: 0 | Z26: 0 | AA26: 0 | AB26: 0 | AC26: 0 | AD26: 0 | AE26: 0 | AF26: 0 | AG26: 0 | AH26: 0 | AI26: 0 | AJ26: 0 | AK26: 0 | AL26: 0 | AM26: 0 | AN26: 0
A27: Operating working capital / revenue | B27: a.nwc_pct | H27: 0.0168 | I27: 0.0168 | J27: 0.0168 | K27: 0.0168 | L27: 0.0168 | M27: 0.0168 | N27: 0.0168 | O27: 0.0168 | P27: 0.0168 | Q27: 0.0168 | R27: 0.0168 | S27: 0.0168 | T27: 0.0168 | U27: 0.0168 | V27: 0.0168 | W27: 0.0168 | X27: 0.0168 | Y27: 0.0168 | Z27: 0.0168 | AA27: 0.0168 | AB27: 0.0168 | AC27: 0.0168 | AD27: 0.0168 | AE27: 0.0168 | AF27: 0.0168 | AG27: 0.0168 | AH27: 0.0168 | AI27: 0.0168 | AJ27: 0.0168 | AK27: 0.0168 | AL27: 0.0168 | AM27: 0.0168 | AN27: 0.0168
A28: Effective tax rate | B28: a.tax_rate | H28: 0.435 | I28: 0.435 | J28: 0.435 | K28: 0.435 | L28: 0.435 | M28: 0.435 | N28: 0.435 | O28: 0.435 | P28: 0.435 | Q28: 0.435 | R28: 0.435 | S28: 0.435 | T28: 0.435 | U28: 0.435 | V28: 0.435 | W28: 0.435 | X28: 0.435 | Y28: 0.435 | Z28: 0.435 | AA28: 0.435 | AB28: 0.435 | AC28: 0.435 | AD28: 0.435 | AE28: 0.435 | AF28: 0.435 | AG28: 0.435 | AH28: 0.435 | AI28: 0.435 | AJ28: 0.435 | AK28: 0.435 | AL28: 0.435 | AM28: 0.435 | AN28: 0.435
A29: Cost of debt (on opening debt) | B29: a.cost_of_debt | C29: 0.082003
A30: Yield on opening cash | B30: a.cash_yield | C30: 0.067159
A31: Net new borrowing | B31: a.net_borrowing | H31: 298.1 | I31: 0 | J31: 0 | K31: 0 | L31: 0 | M31: 0 | N31: 0 | O31: 0 | P31: 0 | Q31: 0 | R31: 0 | S31: 0 | T31: 0 | U31: 0 | V31: 0 | W31: 0 | X31: 0 | Y31: 0 | Z31: 0 | AA31: 0 | AB31: 0 | AC31: 0 | AD31: 0 | AE31: 0 | AF31: 0 | AG31: 0 | AH31: 0 | AI31: 0 | AJ31: 0 | AK31: 0 | AL31: 0 | AM31: 0 | AN31: 0
A32: Other non-operating items | B32: a.other_nonop | H32: 0 | I32: 0 | J32: 0 | K32: 0 | L32: 0 | M32: 0 | N32: 0 | O32: 0 | P32: 0 | Q32: 0 | R32: 0 | S32: 0 | T32: 0 | U32: 0 | V32: 0 | W32: 0 | X32: 0 | Y32: 0 | Z32: 0 | AA32: 0 | AB32: 0 | AC32: 0 | AD32: 0 | AE32: 0 | AF32: 0 | AG32: 0 | AH32: 0 | AI32: 0 | AJ32: 0 | AK32: 0 | AL32: 0 | AM32: 0 | AN32: 0
A33: Minorities' share of net profit | B33: a.minority_pct | H33: 0.5 | I33: 0.5 | J33: 0.5 | K33: 0.5 | L33: 0.5 | M33: 0.5 | N33: 0.5 | O33: 0.5 | P33: 0.5 | Q33: 0.5 | R33: 0.5 | S33: 0.5 | T33: 0.5 | U33: 0.5 | V33: 0.5 | W33: 0.5 | X33: 0.5 | Y33: 0.5 | Z33: 0.5 | AA33: 0.5 | AB33: 0.5 | AC33: 0.5 | AD33: 0.5 | AE33: 0.5 | AF33: 0.5 | AG33: 0.5 | AH33: 0.5 | AI33: 0.5 | AJ33: 0.5 | AK33: 0.5 | AL33: 0.5 | AM33: 0.5 | AN33: 0.5
A34: Dividend payout | B34: a.payout | H34: 0 | I34: 0 | J34: 0 | K34: 0 | L34: 0 | M34: 0 | N34: 0 | O34: 0 | P34: 0 | Q34: 0 | R34: 0 | S34: 0 | T34: 0 | U34: 0 | V34: 0 | W34: 0 | X34: 0 | Y34: 0 | Z34: 0 | AA34: 0 | AB34: 0 | AC34: 0 | AD34: 0 | AE34: 0 | AF34: 0 | AG34: 0 | AH34: 0 | AI34: 0 | AJ34: 0 | AK34: 0 | AL34: 0 | AM34: 0 | AN34: 0
A35: Change in share count | B35: a.share_change | H35: 0 | I35: 0 | J35: 0 | K35: 0 | L35: 0 | M35: 0 | N35: 0 | O35: 0 | P35: 0 | Q35: 0 | R35: 0 | S35: 0 | T35: 0 | U35: 0 | V35: 0 | W35: 0 | X35: 0 | Y35: 0 | Z35: 0 | AA35: 0 | AB35: 0 | AC35: 0 | AD35: 0 | AE35: 0 | AF35: 0 | AG35: 0 | AH35: 0 | AI35: 0 | AJ35: 0 | AK35: 0 | AL35: 0 | AM35: 0 | AN35: 0
A36: Terminal growth (DCF) | B36: a.terminal_growth | C36: 0
A37: SG&A / revenue | B37: a.opex_pct | H37: 0.048 | I37: 0.048 | J37: 0.048 | K37: 0.048 | L37: 0.048 | M37: 0.048 | N37: 0.048 | O37: 0.048 | P37: 0.048 | Q37: 0.048 | R37: 0.048 | S37: 0.048 | T37: 0.048 | U37: 0.048 | V37: 0.048 | W37: 0.048 | X37: 0.048 | Y37: 0.048 | Z37: 0.048 | AA37: 0.048 | AB37: 0.048 | AC37: 0.048 | AD37: 0.048 | AE37: 0.048 | AF37: 0.048 | AG37: 0.048 | AH37: 0.048 | AI37: 0.048 | AJ37: 0.048 | AK37: 0.048 | AL37: 0.048 | AM37: 0.048 | AN37: 0.048
A39: MODEL
A40: Reserves remaining (close) | B40: reserves | G40: 2500 | H40: =MAX((G40-H41),0) | I40: =MAX((H40-I41),0) | J40: =MAX((I40-J41),0) | K40: =MAX((J40-K41),0) | L40: =MAX((K40-L41),0) | M40: =MAX((L40-M41),0) | N40: =MAX((M40-N41),0) | O40: =MAX((N40-O41),0) | ... AN40: =MAX((AM40-AN41),0)
A41: Sales volume | B41: volume | G41: 74.6 | H41: =IF(($C$9>0),MIN(H14,MAX(G40,0)),H14) | I41: =IF(($C$9>0),MIN(I14,MAX(H40,0)),I14) | J41: =IF(($C$9>0),MIN(J14,MAX(I40,0)),J14) | K41: =IF(($C$9>0),MIN(K14,MAX(J40,0)),K14) | L41: =IF(($C$9>0),MIN(L14,MAX(K40,0)),L14) | M41: =IF(($C$9>0),MIN(M14,MAX(L40,0)),M14) | N41: =IF(($C$9>0),MIN(N14,MAX(M40,0)),N14) | O41: =IF(($C$9>0),MIN(O14,MAX(N40,0)),O14) | ... AN41: =IF(($C$9>0),MIN(AN14,MAX(AM40,0)),AN14)
A42: Benchmark price | B42: benchmark | H42: =Drivers!$L$6 | I42: =Drivers!$M$6 | J42: =Drivers!$N$6 | K42: =Drivers!$O$6 | L42: =Drivers!$P$6 | M42: =Drivers!$Q$6 | N42: =Drivers!$R$6 | O42: =Drivers!$S$6 | P42: =Drivers!$T$6 | Q42: =Drivers!$U$6 | R42: =Drivers!$V$6 | S42: =Drivers!$W$6 | T42: =Drivers!$X$6 | U42: =Drivers!$Y$6 | V42: =Drivers!$Z$6 | W42: =Drivers!$AA$6 | X42: =Drivers!$AB$6 | Y42: =Drivers!$AC$6 | Z42: =Drivers!$AD$6 | AA42: =Drivers!$AE$6 | AB42: =Drivers!$AF$6 | AC42: =Drivers!$AG$6 | AD42: =Drivers!$AH$6 | AE42: =Drivers!$AI$6 | AF42: =Drivers!$AJ$6 | AG42: =Drivers!$AK$6 | AH42: =Drivers!$AL$6 | AI42: =Drivers!$AM$6 | AJ42: =Drivers!$AN$6 | AK42: =Drivers!$AO$6 | AL42: =Drivers!$AP$6 | AM42: =Drivers!$AQ$6 | AN42: =Drivers!$AR$6
