Workbook

Sheet README
A1: Six South — Coal distribution, trading & logistics industry model
A2: Generated 2026-10-30T07:57:06+07:00 by the coverage engine. The engine (scripts/cov_engine.py) is the source of truth; this workbook is a live rendering of it.
A3: Colour key: blue = input or hard-coded history; black = formula; green = link to another sheet.
A4: Drivers: every deck variable these models read. Change one and every ticker tab and the Comps sheet recalculate (forecasts, cash flows, DCF value, base-case value, target, rating).
A5: Scenario (bear/bull) and sensitivity tables need full model re-runs and are engine values.
A6: Paper fund — research for education and process transparency, not investment advice.
A8: Tickers:
A9: ALII.JK — PT Ancara Logistics Indonesia Tbk
A10: BBRM.JK — PT Pelayaran Nasional Bina Buana Raya Tbk
A11: BESS.JK — PT Batulicin Nusantara Maritim Tbk
A12: DWGL.JK — PT Dwi Guna Laksana Tbk
A13: FIRE.JK — PT Alfa Energi Investama Tbk
A14: SGER.JK — PT Sumber Global Energy Tbk

Sheet Drivers
A1: Driver decks (state/drivers) — edit a blue cell to flow it through every ticker tab
A3: Variable | B3: Key | C3: Unit / status | D3: FY2022A | E3: FY2023A | F3: FY2024A | G3: FY2025A | H3: FY2026E | I3: FY2027E | J3: FY2028E | K3: FY2029E | L3: FY2030E | M3: FY2031E | N3: FY2032E | O3: FY2033E | P3: FY2034E | Q3: FY2035E
A4: Newcastle 6,000 kcal/kg NAR thermal coal | B4: d.coal.newc | C4: USD/t · reviewed | F4: 136.1 | G4: 108.4 | H4: 137 | I4: 118 | J4: 110 | K4: 105 | L4: 107.1 | M4: 109.242 | N4: 111.42684 | O4: 113.65538 | P4: 115.92848 | Q4: 118.24705
A5: IDR per USD | B5: m.usd_idr | C5: IDR/USD · reviewed | D5: 14843.177 | E5: 15228.8 | F5: 15846.238 | G5: 16448.093 | H5: 17570 | I5: 18350 | J5: 18600 | K5: 18850 | L5: 19093.137 | M5: 19186.731 | N5: 19280.784 | O5: 19375.297 | P5: 19470.274 | Q5: 19565.717
A6: Brent crude | B6: d.oil.brent | C6: USD/bbl · reviewed | D6: 98.9663 | E6: 82.1904 | F6: 79.8213 | G6: 68.1015 | H6: 96 | I6: 84 | J6: 80 | K6: 78 | L6: 76.5 | M6: 78.03 | N6: 79.5906 | O6: 81.182412 | P6: 82.80606 | Q6: 84.462181
A8: Cost-of-capital scalars (macro deck)
A9: 10-year Indonesian government bond yield (IDR) | B9: m.rf_idr | C9: 0.0745 | D9: investor.id — "Yield SUN 7,45%, Saatnya Borong atau Tunggu Lebih Tinggi?" (25 Okt 2026 20:58 WIB; deck source S3); corroborated by kalderanews S1 (10Y SUN 7.41%
A10: 10-year US Treasury yield | B10: m.rf_usd | C10: 0.04989 | D10: Yahoo Finance ^TNX (US 10-year Treasury yield)
A11: Indonesia sovereign default spread (Damodaran) | B11: m.default_spread_id | C11: 0.0162 | D11: Damodaran country risk premiums (https://pages.stern.nyu.edu/~adamodar/New_Home_Page/datafile/ctryprem.html), page dated January 5, 2026, read 2026-10-30
A12: Mature-market equity risk premium (Damodaran) | B12: m.erp_mature | C12: 0.0423 | D12: Damodaran country risk premiums (https://pages.stern.nyu.edu/~adamodar/New_Home_Page/datafile/ctryprem.html), page dated January 5, 2026, read 2026-10-30
A13: Indonesia country risk premium (Damodaran) | B13: m.crp_id | C13: 0.0246 | D13: Damodaran country risk premiums (https://pages.stern.nyu.edu/~adamodar/New_Home_Page/datafile/ctryprem.html), page dated January 5, 2026, read 2026-10-30
A14: House pre-tax corporate debt spread over the risk-free | B14: m.debt_spread_corp | C14: 0.02 | D14: SEED house assumption pending the macro desk: 200 bp over the risk-free rate for an average IDX corporate borrower
A15: Indonesia statutory corporate income tax rate | B15: m.tax_rate_id | C15: 0.22 | D15: Law 7/2021 on Harmonisation of Tax Regulations (UU HPP): 22% corporate income tax from fiscal 2022

Sheet Comps
A1: Ticker | B1: Company | C1: Rating | D1: Target (IDR) | E1: Price (IDR) | F1: Exp. 12m TR | G1: Value today | H1: P/E FY+0 | I1: EV/EBITDA FY+0 | J1: Div. yield FY+0
A2: ALII.JK | B2: PT Ancara Logistics Indonesia Tbk | C2: ='ALII'!$C$151 | D2: ='ALII'!$C$149 | E2: ='ALII'!$C$80 | F2: ='ALII'!$C$150 | G2: ='ALII'!$C$130 | H2: 30.913676 | I2: 28.567517 | J2: 0.017791
A3: BBRM.JK | B3: PT Pelayaran Nasional Bina Buana Raya Tbk | C3: ='BBRM'!$C$141 | D3: ='BBRM'!$C$139 | E3: ='BBRM'!$C$79 | F3: ='BBRM'!$C$140 | G3: ='BBRM'!$C$129 | H3: 8.560511 | I3: 4.591957 | J3: 0
A4: BESS.JK | B4: PT Batulicin Nusantara Maritim Tbk | C4: ='BESS'!$C$136 | D4: ='BESS'!$C$134 | E4: ='BESS'!$C$80 | F4: ='BESS'!$C$135 | G4: ='BESS'!$C$124 | I4: 84.551403 | J4: 0
A5: DWGL.JK | B5: PT Dwi Guna Laksana Tbk | C5: ='DWGL'!$C$142 | D5: ='DWGL'!$C$140 | E5: ='DWGL'!$C$80 | F5: ='DWGL'!$C$141 | G5: ='DWGL'!$C$130 | H5: 8.431587 | I5: 4.622804 | J5: 0
A6: FIRE.JK | B6: PT Alfa Energi Investama Tbk | C6: ='FIRE'!$C$152 | D6: ='FIRE'!$C$150 | E6: ='FIRE'!$C$83 | F6: ='FIRE'!$C$151 | G6: ='FIRE'!$C$140 | H6: 10.959457 | I6: 3.947332 | J6: 0
A7: SGER.JK | B7: PT Sumber Global Energy Tbk | C7: ='SGER'!$C$135 | D7: ='SGER'!$C$133 | E7: ='SGER'!$C$79 | F7: ='SGER'!$C$134 | G7: ='SGER'!$C$123 | H7: 64.637656 | I7: 31.814343 | J7: 0.002321

Sheet ALII
A1: PT Ancara Logistics Indonesia Tbk (ALII.JK) — Coal distribution, trading & logistics
A2: Units: IDR bn; per-share in IDR unless marked IDR. Model asof 2026-10-30 · data 2026-10-28
A4: Line | C4: Scalar | D4: FY2022A | E4: FY2023A | F4: FY2024A | G4: FY2025A | H4: FY2026E | I4: FY2027E | J4: FY2028E | K4: FY2029E | L4: FY2030E | M4: FY2031E | N4: FY2032E | O4: FY2033E | P4: FY2034E | Q4: FY2035E
A6: PARAMETERS
A7: horizon | C7: 10
A8: ps_factor | C8: 1000
A9: vp_factor | C9: 1
A11: INPUTS (company assumptions)
A12: Revenue growth | B12: a.revenue_growth | H12: -0.151 | I12: 0.08 | J12: 0.08 | K12: 0.06 | L12: 0.05 | M12: 0.04 | N12: 0.04 | O12: 0.04 | P12: 0.04 | Q12: 0.04
A13: Gross margin at base input costs | B13: a.gross_margin | H13: 0.452 | I13: 0.45 | J13: 0.45 | K13: 0.45 | L13: 0.45 | M13: 0.45 | N13: 0.45 | O13: 0.45 | P13: 0.45 | Q13: 0.45
A14: Cost link 1: share of COGS exposed | B14: a.link1_share | C14: 0
A15: Cost link 1: pass-through to prices | B15: a.link1_pass | C15: 0
A16: Cost link 2: share of COGS exposed | B16: a.link2_share | C16: 0.228
A17: Cost link 2: pass-through to prices | B17: a.link2_pass | C17: 1
A18: SG&A / revenue | B18: a.opex_pct | H18: 0.095 | I18: 0.09 | J18: 0.086 | K18: 0.085 | L18: 0.085 | M18: 0.085 | N18: 0.085 | O18: 0.085 | P18: 0.085 | Q18: 0.085
A19: D&A / revenue | B19: a.da_pct | H19: 0.07 | I19: 0.07 | J19: 0.069 | K19: 0.068 | L19: 0.067 | M19: 0.065 | N19: 0.065 | O19: 0.065 | P19: 0.065 | Q19: 0.065
A20: Capex / revenue | B20: a.capex_pct | H20: 0.14 | I20: 0.12 | J20: 0.1 | K20: 0.09 | L20: 0.09 | M20: 0.08 | N20: 0.08 | O20: 0.08 | P20: 0.08 | Q20: 0.08
A21: Operating working capital / revenue | B21: a.nwc_pct | H21: 0.38 | I21: 0.38 | J21: 0.38 | K21: 0.38 | L21: 0.38 | M21: 0.38 | N21: 0.38 | O21: 0.38 | P21: 0.38 | Q21: 0.38
A22: Effective tax rate | B22: a.tax_rate | H22: 0.182 | I22: 0.182 | J22: 0.182 | K22: 0.182 | L22: 0.182 | M22: 0.182 | N22: 0.182 | O22: 0.182 | P22: 0.182 | Q22: 0.182
A23: Cost of debt (on opening debt) | B23: a.cost_of_debt | C23: 0.075
A24: Yield on opening cash | B24: a.cash_yield | C24: 0.035
A25: Net new borrowing | B25: a.net_borrowing | H25: 30 | I25: 20 | J25: 10 | K25: 0 | L25: 0 | M25: 0 | N25: 0 | O25: 0 | P25: 0 | Q25: 0
A26: Other non-operating items | B26: a.other_nonop | H26: 160 | I26: 150 | J26: 140 | K26: 130 | L26: 120 | M26: 112.75 | N26: 115.56875 | O26: 118.45797 | P26: 121.41942 | Q26: 124.4549
A27: Minorities' share of net profit | B27: a.minority_pct | H27: 0.11 | I27: 0.11 | J27: 0.11 | K27: 0.11 | L27: 0.11 | M27: 0.11 | N27: 0.11 | O27: 0.11 | P27: 0.11 | Q27: 0.11
A28: Dividend payout | B28: a.payout | H28: 0.55 | I28: 0.55 | J28: 0.55 | K28: 0.55 | L28: 0.55 | M28: 0.55 | N28: 0.55 | O28: 0.55 | P28: 0.55 | Q28: 0.55
A29: Change in share count | B29: a.share_change | H29: 0 | I29: 0 | J29: 0 | K29: 0 | L29: 0 | M29: 0 | N29: 0 | O29: 0 | P29: 0 | Q29: 0
A30: Terminal growth (DCF) | B30: a.terminal_growth | C30: 0.035
A32: MODEL
A33: Revenue | B33: revenue | D33: 670.12038 | E33: 931.0058 | F33: 920.55202 | G33: 970.22898 | H33: =(G33*(1+H12)) | I33: =(H33*(1+I12)) | J33: =(I33*(1+J12)) | K33: =(J33*(1+K12)) | L33: =(K33*(1+L12)) | M33: =(L33*(1+M12)) | N33: =(M33*(1+N12)) | O33: =(N33*(1+O12)) | ... Q33: =(P33*(1+Q12))
A34: Cost of revenue | B34: cogs | D34: 368.90399 | E34: 554.12857 | F34: 519.62428 | G34: 529.83922 | H34: =((H33*(1-H13))*((1+(($C$14*(1-$C$15))*(IF(Drivers!$G$4=0,0,Drivers!$H$4/Drivers!$G$4)-1)))+(($C$16*(1-$C$17))*(IF(Drivers!$G$6=0,0,Drivers!$H$6/Drivers!$G$6)-1)))) | I34: =((I33*(1-I13))*((1+(($C$14*(1-$C$15))*(IF(Drivers!$G$4=0,0,Drivers!$I$4/Drivers!$G$4)-1)))+(($C$16*(1-$C$17))*(IF(Drivers!$G$6=0,0,Drivers!$I$6/Drivers!$G$6)-1)))) | J34: =((J33*(1-J13))*((1+(($C$14*(1-$C$15))*(IF(Drivers!$G$4=0,0,Drivers!$J$4/Drivers!$G$4)-1)))+(($C$16*(1-$C$17))*(IF(Drivers!$G$6=0,0,Drivers!$J$6/Drivers!$G$6)-1)))) | K34: =((K33*(1-K13))*((1+(($C$14*(1-$C$15))*(IF(Drivers!$G$4=0,0,Drivers!$K$4/Drivers!$G$4)-1)))+(($C$16*(1-$C$17))*(IF(Drivers!$G$6=0,0,Drivers!$K$6/Drivers!$G$6)-1)))) | L34: =((L33*(1-L13))*((1+(($C$14*(1-$C$15))*(IF(Drivers!$G$4=0,0,Drivers!$L$4/Drivers!$G$4)-1)))+(($C$16*(1-$C$17))*(IF(Drivers!$G$6=0,0,Drivers!$L$6/Drivers!$G$6)-1)))) | M34: =((M33*(1-M13))*((1+(($C$14*(1-$C$15))*(IF(Drivers!$G$4=0,0,Drivers!$M$4/Drivers!$G$4)-1)))+(($C$16*(1-$C$17))*(IF(Drivers!$G$6=0,0,Drivers!$M$6/Drivers!$G$6)-1)))) | N34: =((N33*(1-N13))*((1+(($C$14*(1-$C$15))*(IF(Drivers!$G$4=0,0,Drivers!$N$4/Drivers!$G$4)-1)))+(($C$16*(1-$C$17))*(IF(Drivers!$G$6=0,0,Drivers!$N$6/Drivers!$G$6)-1)))) | O34: =((O33*(1-O13))*((1+(($C$14*(1-$C$15))*(IF(Drivers!$G$4=0,0,Drivers!$O$4/Drivers!$G$4)-1)))+(($C$16*(1-$C$17))*(IF(Drivers!$G$6=0,0,Drivers!$O$6/Drivers!$G$6)-1)))) | P34: =((P33*(1-P13))*((1+(($C$14*(1-$C$15))*(IF(Drivers!$G$4=0,0,Drivers!$P$4/Drivers!$G$4)-1)))+(($C$16*(1-$C$17))*(IF(Drivers!$G$6=0,0,Drivers!$P$6/Drivers!$G$6)-1)))) | Q34: =((Q33*(1-Q13))*((1+(($C$14*(1-$C$15))*(IF(Drivers!$G$4=0,0,Drivers!$Q$4/Drivers!$G$4)-1)))+(($C$16*(1-$C$17))*(IF(Drivers!$G$6=0,0,Drivers!$Q$6/Drivers!$G$6)-1))))
A35: Gross profit | B35: gross_profit | D35: 301.21639 | E35: 376.87723 | F35: 400.92774 | G35: 440.38975 | H35: =(H33-H34) | I35: =(I33-I34) | J35: =(J33-J34) | K35: =(K33-K34) | L35: =(L33-L34) | M35: =(M33-M34) | N35: =(N33-N34) | O35: =(O33-O34) | ... Q35: =(Q33-Q34)
A36: SG&A and other opex | B36: opex | D36: 67.885024 | E36: 110.80738 | F36: 78.856851 | G36: 80.823571 | H36: =(H33*H18) | I36: =(I33*I18) | J36: =(J33*J18) | K36: =(K33*K18) | L36: =(L33*L18) | M36: =(M33*M18) | N36: =(N33*N18) | O36: =(O33*O18) | ... Q36: =(Q33*Q18)
A37: EBIT | B37: ebit | D37: 233.33137 | E37: 266.06985 | F37: 322.07089 | G37: 359.56618 | H37: =(H35-H36) | I37: =(I35-I36) | J37: =(J35-J36) | K37: =(K35-K36) | L37: =(L35-L36) | M37: =(M35-M36) | N37: =(N35-N36) | O37: =(O35-O36) | ... Q37: =(Q35-Q36)
A38: Depreciation & amortisation | B38: da | F38: 59.761053 | G38: 65.913717 | H38: =(H33*H19) | I38: =(I33*I19) | J38: =(J33*J19) | K38: =(K33*K19) | L38: =(L33*L19) | M38: =(M33*M19) | N38: =(N33*N19) | O38: =(O33*O19) | ... Q38: =(Q33*Q19)
A39: EBITDA | B39: ebitda | F39: 381.83194 | G39: 425.4799 | H39: =(H37+H38) | I39: =(I37+I38) | J39: =(J37+J38) | K39: =(K37+K38) | L39: =(L37+L38) | M39: =(M37+M38) | N39: =(N37+N38) | O39: =(O37+O38) | ... Q39: =(Q37+Q38)
A40: Interest expense | B40: interest_expense | D40: 178.49163 | E40: 193.49873 | F40: 96.39615 | G40: 34.479603 | H40: =(G60*$C$23) | I40: =(H60*$C$23) | J40: =(I60*$C$23) | K40: =(J60*$C$23) | L40: =(K60*$C$23) | M40: =(L60*$C$23) | N40: =(M60*$C$23) | O40: =(N60*$C$23) | ... Q40: =(P60*$C$23)
A41: Interest income | B41: interest_income | D41: 136.30771 | E41: 124.03175 | F41: 4.20412 | G41: 1.792778 | H41: =(G59*$C$24) | I41: =(H59*$C$24) | J41: =(I59*$C$24) | K41: =(J59*$C$24) | L41: =(K59*$C$24) | M41: =(L59*$C$24) | N41: =(M59*$C$24) | O41: =(N59*$C$24) | ... Q41: =(P59*$C$24)
A42: Other non-operating | B42: other_nonop | D42: -43.94857 | E42: -2.404654 | F42: 108.45776 | G42: 170.06969 | H42: =H26 | I42: =I26 | J42: =J26 | K42: =K26 | L42: =L26 | M42: =M26 | N42: =N26 | O42: =O26 | ... Q42: =Q26
A43: Profit before tax | B43: pbt | D43: 147.19887 | E43: 194.19821 | F43: 338.33661 | G43: 496.94905 | H43: =(((H37-H40)+H41)+H42) | I43: =(((I37-I40)+I41)+I42) | J43: =(((J37-J40)+J41)+J42) | K43: =(((K37-K40)+K41)+K42) | L43: =(((L37-L40)+L41)+L42) | M43: =(((M37-M40)+M41)+M42) | N43: =(((N37-N40)+N41)+N42) | O43: =(((O37-O40)+O41)+O42) | ... Q43: =(((Q37-Q40)+Q41)+Q42)
A44: Tax | B44: tax | D44: -4.617118 | E44: 11.287891 | F44: 38.736482 | G44: 74.073666 | H44: =(MAX(H43,0)*H22) | I44: =(MAX(I43,0)*I22) | J44: =(MAX(J43,0)*J22) | K44: =(MAX(K43,0)*K22) | L44: =(MAX(L43,0)*L22) | M44: =(MAX(M43,0)*M22) | N44: =(MAX(N43,0)*N22) | O44: =(MAX(O43,0)*O22) | ... Q44: =(MAX(Q43,0)*Q22)
...

Sheet BBRM
A1: PT Pelayaran Nasional Bina Buana Raya Tbk (BBRM.JK) — Coal distribution, trading & logistics
A2: Units: USD m; per-share in USD unless marked IDR. Model asof 2026-10-30 · data 2026-10-28
A4: Line | C4: Scalar | D4: FY2022A | E4: FY2023A | F4: FY2024A | G4: FY2025A | H4: FY2026E | I4: FY2027E | J4: FY2028E | K4: FY2029E | L4: FY2030E | M4: FY2031E | N4: FY2032E | O4: FY2033E | P4: FY2034E | Q4: FY2035E
A6: PARAMETERS
A7: ps_factor | C7: 1
A8: vp_factor | C8: 1
A10: INPUTS (company assumptions)
A11: Revenue growth | B11: a.revenue_growth | H11: 0.0296 | I11: 0.1036 | J11: 0.03 | K11: 0.03 | L11: 0.03 | M11: 0.03 | N11: 0.03 | O11: 0.03 | P11: 0.03 | Q11: 0.03
A12: Gross margin at base input costs | B12: a.gross_margin | H12: 0.468 | I12: 0.475 | J12: 0.475 | K12: 0.475 | L12: 0.475 | M12: 0.475 | N12: 0.475 | O12: 0.475 | P12: 0.475 | Q12: 0.475
A13: Cost link 1: share of COGS exposed | B13: a.link1_share | C13: 0
A14: Cost link 1: pass-through to prices | B14: a.link1_pass | C14: 0
A15: Cost link 2: share of COGS exposed | B15: a.link2_share | C15: 0.12
A16: Cost link 2: pass-through to prices | B16: a.link2_pass | C16: 0
A17: SG&A / revenue | B17: a.opex_pct | H17: 0.085 | I17: 0.085 | J17: 0.085 | K17: 0.085 | L17: 0.085 | M17: 0.085 | N17: 0.085 | O17: 0.085 | P17: 0.085 | Q17: 0.085
A18: D&A / revenue | B18: a.da_pct | H18: 0.143 | I18: 0.155 | J18: 0.155 | K18: 0.155 | L18: 0.155 | M18: 0.155 | N18: 0.155 | O18: 0.155 | P18: 0.155 | Q18: 0.155
A19: Capex / revenue | B19: a.capex_pct | H19: 0.3965 | I19: 0.135 | J19: 0.15 | K19: 0.155 | L19: 0.155 | M19: 0.155 | N19: 0.155 | O19: 0.155 | P19: 0.155 | Q19: 0.155
A20: Operating working capital / revenue | B20: a.nwc_pct | H20: 0.2 | I20: 0.2 | J20: 0.2 | K20: 0.2 | L20: 0.2 | M20: 0.2 | N20: 0.2 | O20: 0.2 | P20: 0.2 | Q20: 0.2
A21: Effective tax rate | B21: a.tax_rate | H21: 0.025 | I21: 0.025 | J21: 0.025 | K21: 0.025 | L21: 0.025 | M21: 0.025 | N21: 0.025 | O21: 0.025 | P21: 0.025 | Q21: 0.025
A22: Cost of debt (on opening debt) | B22: a.cost_of_debt | C22: 0.09
A23: Yield on opening cash | B23: a.cash_yield | C23: 0.034
A24: Net new borrowing | B24: a.net_borrowing | H24: 5 | I24: -1 | J24: -1 | K24: -1 | L24: -1 | M24: -1.02 | N24: -1.0404 | O24: -1.061208 | P24: -1.0824322 | Q24: -1.1040808
A25: Other non-operating items | B25: a.other_nonop | H25: 0 | I25: 0 | J25: 0 | K25: 0 | L25: 0 | M25: 0 | N25: 0 | O25: 0 | P25: 0 | Q25: 0
A26: Minorities' share of net profit | B26: a.minority_pct | H26: 0 | I26: 0 | J26: 0 | K26: 0 | L26: 0 | M26: 0 | N26: 0 | O26: 0 | P26: 0 | Q26: 0
A27: Dividend payout | B27: a.payout | H27: 0 | I27: 0 | J27: 0 | K27: 0 | L27: 0 | M27: 0 | N27: 0 | O27: 0 | P27: 0 | Q27: 0
A28: Change in share count | B28: a.share_change | H28: 0 | I28: 0 | J28: 0 | K28: 0 | L28: 0 | M28: 0 | N28: 0 | O28: 0 | P28: 0 | Q28: 0
A29: Terminal growth (DCF) | B29: a.terminal_growth | C29: 0.02
A31: MODEL
A32: Revenue | B32: revenue | D32: 9.330724 | E32: 10.545555 | F32: 13.430614 | G32: 13.818874 | H32: =(G32*(1+H11)) | I32: =(H32*(1+I11)) | J32: =(I32*(1+J11)) | K32: =(J32*(1+K11)) | L32: =(K32*(1+L11)) | M32: =(L32*(1+M11)) | N32: =(M32*(1+N11)) | O32: =(N32*(1+O11)) | ... Q32: =(P32*(1+Q11))
A33: Cost of revenue | B33: cogs | D33: 6.711475 | E33: 5.879949 | F33: 6.930319 | G33: 7.166325 | H33: =((H32*(1-H12))*((1+(($C$13*(1-$C$14))*(IF(Drivers!$G$4=0,0,Drivers!$H$4/Drivers!$G$4)-1)))+(($C$15*(1-$C$16))*(IF(Drivers!$G$6=0,0,Drivers!$H$6/Drivers!$G$6)-1)))) | I33: =((I32*(1-I12))*((1+(($C$13*(1-$C$14))*(IF(Drivers!$G$4=0,0,Drivers!$I$4/Drivers!$G$4)-1)))+(($C$15*(1-$C$16))*(IF(Drivers!$G$6=0,0,Drivers!$I$6/Drivers!$G$6)-1)))) | J33: =((J32*(1-J12))*((1+(($C$13*(1-$C$14))*(IF(Drivers!$G$4=0,0,Drivers!$J$4/Drivers!$G$4)-1)))+(($C$15*(1-$C$16))*(IF(Drivers!$G$6=0,0,Drivers!$J$6/Drivers!$G$6)-1)))) | K33: =((K32*(1-K12))*((1+(($C$13*(1-$C$14))*(IF(Drivers!$G$4=0,0,Drivers!$K$4/Drivers!$G$4)-1)))+(($C$15*(1-$C$16))*(IF(Drivers!$G$6=0,0,Drivers!$K$6/Drivers!$G$6)-1)))) | L33: =((L32*(1-L12))*((1+(($C$13*(1-$C$14))*(IF(Drivers!$G$4=0,0,Drivers!$L$4/Drivers!$G$4)-1)))+(($C$15*(1-$C$16))*(IF(Drivers!$G$6=0,0,Drivers!$L$6/Drivers!$G$6)-1)))) | M33: =((M32*(1-M12))*((1+(($C$13*(1-$C$14))*(IF(Drivers!$G$4=0,0,Drivers!$M$4/Drivers!$G$4)-1)))+(($C$15*(1-$C$16))*(IF(Drivers!$G$6=0,0,Drivers!$M$6/Drivers!$G$6)-1)))) | N33: =((N32*(1-N12))*((1+(($C$13*(1-$C$14))*(IF(Drivers!$G$4=0,0,Drivers!$N$4/Drivers!$G$4)-1)))+(($C$15*(1-$C$16))*(IF(Drivers!$G$6=0,0,Drivers!$N$6/Drivers!$G$6)-1)))) | O33: =((O32*(1-O12))*((1+(($C$13*(1-$C$14))*(IF(Drivers!$G$4=0,0,Drivers!$O$4/Drivers!$G$4)-1)))+(($C$15*(1-$C$16))*(IF(Drivers!$G$6=0,0,Drivers!$O$6/Drivers!$G$6)-1)))) | P33: =((P32*(1-P12))*((1+(($C$13*(1-$C$14))*(IF(Drivers!$G$4=0,0,Drivers!$P$4/Drivers!$G$4)-1)))+(($C$15*(1-$C$16))*(IF(Drivers!$G$6=0,0,Drivers!$P$6/Drivers!$G$6)-1)))) | Q33: =((Q32*(1-Q12))*((1+(($C$13*(1-$C$14))*(IF(Drivers!$G$4=0,0,Drivers!$Q$4/Drivers!$G$4)-1)))+(($C$15*(1-$C$16))*(IF(Drivers!$G$6=0,0,Drivers!$Q$6/Drivers!$G$6)-1))))
A34: Gross profit | B34: gross_profit | D34: 2.619249 | E34: 4.665606 | F34: 6.500295 | G34: 6.652549 | H34: =(H32-H33) | I34: =(I32-I33) | J34: =(J32-J33) | K34: =(K32-K33) | L34: =(L32-L33) | M34: =(M32-M33) | N34: =(N32-N33) | O34: =(O32-O33) | ... Q34: =(Q32-Q33)
A35: SG&A and other opex | B35: opex | D35: 0.952259 | E35: 0.88157 | F35: 0.993209 | G35: 1.196047 | H35: =(H32*H17) | I35: =(I32*I17) | J35: =(J32*J17) | K35: =(K32*K17) | L35: =(L32*L17) | M35: =(M32*M17) | N35: =(N32*N17) | O35: =(O32*O17) | ... Q35: =(Q32*Q17)
A36: EBIT | B36: ebit | D36: 1.66699 | E36: 3.784036 | F36: 5.538222 | G36: 5.474846 | H36: =(H34-H35) | I36: =(I34-I35) | J36: =(J34-J35) | K36: =(K34-K35) | L36: =(L34-L35) | M36: =(M34-M35) | N36: =(N34-N35) | O36: =(O34-O35) | ... Q36: =(Q34-Q35)
A37: Depreciation & amortisation | B37: da | D37: 0.006442 | E37: 0.004011 | F37: 2.026606 | G37: 2.033029 | H37: =(H32*H18) | I37: =(I32*I18) | J37: =(J32*J18) | K37: =(K32*K18) | L37: =(L32*L18) | M37: =(M32*M18) | N37: =(N32*N18) | O37: =(O32*O18) | ... Q37: =(Q32*Q18)
A38: EBITDA | B38: ebitda | D38: 1.673432 | E38: 3.788047 | F38: 7.564828 | G38: 7.507875 | H38: =(H36+H37) | I38: =(I36+I37) | J38: =(J36+J37) | K38: =(K36+K37) | L38: =(L36+L37) | M38: =(M36+M37) | N38: =(N36+N37) | O38: =(O36+O37) | ... Q38: =(Q36+Q37)
A39: Interest expense | B39: interest_expense | D39: 0.263353 | E39: 0.163588 | F39: 0.177602 | G39: 0.371307 | H39: =(G59*$C$22) | I39: =(H59*$C$22) | J39: =(I59*$C$22) | K39: =(J59*$C$22) | L39: =(K59*$C$22) | M39: =(L59*$C$22) | N39: =(M59*$C$22) | O39: =(N59*$C$22) | ... Q39: =(P59*$C$22)
A40: Interest income | B40: interest_income | D40: 0.102216 | E40: 0.096194 | F40: 0.342523 | G40: 0.377128 | H40: =(G58*$C$23) | I40: =(H58*$C$23) | J40: =(I58*$C$23) | K40: =(J58*$C$23) | L40: =(K58*$C$23) | M40: =(L58*$C$23) | N40: =(M58*$C$23) | O40: =(N58*$C$23) | ... Q40: =(P58*$C$23)
A41: Other non-operating | B41: other_nonop | D41: -0.700542 | E41: 0.452509 | F41: 2.681484 | G41: 0.946434 | H41: =H25 | I41: =I25 | J41: =J25 | K41: =K25 | L41: =L25 | M41: =M25 | N41: =N25 | O41: =O25 | ... Q41: =Q25
A42: Profit before tax | B42: pbt | D42: 0.805311 | E42: 4.169151 | F42: 8.384627 | G42: 6.427101 | H42: =(((H36-H39)+H40)+H41) | I42: =(((I36-I39)+I40)+I41) | J42: =(((J36-J39)+J40)+J41) | K42: =(((K36-K39)+K40)+K41) | L42: =(((L36-L39)+L40)+L41) | M42: =(((M36-M39)+M40)+M41) | N42: =(((N36-N39)+N40)+N41) | O42: =(((O36-O39)+O40)+O41) | ... Q42: =(((Q36-Q39)+Q40)+Q41)
A43: Tax | B43: tax | D43: 0.112989 | E43: 0.129075 | F43: 0.151121 | G43: 0.1574 | H43: =(MAX(H42,0)*H21) | I43: =(MAX(I42,0)*I21) | J43: =(MAX(J42,0)*J21) | K43: =(MAX(K42,0)*K21) | L43: =(MAX(L42,0)*L21) | M43: =(MAX(M42,0)*M21) | N43: =(MAX(N42,0)*N21) | O43: =(MAX(O42,0)*O21) | ... Q43: =(MAX(Q42,0)*Q21)
A44: Net profit (incl. minorities) | B44: np | D44: 0.692322 | E44: 4.040076 | F44: 8.233506 | G44: 6.269701 | H44: =(H42-H43) | I44: =(I42-I43) | J44: =(J42-J43) | K44: =(K42-K43) | L44: =(L42-L43) | M44: =(M42-M43) | N44: =(N42-N43) | O44: =(O42-O43) | ... Q44: =(Q42-Q43)
...

Sheet BESS
A1: PT Batulicin Nusantara Maritim Tbk (BESS.JK) — Coal distribution, trading & logistics
A2: Units: IDR bn; per-share in IDR unless marked IDR. Model asof 2026-10-30 · data 2026-10-28
A4: Line | C4: Scalar | D4: FY2023A | E4: FY2024A | F4: FY2025A | G4: FY2026E | H4: FY2027E | I4: FY2028E | J4: FY2029E | K4: FY2030E | L4: FY2031E | M4: FY2032E | N4: FY2033E | O4: FY2034E | P4: FY2035E
A6: PARAMETERS
A7: horizon | C7: 10
A8: ps_factor | C8: 1000
A9: vp_factor | C9: 1
A11: INPUTS (company assumptions)
A12: Revenue growth | B12: a.revenue_growth | G12: -0.376 | H12: 0.16 | I12: 0.08 | J12: 0.04 | K12: 0.03 | L12: 0.03 | M12: 0.03 | N12: 0.03 | O12: 0.03 | P12: 0.03
A13: Gross margin at base input costs | B13: a.gross_margin | G13: 0.215 | H13: 0.28 | I13: 0.31 | J13: 0.33 | K13: 0.33 | L13: 0.33 | M13: 0.33 | N13: 0.33 | O13: 0.33 | P13: 0.33
A14: Cost link 1: share of COGS exposed | B14: a.link1_share | C14: 0.06
A15: Cost link 1: pass-through to prices | B15: a.link1_pass | C15: 0.6
A16: Cost link 2: share of COGS exposed | B16: a.link2_share | C16: 0.26
A17: Cost link 2: pass-through to prices | B17: a.link2_pass | C17: 0.5
A18: SG&A / revenue | B18: a.opex_pct | G18: 0.215 | H18: 0.185 | I18: 0.17 | J18: 0.16 | K18: 0.155 | L18: 0.155 | M18: 0.155 | N18: 0.155 | O18: 0.155 | P18: 0.155
A19: D&A / revenue | B19: a.da_pct | G19: 0.17 | H19: 0.148 | I19: 0.137 | J19: 0.131 | K19: 0.127 | L19: 0.127 | M19: 0.127 | N19: 0.127 | O19: 0.127 | P19: 0.127
A20: Capex / revenue | B20: a.capex_pct | G20: 0.08 | H20: 0.08 | I20: 0.08 | J20: 0.08 | K20: 0.08 | L20: 0.08 | M20: 0.08 | N20: 0.08 | O20: 0.08 | P20: 0.08
A21: Operating working capital / revenue | B21: a.nwc_pct | G21: 0.346 | H21: 0.346 | I21: 0.346 | J21: 0.346 | K21: 0.346 | L21: 0.346 | M21: 0.346 | N21: 0.346 | O21: 0.346 | P21: 0.346
A22: Effective tax rate | B22: a.tax_rate | G22: 0 | H22: 0.168 | I22: 0.097 | J22: 0.076 | K22: 0.073 | L22: 0.07 | M22: 0.07 | N22: 0.07 | O22: 0.07 | P22: 0.07
A23: Cost of debt (on opening debt) | B23: a.cost_of_debt | C23: 0.08
A24: Yield on opening cash | B24: a.cash_yield | C24: 0.025
A25: Net new borrowing | B25: a.net_borrowing | G25: 0 | H25: 0 | I25: 0 | J25: 0 | K25: 0 | L25: 0 | M25: 0 | N25: 0 | O25: 0 | P25: 0
A26: Other non-operating items | B26: a.other_nonop | G26: -6.5 | H26: -6.5 | I26: -6.5 | J26: -6.5 | K26: -6.5 | L26: -6.6625 | M26: -6.8290625 | N26: -6.9997891 | O26: -7.1747838 | P26: -7.3541534
A27: Minorities' share of net profit | B27: a.minority_pct | G27: 0.0008 | H27: 0.0008 | I27: 0.0008 | J27: 0.0008 | K27: 0.0008 | L27: 0.0008 | M27: 0.0008 | N27: 0.0008 | O27: 0.0008 | P27: 0.0008
A28: Dividend payout | B28: a.payout | G28: 0.25 | H28: 0.25 | I28: 0.25 | J28: 0.25 | K28: 0.25 | L28: 0.25 | M28: 0.25 | N28: 0.25 | O28: 0.25 | P28: 0.25
A29: Change in share count | B29: a.share_change | G29: 0 | H29: 0 | I29: 0 | J29: 0 | K29: 0 | L29: 0 | M29: 0 | N29: 0 | O29: 0 | P29: 0
A30: Terminal growth (DCF) | B30: a.terminal_growth | C30: 0.03
A32: MODEL
A33: Revenue | B33: revenue | D33: 363.74118 | E33: 318.86883 | F33: 353.69647 | G33: =(F33*(1+G12)) | H33: =(G33*(1+H12)) | I33: =(H33*(1+I12)) | J33: =(I33*(1+J12)) | K33: =(J33*(1+K12)) | L33: =(K33*(1+L12)) | M33: =(L33*(1+M12)) | N33: =(M33*(1+N12)) | ... P33: =(O33*(1+P12))
A34: Cost of revenue | B34: cogs | D34: 234.22518 | E34: 219.96301 | F34: 221.68918 | G34: =((G33*(1-G13))*((1+(($C$14*(1-$C$15))*(IF(Drivers!$G$4=0,0,Drivers!$H$4/Drivers!$G$4)-1)))+(($C$16*(1-$C$17))*(IF(Drivers!$G$6=0,0,Drivers!$H$6/Drivers!$G$6)-1)))) | H34: =((H33*(1-H13))*((1+(($C$14*(1-$C$15))*(IF(Drivers!$G$4=0,0,Drivers!$I$4/Drivers!$G$4)-1)))+(($C$16*(1-$C$17))*(IF(Drivers!$G$6=0,0,Drivers!$I$6/Drivers!$G$6)-1)))) | I34: =((I33*(1-I13))*((1+(($C$14*(1-$C$15))*(IF(Drivers!$G$4=0,0,Drivers!$J$4/Drivers!$G$4)-1)))+(($C$16*(1-$C$17))*(IF(Drivers!$G$6=0,0,Drivers!$J$6/Drivers!$G$6)-1)))) | J34: =((J33*(1-J13))*((1+(($C$14*(1-$C$15))*(IF(Drivers!$G$4=0,0,Drivers!$K$4/Drivers!$G$4)-1)))+(($C$16*(1-$C$17))*(IF(Drivers!$G$6=0,0,Drivers!$K$6/Drivers!$G$6)-1)))) | K34: =((K33*(1-K13))*((1+(($C$14*(1-$C$15))*(IF(Drivers!$G$4=0,0,Drivers!$L$4/Drivers!$G$4)-1)))+(($C$16*(1-$C$17))*(IF(Drivers!$G$6=0,0,Drivers!$L$6/Drivers!$G$6)-1)))) | L34: =((L33*(1-L13))*((1+(($C$14*(1-$C$15))*(IF(Drivers!$G$4=0,0,Drivers!$M$4/Drivers!$G$4)-1)))+(($C$16*(1-$C$17))*(IF(Drivers!$G$6=0,0,Drivers!$M$6/Drivers!$G$6)-1)))) | M34: =((M33*(1-M13))*((1+(($C$14*(1-$C$15))*(IF(Drivers!$G$4=0,0,Drivers!$N$4/Drivers!$G$4)-1)))+(($C$16*(1-$C$17))*(IF(Drivers!$G$6=0,0,Drivers!$N$6/Drivers!$G$6)-1)))) | N34: =((N33*(1-N13))*((1+(($C$14*(1-$C$15))*(IF(Drivers!$G$4=0,0,Drivers!$O$4/Drivers!$G$4)-1)))+(($C$16*(1-$C$17))*(IF(Drivers!$G$6=0,0,Drivers!$O$6/Drivers!$G$6)-1)))) | O34: =((O33*(1-O13))*((1+(($C$14*(1-$C$15))*(IF(Drivers!$G$4=0,0,Drivers!$P$4/Drivers!$G$4)-1)))+(($C$16*(1-$C$17))*(IF(Drivers!$G$6=0,0,Drivers!$P$6/Drivers!$G$6)-1)))) | P34: =((P33*(1-P13))*((1+(($C$14*(1-$C$15))*(IF(Drivers!$G$4=0,0,Drivers!$Q$4/Drivers!$G$4)-1)))+(($C$16*(1-$C$17))*(IF(Drivers!$G$6=0,0,Drivers!$Q$6/Drivers!$G$6)-1))))
A35: Gross profit | B35: gross_profit | D35: 129.516 | E35: 98.905824 | F35: 132.00729 | G35: =(G33-G34) | H35: =(H33-H34) | I35: =(I33-I34) | J35: =(J33-J34) | K35: =(K33-K34) | L35: =(L33-L34) | M35: =(M33-M34) | N35: =(N33-N34) | ... P35: =(P33-P34)
A36: SG&A and other opex | B36: opex | D36: 47.420397 | E36: 56.774903 | F36: 53.13861 | G36: =(G33*G18) | H36: =(H33*H18) | I36: =(I33*I18) | J36: =(J33*J18) | K36: =(K33*K18) | L36: =(L33*L18) | M36: =(M33*M18) | N36: =(N33*N18) | ... P36: =(P33*P18)
A37: EBIT | B37: ebit | D37: 82.095605 | E37: 42.130921 | F37: 78.868681 | G37: =(G35-G36) | H37: =(H35-H36) | I37: =(I35-I36) | J37: =(J35-J36) | K37: =(K35-K36) | L37: =(L35-L36) | M37: =(M35-M36) | N37: =(N35-N36) | ... P37: =(P35-P36)
A38: Depreciation & amortisation | B38: da | D38: 39.469601 | E38: 39.376499 | F38: 39.465717 | G38: =(G33*G19) | H38: =(H33*H19) | I38: =(I33*I19) | J38: =(J33*J19) | K38: =(K33*K19) | L38: =(L33*L19) | M38: =(M33*M19) | N38: =(N33*N19) | ... P38: =(P33*P19)
A39: EBITDA | B39: ebitda | D39: 121.56521 | E39: 81.50742 | F39: 118.3344 | G39: =(G37+G38) | H39: =(H37+H38) | I39: =(I37+I38) | J39: =(J37+J38) | K39: =(K37+K38) | L39: =(L37+L38) | M39: =(M37+M38) | N39: =(N37+N38) | ... P39: =(P37+P38)
A40: Interest expense | B40: interest_expense | D40: 14.376516 | E40: 6.5043221 | F40: 2.1308871 | G40: =(F60*$C$23) | H40: =(G60*$C$23) | I40: =(H60*$C$23) | J40: =(I60*$C$23) | K40: =(J60*$C$23) | L40: =(K60*$C$23) | M40: =(L60*$C$23) | N40: =(M60*$C$23) | ... P40: =(O60*$C$23)
A41: Interest income | B41: interest_income | D41: 1.2458955 | E41: 0.82070621 | F41: 2.1613818 | G41: =(F59*$C$24) | H41: =(G59*$C$24) | I41: =(H59*$C$24) | J41: =(I59*$C$24) | K41: =(J59*$C$24) | L41: =(K59*$C$24) | M41: =(L59*$C$24) | N41: =(M59*$C$24) | ... P41: =(O59*$C$24)
A42: Other non-operating | B42: other_nonop | D42: 12.129067 | E42: -6.2693303 | F42: -15.267172 | G42: =G26 | H42: =H26 | I42: =I26 | J42: =J26 | K42: =K26 | L42: =L26 | M42: =M26 | N42: =N26 | ... P42: =P26
A43: Profit before tax | B43: pbt | D43: 81.094052 | E43: 30.177974 | F43: 63.632004 | G43: =(((G37-G40)+G41)+G42) | H43: =(((H37-H40)+H41)+H42) | I43: =(((I37-I40)+I41)+I42) | J43: =(((J37-J40)+J41)+J42) | K43: =(((K37-K40)+K41)+K42) | L43: =(((L37-L40)+L41)+L42) | M43: =(((M37-M40)+M41)+M42) | N43: =(((N37-N40)+N41)+N42) | ... P43: =(((P37-P40)+P41)+P42)
A44: Tax | B44: tax | D44: 1.644017 | E44: 5.9364555 | F44: 0 | G44: =(MAX(G43,0)*G22) | H44: =(MAX(H43,0)*H22) | I44: =(MAX(I43,0)*I22) | J44: =(MAX(J43,0)*J22) | K44: =(MAX(K43,0)*K22) | L44: =(MAX(L43,0)*L22) | M44: =(MAX(M43,0)*M22) | N44: =(MAX(N43,0)*N22) | ... P44: =(MAX(P43,0)*P22)
...

Sheet DWGL
A1: PT Dwi Guna Laksana Tbk (DWGL.JK) — Coal distribution, trading & logistics
A2: Units: IDR bn; per-share in IDR unless marked IDR. Model asof 2026-10-30 · data 2026-10-30
A4: Line | C4: Scalar | D4: FY2022A | E4: FY2023A | F4: FY2024A | G4: FY2025A | H4: FY2026E | I4: FY2027E | J4: FY2028E | K4: FY2029E | L4: FY2030E | M4: FY2031E | N4: FY2032E | O4: FY2033E | P4: FY2034E | Q4: FY2035E
A6: PARAMETERS
A7: horizon | C7: 10
A8: ps_factor | C8: 1000
A9: vp_factor | C9: 1
A11: INPUTS (company assumptions)
A12: Revenue growth | B12: a.revenue_growth | H12: 0.05 | I12: 0.04 | J12: 0.03 | K12: 0.03 | L12: 0.03 | M12: 0.03 | N12: 0.03 | O12: 0.03 | P12: 0.03 | Q12: 0.03
A13: Gross margin at base input costs | B13: a.gross_margin | H13: 0.1164 | I13: 0.1164 | J13: 0.1164 | K13: 0.1164 | L13: 0.1164 | M13: 0.1164 | N13: 0.1164 | O13: 0.1164 | P13: 0.1164 | Q13: 0.1164
A14: Cost link 1: share of COGS exposed | B14: a.link1_share | C14: 0.837
A15: Cost link 1: pass-through to prices | B15: a.link1_pass | C15: 0.9
A16: Cost link 2: share of COGS exposed | B16: a.link2_share | C16: 0.04
A17: Cost link 2: pass-through to prices | B17: a.link2_pass | C17: 0.6
A18: SG&A / revenue | B18: a.opex_pct | H18: 0.0172 | I18: 0.0172 | J18: 0.0172 | K18: 0.0172 | L18: 0.0172 | M18: 0.0172 | N18: 0.0172 | O18: 0.0172 | P18: 0.0172 | Q18: 0.0172
A19: D&A / revenue | B19: a.da_pct | H19: 0.00091 | I19: 0.00091 | J19: 0.00091 | K19: 0.00091 | L19: 0.00091 | M19: 0.00091 | N19: 0.00091 | O19: 0.00091 | P19: 0.00091 | Q19: 0.00091
A20: Capex / revenue | B20: a.capex_pct | H20: 0.00029 | I20: 0.00029 | J20: 0.00029 | K20: 0.00029 | L20: 0.00029 | M20: 0.00029 | N20: 0.00029 | O20: 0.00029 | P20: 0.00029 | Q20: 0.00029
A21: Operating working capital / revenue | B21: a.nwc_pct | H21: -0.0903 | I21: -0.0903 | J21: -0.0903 | K21: -0.0903 | L21: -0.0903 | M21: -0.0903 | N21: -0.0903 | O21: -0.0903 | P21: -0.0903 | Q21: -0.0903
A22: Effective tax rate | B22: a.tax_rate | H22: 0.206 | I22: 0.206 | J22: 0.206 | K22: 0.206 | L22: 0.206 | M22: 0.206 | N22: 0.206 | O22: 0.206 | P22: 0.206 | Q22: 0.206
A23: Cost of debt (on opening debt) | B23: a.cost_of_debt | C23: 0.1
A24: Yield on opening cash | B24: a.cash_yield | C24: 0.0025
A25: Net new borrowing | B25: a.net_borrowing | H25: 0 | I25: 0 | J25: 0 | K25: 0 | L25: 0 | M25: 0 | N25: 0 | O25: 0 | P25: 0 | Q25: 0
A26: Other non-operating items | B26: a.other_nonop | H26: 0 | I26: 0 | J26: 0 | K26: 0 | L26: 0 | M26: 0 | N26: 0 | O26: 0 | P26: 0 | Q26: 0
A27: Minorities' share of net profit | B27: a.minority_pct | H27: 0 | I27: 0 | J27: 0 | K27: 0 | L27: 0 | M27: 0 | N27: 0 | O27: 0 | P27: 0 | Q27: 0
A28: Dividend payout | B28: a.payout | H28: 0 | I28: 0 | J28: 0 | K28: 0 | L28: 0 | M28: 0 | N28: 0 | O28: 0 | P28: 0 | Q28: 0
A29: Change in share count | B29: a.share_change | H29: 0 | I29: 0 | J29: 0 | K29: 0 | L29: 0 | M29: 0 | N29: 0 | O29: 0 | P29: 0 | Q29: 0
A30: Terminal growth (DCF) | B30: a.terminal_growth | C30: 0.04
A32: MODEL
A33: Revenue | B33: revenue | D33: 2784.8964 | E33: 3261.1837 | F33: 3337.3 | G33: 3496.8 | H33: =(G33*(1+H12)) | I33: =(H33*(1+I12)) | J33: =(I33*(1+J12)) | K33: =(J33*(1+K12)) | L33: =(K33*(1+L12)) | M33: =(L33*(1+M12)) | N33: =(M33*(1+N12)) | O33: =(N33*(1+O12)) | ... Q33: =(P33*(1+Q12))
A34: Cost of revenue | B34: cogs | D34: 2641.6019 | E34: 2991.658 | F34: 3014.5275 | G34: 3089.8009 | H34: =((H33*(1-H13))*((1+(($C$14*(1-$C$15))*(IF(Drivers!$G$4=0,0,Drivers!$H$4/Drivers!$G$4)-1)))+(($C$16*(1-$C$17))*(IF(Drivers!$G$6=0,0,Drivers!$H$6/Drivers!$G$6)-1)))) | I34: =((I33*(1-I13))*((1+(($C$14*(1-$C$15))*(IF(Drivers!$G$4=0,0,Drivers!$I$4/Drivers!$G$4)-1)))+(($C$16*(1-$C$17))*(IF(Drivers!$G$6=0,0,Drivers!$I$6/Drivers!$G$6)-1)))) | J34: =((J33*(1-J13))*((1+(($C$14*(1-$C$15))*(IF(Drivers!$G$4=0,0,Drivers!$J$4/Drivers!$G$4)-1)))+(($C$16*(1-$C$17))*(IF(Drivers!$G$6=0,0,Drivers!$J$6/Drivers!$G$6)-1)))) | K34: =((K33*(1-K13))*((1+(($C$14*(1-$C$15))*(IF(Drivers!$G$4=0,0,Drivers!$K$4/Drivers!$G$4)-1)))+(($C$16*(1-$C$17))*(IF(Drivers!$G$6=0,0,Drivers!$K$6/Drivers!$G$6)-1)))) | L34: =((L33*(1-L13))*((1+(($C$14*(1-$C$15))*(IF(Drivers!$G$4=0,0,Drivers!$L$4/Drivers!$G$4)-1)))+(($C$16*(1-$C$17))*(IF(Drivers!$G$6=0,0,Drivers!$L$6/Drivers!$G$6)-1)))) | M34: =((M33*(1-M13))*((1+(($C$14*(1-$C$15))*(IF(Drivers!$G$4=0,0,Drivers!$M$4/Drivers!$G$4)-1)))+(($C$16*(1-$C$17))*(IF(Drivers!$G$6=0,0,Drivers!$M$6/Drivers!$G$6)-1)))) | N34: =((N33*(1-N13))*((1+(($C$14*(1-$C$15))*(IF(Drivers!$G$4=0,0,Drivers!$N$4/Drivers!$G$4)-1)))+(($C$16*(1-$C$17))*(IF(Drivers!$G$6=0,0,Drivers!$N$6/Drivers!$G$6)-1)))) | O34: =((O33*(1-O13))*((1+(($C$14*(1-$C$15))*(IF(Drivers!$G$4=0,0,Drivers!$O$4/Drivers!$G$4)-1)))+(($C$16*(1-$C$17))*(IF(Drivers!$G$6=0,0,Drivers!$O$6/Drivers!$G$6)-1)))) | P34: =((P33*(1-P13))*((1+(($C$14*(1-$C$15))*(IF(Drivers!$G$4=0,0,Drivers!$P$4/Drivers!$G$4)-1)))+(($C$16*(1-$C$17))*(IF(Drivers!$G$6=0,0,Drivers!$P$6/Drivers!$G$6)-1)))) | Q34: =((Q33*(1-Q13))*((1+(($C$14*(1-$C$15))*(IF(Drivers!$G$4=0,0,Drivers!$Q$4/Drivers!$G$4)-1)))+(($C$16*(1-$C$17))*(IF(Drivers!$G$6=0,0,Drivers!$Q$6/Drivers!$G$6)-1))))
A35: Gross profit | B35: gross_profit | D35: 143.29443 | E35: 269.52575 | F35: 322.7444 | G35: 406.99546 | H35: =(H33-H34) | I35: =(I33-I34) | J35: =(J33-J34) | K35: =(K33-K34) | L35: =(L33-L34) | M35: =(M33-M34) | N35: =(N33-N34) | O35: =(O33-O34) | ... Q35: =(Q33-Q34)
A36: SG&A and other opex | B36: opex | D36: 83.77059 | E36: 95.948046 | F36: 82.256693 | G36: 58.925801 | H36: =(H33*H18) | I36: =(I33*I18) | J36: =(J33*J18) | K36: =(K33*K18) | L36: =(L33*L18) | M36: =(M33*M18) | N36: =(N33*N18) | O36: =(O33*O18) | ... Q36: =(Q33*Q18)
A37: EBIT | B37: ebit | D37: 59.523845 | E37: 173.57771 | F37: 240.48771 | G37: 348.06966 | H37: =(H35-H36) | I37: =(I35-I36) | J37: =(J35-J36) | K37: =(K35-K36) | L37: =(L35-L36) | M37: =(M35-M36) | N37: =(N35-N36) | O37: =(O35-O36) | ... Q37: =(Q35-Q36)
A38: Depreciation & amortisation | B38: da | D38: 1.545242 | E38: 1.622245 | F38: 1.308549 | G38: 3.121606 | H38: =(H33*H19) | I38: =(I33*I19) | J38: =(J33*J19) | K38: =(K33*K19) | L38: =(L33*L19) | M38: =(M33*M19) | N38: =(N33*N19) | O38: =(O33*O19) | ... Q38: =(Q33*Q19)
A39: EBITDA | B39: ebitda | D39: 61.069087 | E39: 175.19995 | F39: 241.79626 | G39: 351.19126 | H39: =(H37+H38) | I39: =(I37+I38) | J39: =(J37+J38) | K39: =(K37+K38) | L39: =(L37+L38) | M39: =(M37+M38) | N39: =(N37+N38) | O39: =(O37+O38) | ... Q39: =(Q37+Q38)
A40: Interest expense | B40: interest_expense | D40: 47.575361 | E40: 51.684894 | F40: 43.776619 | G40: 49.736655 | H40: =(G60*$C$23) | I40: =(H60*$C$23) | J40: =(I60*$C$23) | K40: =(J60*$C$23) | L40: =(K60*$C$23) | M40: =(L60*$C$23) | N40: =(M60*$C$23) | O40: =(N60*$C$23) | ... Q40: =(P60*$C$23)
A41: Interest income | B41: interest_income | D41: 1.686313 | E41: 1.638996 | F41: 2.022456 | G41: 1.447515 | H41: =(G59*$C$24) | I41: =(H59*$C$24) | J41: =(I59*$C$24) | K41: =(J59*$C$24) | L41: =(K59*$C$24) | M41: =(L59*$C$24) | N41: =(M59*$C$24) | O41: =(N59*$C$24) | ... Q41: =(P59*$C$24)
A42: Other non-operating | B42: other_nonop | D42: 3.301112 | E42: -100.02209 | F42: -48.879251 | G42: -16.693275 | H42: =H26 | I42: =I26 | J42: =J26 | K42: =K26 | L42: =L26 | M42: =M26 | N42: =N26 | O42: =O26 | ... Q42: =Q26
A43: Profit before tax | B43: pbt | D43: 16.935909 | E43: 23.509724 | F43: 149.85429 | G43: 283.08724 | H43: =(((H37-H40)+H41)+H42) | I43: =(((I37-I40)+I41)+I42) | J43: =(((J37-J40)+J41)+J42) | K43: =(((K37-K40)+K41)+K42) | L43: =(((L37-L40)+L41)+L42) | M43: =(((M37-M40)+M41)+M42) | N43: =(((N37-N40)+N41)+N42) | O43: =(((O37-O40)+O41)+O42) | ... Q43: =(((Q37-Q40)+Q41)+Q42)
A44: Tax | B44: tax | D44: 13.535751 | E44: 7.872249 | F44: 31.439482 | G44: 58.413094 | H44: =(MAX(H43,0)*H22) | I44: =(MAX(I43,0)*I22) | J44: =(MAX(J43,0)*J22) | K44: =(MAX(K43,0)*K22) | L44: =(MAX(L43,0)*L22) | M44: =(MAX(M43,0)*M22) | N44: =(MAX(N43,0)*N22) | O44: =(MAX(O43,0)*O22) | ... Q44: =(MAX(Q43,0)*Q22)
...

Sheet FIRE
A1: PT Alfa Energi Investama Tbk (FIRE.JK) — Coal distribution, trading & logistics
A2: Units: IDR bn; per-share in IDR unless marked IDR. Model asof 2026-10-30 · data 2026-10-30
A4: Line | C4: Scalar | D4: FY2022A | E4: FY2023A | F4: FY2024A | G4: FY2025A | H4: FY2026E | I4: FY2027E | J4: FY2028E | K4: FY2029E | L4: FY2030E | M4: FY2031E | N4: FY2032E | O4: FY2033E | P4: FY2034E | Q4: FY2035E
A6: PARAMETERS
A7: horizon | C7: 10
A8: ps_factor | C8: 1000
A9: vp_factor | C9: 1e-06
A11: INPUTS (company assumptions)
A12: Volume | B12: a.volume | H12: 400 | I12: 400 | J12: 400 | K12: 400 | L12: 400 | M12: 400 | N12: 400 | O12: 400 | P12: 400 | Q12: 400
A13: Average price | B13: a.price | H13: 830376 | I13: 851135 | J13: 872414 | K13: 894224 | L13: 916580 | M13: 939494 | N13: 962982 | O13: 987056 | P13: 1011733 | Q13: 1037026
A14: Gross margin at base input costs | B14: a.gross_margin | H14: 0.214 | I14: 0.214 | J14: 0.214 | K14: 0.214 | L14: 0.214 | M14: 0.214 | N14: 0.214 | O14: 0.214 | P14: 0.214 | Q14: 0.214
A15: Cost link 1: share of COGS exposed | B15: a.link1_share | C15: 0.15
A16: Cost link 1: pass-through to prices | B16: a.link1_pass | C16: 0.8
A17: Cost link 2: share of COGS exposed | B17: a.link2_share | C17: 0.15
A18: Cost link 2: pass-through to prices | B18: a.link2_pass | C18: 0.5
A19: SG&A / revenue | B19: a.opex_pct | H19: 0.138 | I19: 0.138 | J19: 0.138 | K19: 0.138 | L19: 0.138 | M19: 0.138 | N19: 0.138 | O19: 0.138 | P19: 0.138 | Q19: 0.138
A20: D&A / revenue | B20: a.da_pct | H20: 0.035 | I20: 0.035 | J20: 0.035 | K20: 0.035 | L20: 0.035 | M20: 0.035 | N20: 0.035 | O20: 0.035 | P20: 0.035 | Q20: 0.035
A21: Capex / revenue | B21: a.capex_pct | H21: 0.015 | I21: 0.015 | J21: 0.015 | K21: 0.015 | L21: 0.015 | M21: 0.015 | N21: 0.015 | O21: 0.015 | P21: 0.015 | Q21: 0.015
A22: Operating working capital / revenue | B22: a.nwc_pct | H22: -0.06 | I22: -0.06 | J22: -0.06 | K22: -0.06 | L22: -0.06 | M22: -0.06 | N22: -0.06 | O22: -0.06 | P22: -0.06 | Q22: -0.06
A23: Effective tax rate | B23: a.tax_rate | H23: 0.22 | I23: 0.22 | J23: 0.22 | K23: 0.22 | L23: 0.22 | M23: 0.22 | N23: 0.22 | O23: 0.22 | P23: 0.22 | Q23: 0.22
A24: Cost of debt (on opening debt) | B24: a.cost_of_debt | C24: 0.095
A25: Yield on opening cash | B25: a.cash_yield | C25: 0.025
A26: Net new borrowing | B26: a.net_borrowing | H26: 0 | I26: 0 | J26: 0 | K26: 0 | L26: 0 | M26: 0 | N26: 0 | O26: 0 | P26: 0 | Q26: 0
A27: Other non-operating items | B27: a.other_nonop | H27: 0 | I27: 0 | J27: 0 | K27: 0 | L27: 0 | M27: 0 | N27: 0 | O27: 0 | P27: 0 | Q27: 0
A28: Minorities' share of net profit | B28: a.minority_pct | H28: 0.01 | I28: 0.01 | J28: 0.01 | K28: 0.01 | L28: 0.01 | M28: 0.01 | N28: 0.01 | O28: 0.01 | P28: 0.01 | Q28: 0.01
A29: Dividend payout | B29: a.payout | H29: 0 | I29: 0 | J29: 0 | K29: 0 | L29: 0 | M29: 0 | N29: 0 | O29: 0 | P29: 0 | Q29: 0
A30: Change in share count | B30: a.share_change | H30: 0 | I30: 0 | J30: 0 | K30: 0 | L30: 0 | M30: 0 | N30: 0 | O30: 0 | P30: 0 | Q30: 0
A31: Terminal growth (DCF) | B31: a.terminal_growth | C31: 0.03
A33: MODEL
A34: Volume | B34: volume | F34: 556.995 | G34: 375.167 | H34: =H12 | I34: =I12 | J34: =J12 | K34: =K12 | L34: =L12 | M34: =M12 | N34: =N12 | O34: =O12 | ... Q34: =Q12
A35: Average price | B35: price | H35: =H13 | I35: =I13 | J35: =J13 | K35: =K13 | L35: =L13 | M35: =M13 | N35: =N13 | O35: =O13 | ... Q35: =Q13
A36: Revenue | B36: revenue | D36: 250.18171 | E36: 264.36448 | F36: 473.5021 | G36: 311.5296 | H36: =((H12*H13)*$C$9) | I36: =((I12*I13)*$C$9) | J36: =((J12*J13)*$C$9) | K36: =((K12*K13)*$C$9) | L36: =((L12*L13)*$C$9) | M36: =((M12*M13)*$C$9) | N36: =((N12*N13)*$C$9) | O36: =((O12*O13)*$C$9) | ... Q36: =((Q12*Q13)*$C$9)
A37: Cost of revenue | B37: cogs | D37: 191.71121 | E37: 194.72102 | F37: 338.2158 | G37: 252.5344 | H37: =((H36*(1-H14))*((1+(($C$15*(1-$C$16))*(IF(Drivers!$G$4=0,0,Drivers!$H$4/Drivers!$G$4)-1)))+(($C$17*(1-$C$18))*(IF(Drivers!$G$6=0,0,Drivers!$H$6/Drivers!$G$6)-1)))) | I37: =((I36*(1-I14))*((1+(($C$15*(1-$C$16))*(IF(Drivers!$G$4=0,0,Drivers!$I$4/Drivers!$G$4)-1)))+(($C$17*(1-$C$18))*(IF(Drivers!$G$6=0,0,Drivers!$I$6/Drivers!$G$6)-1)))) | J37: =((J36*(1-J14))*((1+(($C$15*(1-$C$16))*(IF(Drivers!$G$4=0,0,Drivers!$J$4/Drivers!$G$4)-1)))+(($C$17*(1-$C$18))*(IF(Drivers!$G$6=0,0,Drivers!$J$6/Drivers!$G$6)-1)))) | K37: =((K36*(1-K14))*((1+(($C$15*(1-$C$16))*(IF(Drivers!$G$4=0,0,Drivers!$K$4/Drivers!$G$4)-1)))+(($C$17*(1-$C$18))*(IF(Drivers!$G$6=0,0,Drivers!$K$6/Drivers!$G$6)-1)))) | L37: =((L36*(1-L14))*((1+(($C$15*(1-$C$16))*(IF(Drivers!$G$4=0,0,Drivers!$L$4/Drivers!$G$4)-1)))+(($C$17*(1-$C$18))*(IF(Drivers!$G$6=0,0,Drivers!$L$6/Drivers!$G$6)-1)))) | M37: =((M36*(1-M14))*((1+(($C$15*(1-$C$16))*(IF(Drivers!$G$4=0,0,Drivers!$M$4/Drivers!$G$4)-1)))+(($C$17*(1-$C$18))*(IF(Drivers!$G$6=0,0,Drivers!$M$6/Drivers!$G$6)-1)))) | N37: =((N36*(1-N14))*((1+(($C$15*(1-$C$16))*(IF(Drivers!$G$4=0,0,Drivers!$N$4/Drivers!$G$4)-1)))+(($C$17*(1-$C$18))*(IF(Drivers!$G$6=0,0,Drivers!$N$6/Drivers!$G$6)-1)))) | O37: =((O36*(1-O14))*((1+(($C$15*(1-$C$16))*(IF(Drivers!$G$4=0,0,Drivers!$O$4/Drivers!$G$4)-1)))+(($C$17*(1-$C$18))*(IF(Drivers!$G$6=0,0,Drivers!$O$6/Drivers!$G$6)-1)))) | P37: =((P36*(1-P14))*((1+(($C$15*(1-$C$16))*(IF(Drivers!$G$4=0,0,Drivers!$P$4/Drivers!$G$4)-1)))+(($C$17*(1-$C$18))*(IF(Drivers!$G$6=0,0,Drivers!$P$6/Drivers!$G$6)-1)))) | Q37: =((Q36*(1-Q14))*((1+(($C$15*(1-$C$16))*(IF(Drivers!$G$4=0,0,Drivers!$Q$4/Drivers!$G$4)-1)))+(($C$17*(1-$C$18))*(IF(Drivers!$G$6=0,0,Drivers!$Q$6/Drivers!$G$6)-1))))
A38: Gross profit | B38: gross_profit | D38: 58.470498 | E38: 69.643457 | F38: 135.28635 | G38: 58.995224 | H38: =(H36-H37) | I38: =(I36-I37) | J38: =(J36-J37) | K38: =(K36-K37) | L38: =(L36-L37) | M38: =(M36-M37) | N38: =(N36-N37) | O38: =(O36-O37) | ... Q38: =(Q36-Q37)
A39: SG&A and other opex | B39: opex | D39: 78.45363 | E39: 59.345084 | F39: 96.8886 | G39: 61.3805 | H39: =(H36*H19) | I39: =(I36*I19) | J39: =(J36*J19) | K39: =(K36*K19) | L39: =(L36*L19) | M39: =(M36*M19) | N39: =(N36*N19) | O39: =(O36*O19) | ... Q39: =(Q36*Q19)
A40: EBIT | B40: ebit | D40: -19.983133 | E40: 10.298372 | F40: 38.39776 | G40: -2.3853236 | H40: =(H38-H39) | I40: =(I38-I39) | J40: =(J38-J39) | K40: =(K38-K39) | L40: =(L38-L39) | M40: =(M38-M39) | N40: =(N38-N39) | O40: =(O38-O39) | ... Q40: =(Q38-Q39)
A41: Depreciation & amortisation | B41: da | D41: 2.9737442 | E41: 3.5635278 | F41: 9.8517588 | G41: 9.4212526 | H41: =(H36*H20) | I41: =(I36*I20) | J41: =(J36*J20) | K41: =(K36*K20) | L41: =(L36*L20) | M41: =(M36*M20) | N41: =(N36*N20) | O41: =(O36*O20) | ... Q41: =(Q36*Q20)
A42: EBITDA | B42: ebitda | D42: -17.009388 | E42: 13.8619 | F42: 48.249518 | G42: 7.035929 | H42: =(H40+H41) | I42: =(I40+I41) | J42: =(J40+J41) | K42: =(K40+K41) | L42: =(L40+L41) | M42: =(M40+M41) | N42: =(N40+N41) | O42: =(O40+O41) | ... Q42: =(Q40+Q41)
A43: Interest expense | B43: interest_expense | D43: 4.8827931 | E43: 4.1007345 | F43: 1.6047098 | G43: 0.91339057 | H43: =(G63*$C$24) | I43: =(H63*$C$24) | J43: =(I63*$C$24) | K43: =(J63*$C$24) | L43: =(K63*$C$24) | M43: =(L63*$C$24) | N43: =(M63*$C$24) | O43: =(N63*$C$24) | ... Q43: =(P63*$C$24)
A44: Interest income | B44: interest_income | D44: 0.35623258 | E44: 0.35441447 | F44: 0.38586441 | G44: 0.39973604 | H44: =(G62*$C$25) | I44: =(H62*$C$25) | J44: =(I62*$C$25) | K44: =(J62*$C$25) | L44: =(K62*$C$25) | M44: =(L62*$C$25) | N44: =(M62*$C$25) | O44: =(N62*$C$25) | ... Q44: =(P62*$C$25)
...

Sheet SGER
A1: PT Sumber Global Energy Tbk (SGER.JK) — Coal distribution, trading & logistics
A2: Units: IDR bn; per-share in IDR unless marked IDR. Model asof 2026-10-30 · data 2026-10-27
A4: Line | C4: Scalar | D4: FY2022A | E4: FY2023A | F4: FY2024A | G4: FY2025A | H4: FY2026E | I4: FY2027E | J4: FY2028E | K4: FY2029E | L4: FY2030E | M4: FY2031E | N4: FY2032E | O4: FY2033E | P4: FY2034E | Q4: FY2035E
A6: PARAMETERS
A7: ps_factor | C7: 1000
A8: vp_factor | C8: 1
A10: INPUTS (company assumptions)
A11: Revenue growth | B11: a.revenue_growth | H11: 0.067 | I11: -0.05 | J11: -0.02 | K11: 0 | L11: 0.015 | M11: 0.0328 | N11: 0.0328 | O11: 0.0328 | P11: 0.0328 | Q11: 0.0328
A12: Gross margin at base input costs | B12: a.gross_margin | H12: 0.08 | I12: 0.08 | J12: 0.08 | K12: 0.08 | L12: 0.08 | M12: 0.08 | N12: 0.08 | O12: 0.08 | P12: 0.08 | Q12: 0.08
A13: Cost link 1: share of COGS exposed | B13: a.link1_share | C13: 0.732
A14: Cost link 1: pass-through to prices | B14: a.link1_pass | C14: 1
A15: Cost link 2: share of COGS exposed | B15: a.link2_share | C15: 0
A16: Cost link 2: pass-through to prices | B16: a.link2_pass | C16: 0
A17: SG&A / revenue | B17: a.opex_pct | H17: 0.0233 | I17: 0.0233 | J17: 0.0233 | K17: 0.0233 | L17: 0.0233 | M17: 0.0233 | N17: 0.0233 | O17: 0.0233 | P17: 0.0233 | Q17: 0.0233
A18: D&A / revenue | B18: a.da_pct | H18: 0.003 | I18: 0.003 | J18: 0.003 | K18: 0.003 | L18: 0.003 | M18: 0.003 | N18: 0.003 | O18: 0.003 | P18: 0.003 | Q18: 0.003
A19: Capex / revenue | B19: a.capex_pct | H19: 0.035 | I19: 0.025 | J19: 0.02 | K19: 0.015 | L19: 0.012 | M19: 0.01 | N19: 0.01 | O19: 0.01 | P19: 0.01 | Q19: 0.01
A20: Operating working capital / revenue | B20: a.nwc_pct | H20: 0.35 | I20: 0.35 | J20: 0.35 | K20: 0.35 | L20: 0.35 | M20: 0.35 | N20: 0.35 | O20: 0.35 | P20: 0.35 | Q20: 0.35
A21: Effective tax rate | B21: a.tax_rate | H21: 0.1279 | I21: 0.1279 | J21: 0.1279 | K21: 0.1279 | L21: 0.1279 | M21: 0.1279 | N21: 0.1279 | O21: 0.1279 | P21: 0.1279 | Q21: 0.1279
A22: Cost of debt (on opening debt) | B22: a.cost_of_debt | C22: 0.085
A23: Yield on opening cash | B23: a.cash_yield | C23: 0.025
A24: Net new borrowing | B24: a.net_borrowing | H24: -352 | I24: 0 | J24: 0 | K24: 0 | L24: 0 | M24: 0 | N24: 0 | O24: 0 | P24: 0 | Q24: 0
A25: Other non-operating items | B25: a.other_nonop | H25: 0 | I25: 0 | J25: 0 | K25: 0 | L25: 0 | M25: 0 | N25: 0 | O25: 0 | P25: 0 | Q25: 0
A26: Minorities' share of net profit | B26: a.minority_pct | H26: 0 | I26: 0 | J26: 0 | K26: 0 | L26: 0 | M26: 0 | N26: 0 | O26: 0 | P26: 0 | Q26: 0
A27: Dividend payout | B27: a.payout | H27: 0.15 | I27: 0.15 | J27: 0.15 | K27: 0.15 | L27: 0.15 | M27: 0.15 | N27: 0.15 | O27: 0.15 | P27: 0.15 | Q27: 0.15
A28: Change in share count | B28: a.share_change | H28: 0 | I28: 0 | J28: 0 | K28: 0 | L28: 0 | M28: 0 | N28: 0 | O28: 0 | P28: 0 | Q28: 0
A29: Terminal growth (DCF) | B29: a.terminal_growth | C29: 0.0328
A31: MODEL
A32: Revenue | B32: revenue | D32: 10448.875 | E32: 12312.862 | F32: 14762.475 | G32: 6739.5203 | H32: =(G32*(1+H11)) | I32: =(H32*(1+I11)) | J32: =(I32*(1+J11)) | K32: =(J32*(1+K11)) | L32: =(K32*(1+L11)) | M32: =(L32*(1+M11)) | N32: =(M32*(1+N11)) | O32: =(N32*(1+O11)) | ... Q32: =(P32*(1+Q11))
A33: Cost of revenue | B33: cogs | D33: 9718.9054 | E33: 11254.656 | F33: 13732.694 | G33: 6202.5784 | H33: =((H32*(1-H12))*((1+(($C$13*(1-$C$14))*(IF(Drivers!$G$4=0,0,Drivers!$H$4/Drivers!$G$4)-1)))+(($C$15*(1-$C$16))*(IF(Drivers!$G$6=0,0,Drivers!$H$6/Drivers!$G$6)-1)))) | I33: =((I32*(1-I12))*((1+(($C$13*(1-$C$14))*(IF(Drivers!$G$4=0,0,Drivers!$I$4/Drivers!$G$4)-1)))+(($C$15*(1-$C$16))*(IF(Drivers!$G$6=0,0,Drivers!$I$6/Drivers!$G$6)-1)))) | J33: =((J32*(1-J12))*((1+(($C$13*(1-$C$14))*(IF(Drivers!$G$4=0,0,Drivers!$J$4/Drivers!$G$4)-1)))+(($C$15*(1-$C$16))*(IF(Drivers!$G$6=0,0,Drivers!$J$6/Drivers!$G$6)-1)))) | K33: =((K32*(1-K12))*((1+(($C$13*(1-$C$14))*(IF(Drivers!$G$4=0,0,Drivers!$K$4/Drivers!$G$4)-1)))+(($C$15*(1-$C$16))*(IF(Drivers!$G$6=0,0,Drivers!$K$6/Drivers!$G$6)-1)))) | L33: =((L32*(1-L12))*((1+(($C$13*(1-$C$14))*(IF(Drivers!$G$4=0,0,Drivers!$L$4/Drivers!$G$4)-1)))+(($C$15*(1-$C$16))*(IF(Drivers!$G$6=0,0,Drivers!$L$6/Drivers!$G$6)-1)))) | M33: =((M32*(1-M12))*((1+(($C$13*(1-$C$14))*(IF(Drivers!$G$4=0,0,Drivers!$M$4/Drivers!$G$4)-1)))+(($C$15*(1-$C$16))*(IF(Drivers!$G$6=0,0,Drivers!$M$6/Drivers!$G$6)-1)))) | N33: =((N32*(1-N12))*((1+(($C$13*(1-$C$14))*(IF(Drivers!$G$4=0,0,Drivers!$N$4/Drivers!$G$4)-1)))+(($C$15*(1-$C$16))*(IF(Drivers!$G$6=0,0,Drivers!$N$6/Drivers!$G$6)-1)))) | O33: =((O32*(1-O12))*((1+(($C$13*(1-$C$14))*(IF(Drivers!$G$4=0,0,Drivers!$O$4/Drivers!$G$4)-1)))+(($C$15*(1-$C$16))*(IF(Drivers!$G$6=0,0,Drivers!$O$6/Drivers!$G$6)-1)))) | P33: =((P32*(1-P12))*((1+(($C$13*(1-$C$14))*(IF(Drivers!$G$4=0,0,Drivers!$P$4/Drivers!$G$4)-1)))+(($C$15*(1-$C$16))*(IF(Drivers!$G$6=0,0,Drivers!$P$6/Drivers!$G$6)-1)))) | Q33: =((Q32*(1-Q12))*((1+(($C$13*(1-$C$14))*(IF(Drivers!$G$4=0,0,Drivers!$Q$4/Drivers!$G$4)-1)))+(($C$15*(1-$C$16))*(IF(Drivers!$G$6=0,0,Drivers!$Q$6/Drivers!$G$6)-1))))
A34: Gross profit | B34: gross_profit | D34: 729.96975 | E34: 1058.2061 | F34: 1029.7812 | G34: 536.94193 | H34: =(H32-H33) | I34: =(I32-I33) | J34: =(J32-J33) | K34: =(K32-K33) | L34: =(L32-L33) | M34: =(M32-M33) | N34: =(N32-N33) | O34: =(O32-O33) | ... Q34: =(Q32-Q33)
A35: SG&A and other opex | B35: opex | D35: 113.71253 | E35: 165.21331 | F35: 115.99653 | G35: 157.13156 | H35: =(H32*H17) | I35: =(I32*I17) | J35: =(J32*J17) | K35: =(K32*K17) | L35: =(L32*L17) | M35: =(M32*M17) | N35: =(N32*N17) | O35: =(O32*O17) | ... Q35: =(Q32*Q17)
A36: EBIT | B36: ebit | D36: 616.25722 | E36: 892.99282 | F36: 913.78466 | G36: 379.81036 | H36: =(H34-H35) | I36: =(I34-I35) | J36: =(J34-J35) | K36: =(K34-K35) | L36: =(L34-L35) | M36: =(M34-M35) | N36: =(N34-N35) | O36: =(O34-O35) | ... Q36: =(Q34-Q35)
A37: Depreciation & amortisation | B37: da | D37: 3.6351996 | E37: 5.7042662 | F37: 13.040679 | G37: 17.740539 | H37: =(H32*H18) | I37: =(I32*I18) | J37: =(J32*J18) | K37: =(K32*K18) | L37: =(L32*L18) | M37: =(M32*M18) | N37: =(N32*N18) | O37: =(O32*O18) | ... Q37: =(Q32*Q18)
A38: EBITDA | B38: ebitda | D38: 619.89242 | E38: 898.69709 | F38: 926.82534 | G38: 397.5509 | H38: =(H36+H37) | I38: =(I36+I37) | J38: =(J36+J37) | K38: =(K36+K37) | L38: =(L36+L37) | M38: =(M36+M37) | N38: =(N36+N37) | O38: =(O36+O37) | ... Q38: =(Q36+Q37)
A39: Interest expense | B39: interest_expense | D39: 33.217496 | E39: 42.482409 | F39: 106.49781 | G39: 151.15052 | H39: =(G59*$C$22) | I39: =(H59*$C$22) | J39: =(I59*$C$22) | K39: =(J59*$C$22) | L39: =(K59*$C$22) | M39: =(L59*$C$22) | N39: =(M59*$C$22) | O39: =(N59*$C$22) | ... Q39: =(P59*$C$22)
A40: Interest income | B40: interest_income | H40: =(G58*$C$23) | I40: =(H58*$C$23) | J40: =(I58*$C$23) | K40: =(J58*$C$23) | L40: =(K58*$C$23) | M40: =(L58*$C$23) | N40: =(M58*$C$23) | O40: =(N58*$C$23) | ... Q40: =(P58*$C$23)
A41: Other non-operating | B41: other_nonop | H41: =H25 | I41: =I25 | J41: =J25 | K41: =K25 | L41: =L25 | M41: =M25 | N41: =N25 | O41: =O25 | ... Q41: =Q25
A42: Profit before tax | B42: pbt | D42: 748.25049 | E42: 840.91049 | F42: 810.94346 | G42: 238.25612 | H42: =(((H36-H39)+H40)+H41) | I42: =(((I36-I39)+I40)+I41) | J42: =(((J36-J39)+J40)+J41) | K42: =(((K36-K39)+K40)+K41) | L42: =(((L36-L39)+L40)+L41) | M42: =(((M36-M39)+M40)+M41) | N42: =(((N36-N39)+N40)+N41) | O42: =(((O36-O39)+O40)+O41) | ... Q42: =(((Q36-Q39)+Q40)+Q41)
A43: Tax | B43: tax | D43: 157.31943 | E43: 159.60399 | F43: 156.2847 | G43: 30.467122 | H43: =(MAX(H42,0)*H21) | I43: =(MAX(I42,0)*I21) | J43: =(MAX(J42,0)*J21) | K43: =(MAX(K42,0)*K21) | L43: =(MAX(L42,0)*L21) | M43: =(MAX(M42,0)*M21) | N43: =(MAX(N42,0)*N21) | O43: =(MAX(O42,0)*O21) | ... Q43: =(MAX(Q42,0)*Q21)
A44: Net profit (incl. minorities) | B44: np | D44: 590.93106 | E44: 681.30649 | F44: 654.65876 | G44: 207.78899 | H44: =(H42-H43) | I44: =(I42-I43) | J44: =(J42-J43) | K44: =(K42-K43) | L44: =(L42-L43) | M44: =(M42-M43) | N44: =(N42-N43) | O44: =(O42-O43) | ... Q44: =(Q42-Q43)
...
