Workbook

Sheet README
A1: Six South — Conglomerates & multi-sector holdings industry model
A2: Generated 2026-10-29T10:26:30+07:00 by the coverage engine. The engine (scripts/cov_engine.py) is the source of truth; this workbook is a live rendering of it.
A3: Colour key: blue = input or hard-coded history; black = formula; green = link to another sheet.
A4: Drivers: every deck variable these models read. Change one and every ticker tab and the Comps sheet recalculate (forecasts, cash flows, DCF value, base-case value, target, rating).
A5: Scenario (bear/bull) and sensitivity tables need full model re-runs and are engine values.
A6: Paper fund — research for education and process transparency, not investment advice.
A8: Tickers:
A9: ABMM.JK — PT ABM Investama Tbk
A10: ADRO.JK — PT Alamtri Resources Indonesia Tbk
A11: ASII.JK — PT Astra International Tbk
A12: BHIT.JK — PT MNC Asia Holding Tbk
A13: BNBR.JK — PT Bakrie & Brothers Tbk
... A20: ZBRA.JK — PT Dosni Roha Indonesia Tbk

Sheet Drivers
A1: Driver decks (state/drivers) — edit a blue cell to flow it through every ticker tab
A3: Variable | B3: Key | C3: Unit / status | D3: FY2021A | E3: FY2022A | F3: FY2023A | G3: FY2024A | H3: FY2024E | I3: FY2025A | J3: FY2025E | K3: FY2026E | L3: FY2027E | M3: FY2028E | N3: FY2029E | O3: FY2030E | P3: FY2031E | Q3: FY2032E | R3: FY2033E | S3: FY2034E | T3: FY2035E
A4: IDR per USD | B4: m.usd_idr | C4: IDR/USD · reviewed | D4: 14310.54 | E4: 14843.177 | F4: 15228.8 | G4: 15846.238 | H4: 19000 | I4: 16448.093 | J4: 19000 | K4: 17570 | L4: 18350 | M4: 18600 | N4: 18850 | O4: 19093.137 | P4: 19186.731 | Q4: 19280.784 | R4: 19375.297 | S4: 19470.274 | T4: 19565.717
A6: Cost-of-capital scalars (macro deck)
A7: 10-year Indonesian government bond yield (IDR) | B7: m.rf_idr | C7: 0.0745 | D7: investor.id — "Yield SUN 7,45%, Saatnya Borong atau Tunggu Lebih Tinggi?" (25 Okt 2026 20:58 WIB; deck source S3); corroborated by kalderanews S1 (10Y SUN 7.41%
A8: 10-year US Treasury yield | B8: m.rf_usd | C8: 0.05045 | D8: Yahoo Finance ^TNX (US 10-year Treasury yield)
A9: Indonesia sovereign default spread (Damodaran) | B9: m.default_spread_id | C9: 0.0162 | D9: Damodaran country risk premiums (https://pages.stern.nyu.edu/~adamodar/New_Home_Page/datafile/ctryprem.html), page dated January 5, 2026, read 2026-10-29
A10: Mature-market equity risk premium (Damodaran) | B10: m.erp_mature | C10: 0.0423 | D10: Damodaran country risk premiums (https://pages.stern.nyu.edu/~adamodar/New_Home_Page/datafile/ctryprem.html), page dated January 5, 2026, read 2026-10-29
A11: Indonesia country risk premium (Damodaran) | B11: m.crp_id | C11: 0.0246 | D11: Damodaran country risk premiums (https://pages.stern.nyu.edu/~adamodar/New_Home_Page/datafile/ctryprem.html), page dated January 5, 2026, read 2026-10-29
A12: House pre-tax corporate debt spread over the risk-free | B12: m.debt_spread_corp | C12: 0.02 | D12: SEED house assumption pending the macro desk: 200 bp over the risk-free rate for an average IDX corporate borrower
A13: Indonesia statutory corporate income tax rate | B13: m.tax_rate_id | C13: 0.22 | D13: Law 7/2021 on Harmonisation of Tax Regulations (UU HPP): 22% corporate income tax from fiscal 2022

Sheet Comps
A1: Ticker | B1: Company | C1: Rating | D1: Target (IDR) | E1: Price (IDR) | F1: Exp. 12m TR | G1: Value today | H1: P/E FY+0 | I1: EV/EBITDA FY+0 | J1: Div. yield FY+0
A2: ABMM.JK | B2: PT ABM Investama Tbk | C2: ='ABMM'!$C$128 | D2: ='ABMM'!$C$126 | E2: ='ABMM'!$C$76 | F2: ='ABMM'!$C$127 | G2: ='ABMM'!$C$116 | H2: 5.148453 | I2: 3.920208 | J2: 0.041236
A3: ADRO.JK | B3: PT Alamtri Resources Indonesia Tbk | C3: ='ADRO'!$C$128 | D3: ='ADRO'!$C$126 | E3: ='ADRO'!$C$76 | F3: ='ADRO'!$C$127 | G3: ='ADRO'!$C$116 | H3: 8.30708 | I3: 4.405562 | J3: 0.120331
A4: ASII.JK | B4: PT Astra International Tbk | C4: ='ASII'!$C$128 | D4: ='ASII'!$C$126 | E4: ='ASII'!$C$76 | F4: ='ASII'!$C$127 | G4: ='ASII'!$C$116 | H4: 5.401133 | I4: 5.201985 | J4: 0.092573
A5: BHIT.JK | B5: PT MNC Asia Holding Tbk | C5: ='BHIT'!$C$128 | D5: ='BHIT'!$C$126 | E5: ='BHIT'!$C$76 | F5: ='BHIT'!$C$127 | G5: ='BHIT'!$C$116 | H5: 8.902137 | I5: 7.317416 | J5: 0
A6: BNBR.JK | B6: PT Bakrie & Brothers Tbk | C6: ='BNBR'!$C$131 | D6: ='BNBR'!$C$129 | E6: ='BNBR'!$C$76 | F6: ='BNBR'!$C$130 | G6: ='BNBR'!$C$110 | I6: 33.24141 | J6: 0
A7: BRPT.JK | B7: PT Barito Pacific Tbk | C7: ='BRPT'!$C$137 | D7: ='BRPT'!$C$135 | E7: ='BRPT'!$C$76 | F7: ='BRPT'!$C$136 | G7: ='BRPT'!$C$116 | H7: 84.339622 | I7: 15.053141 | J7: 0.011857
A8: CUAN.JK | B8: PT Petrindo Jaya Kreasi Tbk | C8: ='CUAN'!$C$131 | D8: ='CUAN'!$C$129 | E8: ='CUAN'!$C$76 | F8: ='CUAN'!$C$130 | G8: ='CUAN'!$C$110 | H8: 1705.7116 | I8: 14.393063 | J8: 1.2e-05
A9: DSSA.JK | B9: PT Dian Swastatika Sentosa Tbk | C9: ='DSSA'!$C$125 | D9: ='DSSA'!$C$123 | E9: ='DSSA'!$C$76 | F9: ='DSSA'!$C$124 | G9: ='DSSA'!$C$104 | H9: 38.835833 | I9: 15.660056 | J9: 0
A10: FOLK.JK | B10: PT Multi Garam Utama Tbk | C10: ='FOLK'!$C$116 | D10: ='FOLK'!$C$114 | E10: ='FOLK'!$C$76 | F10: ='FOLK'!$C$115 | G10: ='FOLK'!$C$104 | J10: 0
A11: IMJS.JK | B11: PT Indomobil Multi Jasa Tbk | C11: ='IMJS'!$C$122 | D11: ='IMJS'!$C$120 | E11: ='IMJS'!$C$76 | F11: ='IMJS'!$C$121 | G11: ='IMJS'!$C$110 | H11: 9.724263 | I11: 12.554759 | J11: 0.002333
A12: TOBA.JK | B12: PT TBS Energi Utama Tbk | C12: ='TOBA'!$C$128 | D12: ='TOBA'!$C$126 | E12: ='TOBA'!$C$76 | F12: ='TOBA'!$C$127 | G12: ='TOBA'!$C$116 | I12: 10.714611 | J12: 0
A13: ZBRA.JK | B13: PT Dosni Roha Indonesia Tbk | C13: ='ZBRA'!$C$116 | D13: ='ZBRA'!$C$114 | E13: ='ZBRA'!$C$76 | F13: ='ZBRA'!$C$115 | G13: ='ZBRA'!$C$104 | I13: 36.065089 | J13: 0

Sheet ABMM
A1: PT ABM Investama Tbk (ABMM.JK) — Conglomerates & multi-sector holdings
A2: Units: USD m; per-share in USD unless marked IDR. Model asof 2026-10-29 · data 2026-10-26
A4: Line | C4: Scalar | D4: FY2022A | E4: FY2023A | F4: FY2024A | G4: FY2025A | H4: FY2026E | I4: FY2027E | J4: FY2028E | K4: FY2029E | L4: FY2030E | M4: FY2031E | N4: FY2032E | O4: FY2033E | P4: FY2034E | Q4: FY2035E
A6: PARAMETERS
A7: ps_factor | C7: 1
A8: vp_factor | C8: 1
A10: INPUTS (company assumptions)
A11: Revenue growth | B11: a.revenue_growth | H11: 0 | I11: 0 | J11: 0 | K11: 0 | L11: 0 | M11: 0 | N11: 0 | O11: 0 | P11: 0 | Q11: 0
A12: Gross margin at base input costs | B12: a.gross_margin | H12: 0.09986 | I12: 0.09986 | J12: 0.09986 | K12: 0.09986 | L12: 0.09986 | M12: 0.09986 | N12: 0.09986 | O12: 0.09986 | P12: 0.09986 | Q12: 0.09986
A13: SG&A / revenue | B13: a.opex_pct | H13: 0.058785 | I13: 0.058785 | J13: 0.058785 | K13: 0.058785 | L13: 0.058785 | M13: 0.058785 | N13: 0.058785 | O13: 0.058785 | P13: 0.058785 | Q13: 0.058785
A14: D&A / revenue | B14: a.da_pct | H14: 0.20379 | I14: 0.20379 | J14: 0.20379 | K14: 0.20379 | L14: 0.20379 | M14: 0.20379 | N14: 0.20379 | O14: 0.20379 | P14: 0.20379 | Q14: 0.20379
A15: Capex / revenue | B15: a.capex_pct | H15: 0.13155 | I15: 0.13155 | J15: 0.13155 | K15: 0.13155 | L15: 0.13155 | M15: 0.13155 | N15: 0.13155 | O15: 0.13155 | P15: 0.13155 | Q15: 0.13155
A16: Operating working capital / revenue | B16: a.nwc_pct | H16: 0.106679 | I16: 0.106679 | J16: 0.106679 | K16: 0.106679 | L16: 0.106679 | M16: 0.106679 | N16: 0.106679 | O16: 0.106679 | P16: 0.106679 | Q16: 0.106679
A17: Effective tax rate | B17: a.tax_rate | H17: 0.059 | I17: 0.059 | J17: 0.059 | K17: 0.059 | L17: 0.059 | M17: 0.059 | N17: 0.059 | O17: 0.059 | P17: 0.059 | Q17: 0.059
A18: Cost of debt (on opening debt) | B18: a.cost_of_debt | C18: 0.075
A19: Yield on opening cash | B19: a.cash_yield | C19: 0.02
A20: Net new borrowing | B20: a.net_borrowing | H20: 0 | I20: 0 | J20: 0 | K20: 0 | L20: 0 | M20: 0 | N20: 0 | O20: 0 | P20: 0 | Q20: 0
A21: Other non-operating items | B21: a.other_nonop | H21: 105.37707 | I21: 105.37707 | J21: 105.37707 | K21: 105.37707 | L21: 105.37707 | M21: 107.48461 | N21: 109.6343 | O21: 111.82699 | P21: 114.06353 | Q21: 116.3448
A22: Minorities' share of net profit | B22: a.minority_pct | H22: 0 | I22: 0 | J22: 0 | K22: 0 | L22: 0 | M22: 0 | N22: 0 | O22: 0 | P22: 0 | Q22: 0
A23: Dividend payout | B23: a.payout | H23: 0.2123 | I23: 0.2123 | J23: 0.2123 | K23: 0.2123 | L23: 0.2123 | M23: 0.2123 | N23: 0.2123 | O23: 0.2123 | P23: 0.2123 | Q23: 0.2123
A24: Change in share count | B24: a.share_change | H24: 0 | I24: 0 | J24: 0 | K24: 0 | L24: 0 | M24: 0 | N24: 0 | O24: 0 | P24: 0 | Q24: 0
A25: Terminal growth (DCF) | B25: a.terminal_growth | C25: 0
A26: Holding-company discount to SOTP | B26: a.holdco_discount | C26: 0.662462
A28: MODEL
A29: Revenue | B29: revenue | D29: 1445.5274 | E29: 1492.9989 | F29: 1200.1325 | G29: 1038.1703 | H29: =(G29*(1+H11)) | I29: =(H29*(1+I11)) | J29: =(I29*(1+J11)) | K29: =(J29*(1+K11)) | L29: =(K29*(1+L11)) | M29: =(L29*(1+M11)) | N29: =(M29*(1+N11)) | O29: =(N29*(1+O11)) | ... Q29: =(P29*(1+Q11))
A30: Cost of revenue | B30: cogs | D30: 923.6231 | E30: 1100.9528 | F30: 1068.9408 | G30: 934.49149 | H30: =(H29*(1-H12)) | I30: =(I29*(1-I12)) | J30: =(J29*(1-J12)) | K30: =(K29*(1-K12)) | L30: =(L29*(1-L12)) | M30: =(M29*(1-M12)) | N30: =(N29*(1-N12)) | O30: =(O29*(1-O12)) | ... Q30: =(Q29*(1-Q12))
A31: Gross profit | B31: gross_profit | D31: 521.90427 | E31: 392.04603 | F31: 131.19162 | G31: 103.67876 | H31: =(H29-H30) | I31: =(I29-I30) | J31: =(J29-J30) | K31: =(K29-K30) | L31: =(L29-L30) | M31: =(M29-M30) | N31: =(N29-N30) | O31: =(O29-O30) | ... Q31: =(Q29-Q30)
A32: SG&A and other opex | B32: opex | D32: 126.17262 | E32: 134.17259 | F32: 57.505347 | G32: 61.024162 | H32: =(H29*H13) | I32: =(I29*I13) | J32: =(J29*J13) | K32: =(K29*K13) | L32: =(L29*L13) | M32: =(M29*M13) | N32: =(N29*N13) | O32: =(O29*O13) | ... Q32: =(Q29*Q13)
A33: EBIT | B33: ebit | D33: 395.73165 | E33: 257.87344 | F33: 73.686271 | G33: 42.6546 | H33: =(H31-H32) | I33: =(I31-I32) | J33: =(J31-J32) | K33: =(K31-K32) | L33: =(L31-L32) | M33: =(M31-M32) | N33: =(N31-N32) | O33: =(O31-O32) | ... Q33: =(Q31-Q32)
A34: Depreciation & amortisation | B34: da | D34: 4.986805 | E34: 5.48014 | F34: 205.07883 | G34: 211.56525 | H34: =(H29*H14) | I34: =(I29*I14) | J34: =(J29*J14) | K34: =(K29*K14) | L34: =(L29*L14) | M34: =(M29*M14) | N34: =(N29*N14) | O34: =(O29*O14) | ... Q34: =(Q29*Q14)
A35: EBITDA | B35: ebitda | D35: 400.71845 | E35: 263.35358 | F35: 278.7651 | G35: 254.21985 | H35: =(H33+H34) | I35: =(I33+I34) | J35: =(J33+J34) | K35: =(K33+K34) | L35: =(L33+L34) | M35: =(M33+M34) | N35: =(N33+N34) | O35: =(O33+O34) | ... Q35: =(Q33+Q34)
A36: Interest expense | B36: interest_expense | D36: 52.481411 | E36: 106.10741 | F36: 109.80308 | G36: 76.554485 | H36: =(G56*$C$18) | I36: =(H56*$C$18) | J36: =(I56*$C$18) | K36: =(J56*$C$18) | L36: =(K56*$C$18) | M36: =(L56*$C$18) | N36: =(M56*$C$18) | O36: =(N56*$C$18) | ... Q36: =(P56*$C$18)
A37: Interest income | B37: interest_income | D37: 2.596132 | E37: 4.812848 | F37: 4.558293 | G37: 4.382377 | H37: =(G55*$C$19) | I37: =(H55*$C$19) | J37: =(I55*$C$19) | K37: =(J55*$C$19) | L37: =(K55*$C$19) | M37: =(L55*$C$19) | N37: =(M55*$C$19) | O37: =(N55*$C$19) | ... Q37: =(P55*$C$19)
A38: Other non-operating | B38: other_nonop | D38: 87.215074 | E38: 214.91204 | F38: 186.38059 | G38: 105.37707 | H38: =H21 | I38: =I21 | J38: =J21 | K38: =K21 | L38: =L21 | M38: =M21 | N38: =N21 | O38: =O21 | ... Q38: =Q21
A39: Profit before tax | B39: pbt | D39: 433.06144 | E39: 371.49092 | F39: 154.82207 | G39: 75.859561 | H39: =(((H33-H36)+H37)+H38) | I39: =(((I33-I36)+I37)+I38) | J39: =(((J33-J36)+J37)+J38) | K39: =(((K33-K36)+K37)+K38) | L39: =(((L33-L36)+L37)+L38) | M39: =(((M33-M36)+M37)+M38) | N39: =(((N33-N36)+N37)+N38) | O39: =(((O33-O36)+O37)+O38) | ... Q39: =(((Q33-Q36)+Q37)+Q38)
A40: Tax | B40: tax | D40: 91.157937 | E40: 55.86703 | F40: 15.480224 | G40: 5.378922 | H40: =(MAX(H39,0)*H17) | I40: =(MAX(I39,0)*I17) | J40: =(MAX(J39,0)*J17) | K40: =(MAX(K39,0)*K17) | L40: =(MAX(L39,0)*L17) | M40: =(MAX(M39,0)*M17) | N40: =(MAX(N39,0)*N17) | O40: =(MAX(O39,0)*O17) | ... Q40: =(MAX(Q39,0)*Q17)
A41: Net profit (incl. minorities) | B41: np | D41: 341.90351 | E41: 315.62389 | F41: 139.34185 | G41: 70.480639 | H41: =(H39-H40) | I41: =(I39-I40) | J41: =(J39-J40) | K41: =(K39-K40) | L41: =(L39-L40) | M41: =(M39-M40) | N41: =(N39-N40) | O41: =(O39-O40) | ... Q41: =(Q39-Q40)
A42: Minority interests | B42: minority | D42: 71.993581 | E42: 26.623336 | F42: -0.026664 | G42: -0.135678 | H42: =(H41*H22) | I42: =(I41*I22) | J42: =(J41*J22) | K42: =(K41*K22) | L42: =(L41*L22) | M42: =(M41*M22) | N42: =(N41*N22) | O42: =(O41*O22) | ... Q42: =(Q41*Q22)
A43: Net profit to parent | B43: np_parent | D43: 269.90993 | E43: 289.00056 | F43: 139.36851 | G43: 70.616317 | H43: =(H41-H42) | I43: =(I41-I42) | J43: =(J41-J42) | K43: =(K41-K42) | L43: =(L41-L42) | M43: =(M41-M42) | N43: =(N41-N42) | O43: =(O41-O42) | ... Q43: =(Q41-Q42)
A44: Shares outstanding (m) | B44: shares | D44: 2753.165 | E44: 2753.165 | F44: 2753.165 | G44: 2753.165 | H44: =(G44*(1+H24)) | I44: =(H44*(1+I24)) | J44: =(I44*(1+J24)) | K44: =(J44*(1+K24)) | L44: =(K44*(1+L24)) | M44: =(L44*(1+M24)) | N44: =(M44*(1+N24)) | O44: =(N44*(1+O24)) | ... Q44: =(P44*(1+Q24))
...

Sheet ADRO
A1: PT Alamtri Resources Indonesia Tbk (ADRO.JK) — Conglomerates & multi-sector holdings
A2: Units: USD m; per-share in USD unless marked IDR. Model asof 2026-10-29 · data 2026-10-26
A4: Line | C4: Scalar | D4: FY2022A | E4: FY2023A | F4: FY2024A | G4: FY2025A | H4: FY2026E | I4: FY2027E | J4: FY2028E | K4: FY2029E | L4: FY2030E | M4: FY2031E | N4: FY2032E | O4: FY2033E | P4: FY2034E | Q4: FY2035E
A6: PARAMETERS
A7: ps_factor | C7: 1
A8: vp_factor | C8: 1
A10: INPUTS (company assumptions)
A11: Revenue growth | B11: a.revenue_growth | H11: 0.1 | I11: -0.06 | J11: -0.03 | K11: -0.02 | L11: 0 | M11: 0 | N11: 0 | O11: 0 | P11: 0 | Q11: 0
A12: Gross margin at base input costs | B12: a.gross_margin | H12: 0.339852 | I12: 0.339852 | J12: 0.339852 | K12: 0.339852 | L12: 0.339852 | M12: 0.339852 | N12: 0.339852 | O12: 0.339852 | P12: 0.339852 | Q12: 0.339852
A13: SG&A / revenue | B13: a.opex_pct | H13: 0.057192 | I13: 0.057192 | J13: 0.057192 | K13: 0.057192 | L13: 0.057192 | M13: 0.057192 | N13: 0.057192 | O13: 0.057192 | P13: 0.057192 | Q13: 0.057192
A14: D&A / revenue | B14: a.da_pct | H14: 0.126756 | I14: 0.126756 | J14: 0.126756 | K14: 0.126756 | L14: 0.126756 | M14: 0.126756 | N14: 0.126756 | O14: 0.126756 | P14: 0.126756 | Q14: 0.126756
A15: Capex / revenue | B15: a.capex_pct | H15: 0.177 | I15: 0.16 | J15: 0.15 | K15: 0.14 | L15: 0.14 | M15: 0.14 | N15: 0.14 | O15: 0.14 | P15: 0.14 | Q15: 0.14
A16: Operating working capital / revenue | B16: a.nwc_pct | H16: -0.0927 | I16: -0.0927 | J16: -0.0927 | K16: -0.0927 | L16: -0.0927 | M16: -0.0927 | N16: -0.0927 | O16: -0.0927 | P16: -0.0927 | Q16: -0.0927
A17: Effective tax rate | B17: a.tax_rate | H17: 0.200202 | I17: 0.200202 | J17: 0.200202 | K17: 0.200202 | L17: 0.200202 | M17: 0.200202 | N17: 0.200202 | O17: 0.200202 | P17: 0.200202 | Q17: 0.200202
A18: Cost of debt (on opening debt) | B18: a.cost_of_debt | C18: 0.020375
A19: Yield on opening cash | B19: a.cash_yield | C19: 0.047925
A20: Net new borrowing | B20: a.net_borrowing | H20: 1118.124 | I20: 150 | J20: 150 | K20: 150 | L20: 150 | M20: 153 | N20: 156.06 | O20: 159.1812 | P20: 162.36482 | Q20: 165.61212
A21: Other non-operating items | B21: a.other_nonop | H21: 0 | I21: 0 | J21: 0 | K21: 0 | L21: 0 | M21: 0 | N21: 0 | O21: 0 | P21: 0 | Q21: 0
A22: Minorities' share of net profit | B22: a.minority_pct | H22: 0.086048 | I22: 0.086048 | J22: 0.086048 | K22: 0.086048 | L22: 0.086048 | M22: 0.086048 | N22: 0.086048 | O22: 0.086048 | P22: 0.086048 | Q22: 0.086048
A23: Dividend payout | B23: a.payout | H23: 0.9996 | I23: 0.8 | J23: 0.7 | K23: 0.6 | L23: 0.6 | M23: 0.6 | N23: 0.6 | O23: 0.6 | P23: 0.6 | Q23: 0.6
A24: Change in share count | B24: a.share_change | H24: 0 | I24: 0 | J24: 0 | K24: 0 | L24: 0 | M24: 0 | N24: 0 | O24: 0 | P24: 0 | Q24: 0
A25: Terminal growth (DCF) | B25: a.terminal_growth | C25: 0.02
A26: Holding-company discount to SOTP | B26: a.holdco_discount | C26: 0.3
A28: MODEL
A29: Revenue | B29: revenue | D29: 8102.399 | E29: 2135.412 | F29: 2078.689 | G29: 1874 | H29: =(G29*(1+H11)) | I29: =(H29*(1+I11)) | J29: =(I29*(1+J11)) | K29: =(J29*(1+K11)) | L29: =(K29*(1+L11)) | M29: =(L29*(1+M11)) | N29: =(M29*(1+N11)) | O29: =(N29*(1+O11)) | ... Q29: =(P29*(1+Q11))
A30: Cost of revenue | B30: cogs | D30: 3449.427 | E30: 1267.731 | F30: 1204.69 | G30: 1236.892 | H30: =(H29*(1-H12)) | I30: =(I29*(1-I12)) | J30: =(J29*(1-J12)) | K30: =(K29*(1-K12)) | L30: =(L29*(1-L12)) | M30: =(M29*(1-M12)) | N30: =(N29*(1-N12)) | O30: =(O29*(1-O12)) | ... Q30: =(Q29*(1-Q12))
A31: Gross profit | B31: gross_profit | D31: 4652.972 | E31: 867.681 | F31: 873.999 | G31: 636.636 | H31: =(H29-H30) | I31: =(I29-I30) | J31: =(J29-J30) | K31: =(K29-K30) | L31: =(L29-L30) | M31: =(M29-M30) | N31: =(N29-N30) | O31: =(O29-O30) | ... Q31: =(Q29-Q30)
A32: SG&A and other opex | B32: opex | D32: 375.974 | E32: 93.945 | F32: 140.357 | G32: 107.149 | H32: =(H29*H13) | I32: =(I29*I13) | J32: =(J29*J13) | K32: =(K29*K13) | L32: =(L29*L13) | M32: =(M29*M13) | N32: =(N29*N13) | O32: =(O29*O13) | ... Q32: =(Q29*Q13)
A33: EBIT | B33: ebit | D33: 4276.998 | E33: 773.736 | F33: 733.642 | G33: 529.487 | H33: =(H31-H32) | I33: =(I31-I32) | J33: =(J31-J32) | K33: =(K31-K32) | L33: =(L31-L32) | M33: =(M31-M32) | N33: =(N31-N32) | O33: =(O31-O32) | ... Q33: =(Q31-Q32)
A34: Depreciation & amortisation | B34: da | D34: 6.847 | E34: 4.893 | F34: 210.763 | G34: 237.474 | H34: =(H29*H14) | I34: =(I29*I14) | J34: =(J29*J14) | K34: =(K29*K14) | L34: =(L29*L14) | M34: =(M29*M14) | N34: =(N29*N14) | O34: =(O29*O14) | ... Q34: =(Q29*Q14)
A35: EBITDA | B35: ebitda | D35: 4283.845 | E35: 778.629 | F35: 944.405 | G35: 766.961 | H35: =(H33+H34) | I35: =(I33+I34) | J35: =(J33+J34) | K35: =(K33+K34) | L35: =(L33+L34) | M35: =(M33+M34) | N35: =(N33+N34) | O35: =(O33+O34) | ... Q35: =(Q33+Q34)
A36: Interest expense | B36: interest_expense | D36: 74.744 | E36: 60.059 | F36: 43.773 | G36: 11.814 | H36: =(G56*$C$18) | I36: =(H56*$C$18) | J36: =(I56*$C$18) | K36: =(J56*$C$18) | L36: =(K56*$C$18) | M36: =(L56*$C$18) | N36: =(M56*$C$18) | O36: =(N56*$C$18) | ... Q36: =(P56*$C$18)
A37: Interest income | B37: interest_income | D37: 47.397 | E37: 65.965 | F37: 118.218 | G37: 97.461 | H37: =(G55*$C$19) | I37: =(H55*$C$19) | J37: =(I55*$C$19) | K37: =(J55*$C$19) | L37: =(K55*$C$19) | M37: =(L55*$C$19) | N37: =(M55*$C$19) | O37: =(N55*$C$19) | ... Q37: =(P55*$C$19)
A38: Other non-operating | B38: other_nonop | D38: 226.568 | E38: 38.946 | F38: 1.733 | G38: -2.673 | H38: =H21 | I38: =I21 | J38: =J21 | K38: =K21 | L38: =L21 | M38: =M21 | N38: =N21 | O38: =O21 | ... Q38: =Q21
A39: Profit before tax | B39: pbt | D39: 4476.219 | E39: 818.588 | F39: 809.82 | G39: 612.461 | H39: =(((H33-H36)+H37)+H38) | I39: =(((I33-I36)+I37)+I38) | J39: =(((J33-J36)+J37)+J38) | K39: =(((K33-K36)+K37)+K38) | L39: =(((L33-L36)+L37)+L38) | M39: =(((M33-M36)+M37)+M38) | N39: =(((N33-N36)+N37)+N38) | O39: =(((O33-O36)+O37)+O38) | ... Q39: =(((Q33-Q36)+Q37)+Q38)
A40: Tax | B40: tax | D40: 1645.096 | E40: 165.282 | F40: 172.336 | G40: 122.616 | H40: =(MAX(H39,0)*H17) | I40: =(MAX(I39,0)*I17) | J40: =(MAX(J39,0)*J17) | K40: =(MAX(K39,0)*K17) | L40: =(MAX(L39,0)*L17) | M40: =(MAX(M39,0)*M17) | N40: =(MAX(N39,0)*N17) | O40: =(MAX(O39,0)*O17) | ... Q40: =(MAX(Q39,0)*Q17)
A41: Net profit (incl. minorities) | B41: np | D41: 2831.123 | E41: 1854.878 | F41: 1556.132 | G41: 489.845 | H41: =(H39-H40) | I41: =(I39-I40) | J41: =(J39-J40) | K41: =(K39-K40) | L41: =(L39-L40) | M41: =(M39-M40) | N41: =(N39-N40) | O41: =(O39-O40) | ... Q41: =(Q39-Q40)
A42: Minority interests | B42: minority | D42: 338.043 | E42: 213.441 | F42: 176.119 | G42: 42.151 | H42: =(H41*H22) | I42: =(I41*I22) | J42: =(J41*J22) | K42: =(K41*K22) | L42: =(L41*L22) | M42: =(M41*M22) | N42: =(N41*N22) | O42: =(O41*O22) | ... Q42: =(Q41*Q22)
A43: Net profit to parent | B43: np_parent | D43: 2493.08 | E43: 1641.437 | F43: 1380.013 | G43: 447.69422 | H43: =(H41-H42) | I43: =(I41-I42) | J43: =(J41-J42) | K43: =(K41-K42) | L43: =(L41-L42) | M43: =(M41-M42) | N43: =(N41-N42) | O43: =(O41-O42) | ... Q43: =(Q41-Q42)
A44: Shares outstanding (m) | B44: shares | D44: 30985.962 | E44: 30881.206 | F44: 30244.918 | G44: 28800.494 | H44: =(G44*(1+H24)) | I44: =(H44*(1+I24)) | J44: =(I44*(1+J24)) | K44: =(J44*(1+K24)) | L44: =(K44*(1+L24)) | M44: =(L44*(1+M24)) | N44: =(M44*(1+N24)) | O44: =(N44*(1+O24)) | ... Q44: =(P44*(1+Q24))
...

Sheet ASII
A1: PT Astra International Tbk (ASII.JK) — Conglomerates & multi-sector holdings
A2: Units: IDR bn; per-share in IDR unless marked IDR. Model asof 2026-10-29 · data 2026-10-26
A4: Line | C4: Scalar | D4: FY2022A | E4: FY2023A | F4: FY2024A | G4: FY2025A | H4: FY2026E | I4: FY2027E | J4: FY2028E | K4: FY2029E | L4: FY2030E | M4: FY2031E | N4: FY2032E | O4: FY2033E | P4: FY2034E | Q4: FY2035E
A6: PARAMETERS
A7: ps_factor | C7: 1000
A8: vp_factor | C8: 1
A10: INPUTS (company assumptions)
A11: Revenue growth | B11: a.revenue_growth | H11: 0.01 | I11: 0.05 | J11: 0.05 | K11: 0.05 | L11: 0.05 | M11: 0.05 | N11: 0.05 | O11: 0.05 | P11: 0.05 | Q11: 0.05
A12: Gross margin at base input costs | B12: a.gross_margin | H12: 0.2169 | I12: 0.220925 | J12: 0.220925 | K12: 0.220925 | L12: 0.220925 | M12: 0.220925 | N12: 0.220925 | O12: 0.220925 | P12: 0.220925 | Q12: 0.220925
A13: SG&A / revenue | B13: a.opex_pct | H13: 0.1112 | I13: 0.1084 | J13: 0.1084 | K13: 0.1084 | L13: 0.1084 | M13: 0.1084 | N13: 0.1084 | O13: 0.1084 | P13: 0.1084 | Q13: 0.1084
A14: D&A / revenue | B14: a.da_pct | H14: 0.055261 | I14: 0.055261 | J14: 0.055261 | K14: 0.055261 | L14: 0.055261 | M14: 0.055261 | N14: 0.055261 | O14: 0.055261 | P14: 0.055261 | Q14: 0.055261
A15: Capex / revenue | B15: a.capex_pct | H15: 0.053928 | I15: 0.053928 | J15: 0.053928 | K15: 0.053928 | L15: 0.053928 | M15: 0.053928 | N15: 0.053928 | O15: 0.053928 | P15: 0.053928 | Q15: 0.053928
A16: Operating working capital / revenue | B16: a.nwc_pct | H16: 0.140455 | I16: 0.140455 | J16: 0.140455 | K16: 0.140455 | L16: 0.140455 | M16: 0.140455 | N16: 0.140455 | O16: 0.140455 | P16: 0.140455 | Q16: 0.140455
A17: Effective tax rate | B17: a.tax_rate | H17: 0.184904 | I17: 0.184904 | J17: 0.184904 | K17: 0.184904 | L17: 0.184904 | M17: 0.184904 | N17: 0.184904 | O17: 0.184904 | P17: 0.184904 | Q17: 0.184904
A18: Cost of debt (on opening debt) | B18: a.cost_of_debt | C18: 0.040635
A19: Yield on opening cash | B19: a.cash_yield | C19: 0.067378
A20: Net new borrowing | B20: a.net_borrowing | H20: 0 | I20: 0 | J20: 0 | K20: 0 | L20: 0 | M20: 0 | N20: 0 | O20: 0 | P20: 0 | Q20: 0
A21: Other non-operating items | B21: a.other_nonop | H21: 11548 | I21: 10702 | J21: 10702 | K21: 10702 | L21: 10702 | M21: 10969.55 | N21: 11243.789 | O21: 11524.883 | P21: 11813.006 | Q21: 12108.331
A22: Minorities' share of net profit | B22: a.minority_pct | H22: 0.095 | I22: 0.115 | J22: 0.12 | K22: 0.12 | L22: 0.12 | M22: 0.12 | N22: 0.12 | O22: 0.12 | P22: 0.12 | Q22: 0.12
A23: Dividend payout | B23: a.payout | H23: 0.5 | I23: 0.5 | J23: 0.5 | K23: 0.5 | L23: 0.5 | M23: 0.5 | N23: 0.5 | O23: 0.5 | P23: 0.5 | Q23: 0.5
A24: Change in share count | B24: a.share_change | H24: -0.013 | I24: 0 | J24: 0 | K24: 0 | L24: 0 | M24: 0 | N24: 0 | O24: 0 | P24: 0 | Q24: 0
A25: Terminal growth (DCF) | B25: a.terminal_growth | C25: 0.04
A26: Holding-company discount to SOTP | B26: a.holdco_discount | C26: 0.25
A28: MODEL
A29: Revenue | B29: revenue | D29: 301379 | E29: 316565 | F29: 328480 | G29: 323392 | H29: =(G29*(1+H11)) | I29: =(H29*(1+I11)) | J29: =(I29*(1+J11)) | K29: =(J29*(1+K11)) | L29: =(K29*(1+L11)) | M29: =(L29*(1+M11)) | N29: =(M29*(1+N11)) | O29: =(N29*(1+O11)) | ... Q29: =(P29*(1+Q11))
A30: Cost of revenue | B30: cogs | D30: 231291 | E30: 243255 | F30: 255421 | G30: 251948 | H30: =(H29*(1-H12)) | I30: =(I29*(1-I12)) | J30: =(J29*(1-J12)) | K30: =(K29*(1-K12)) | L30: =(L29*(1-L12)) | M30: =(M29*(1-M12)) | N30: =(N29*(1-N12)) | O30: =(O29*(1-O12)) | ... Q30: =(Q29*(1-Q12))
A31: Gross profit | B31: gross_profit | D31: 70088 | E31: 73310 | F31: 73059 | G31: 71444 | H31: =(H29-H30) | I31: =(I29-I30) | J31: =(J29-J30) | K31: =(K29-K30) | L31: =(L29-L30) | M31: =(M29-M30) | N31: =(N29-N30) | O31: =(O29-O30) | ... Q31: =(Q29-Q30)
A32: SG&A and other opex | B32: opex | D32: 27887 | E32: 29042 | F32: 30659 | G32: 32779 | H32: =(H29*H13) | I32: =(I29*I13) | J32: =(J29*J13) | K32: =(K29*K13) | L32: =(L29*L13) | M32: =(M29*M13) | N32: =(N29*N13) | O32: =(O29*O13) | ... Q32: =(Q29*Q13)
A33: EBIT | B33: ebit | D33: 42201 | E33: 44268 | F33: 42400 | G33: 38665 | H33: =(H31-H32) | I33: =(I31-I32) | J33: =(J31-J32) | K33: =(K31-K32) | L33: =(L31-L32) | M33: =(M31-M32) | N33: =(N31-N32) | O33: =(O31-O32) | ... Q33: =(Q31-Q32)
A34: Depreciation & amortisation | B34: da | F34: 16696 | G34: 17871 | H34: =(H29*H14) | I34: =(I29*I14) | J34: =(J29*J14) | K34: =(K29*K14) | L34: =(L29*L14) | M34: =(M29*M14) | N34: =(N29*N14) | O34: =(O29*O14) | ... Q34: =(Q29*Q14)
A35: EBITDA | B35: ebitda | F35: 59096 | G35: 56536 | H35: =(H33+H34) | I35: =(I33+I34) | J35: =(J33+J34) | K35: =(K33+K34) | L35: =(L33+L34) | M35: =(M33+M34) | N35: =(N33+N34) | O35: =(O33+O34) | ... Q35: =(Q33+Q34)
A36: Interest expense | B36: interest_expense | D36: 2107 | E36: 3112 | F36: 3808 | G36: 3734 | H36: =(G56*$C$18) | I36: =(H56*$C$18) | J36: =(I56*$C$18) | K36: =(J56*$C$18) | L36: =(K56*$C$18) | M36: =(L56*$C$18) | N36: =(M56*$C$18) | O36: =(N56*$C$18) | ... Q36: =(P56*$C$18)
A37: Interest income | B37: interest_income | D37: 2535 | E37: 3053 | F37: 3289 | G37: 3655 | H37: =(G55*$C$19) | I37: =(H55*$C$19) | J37: =(I55*$C$19) | K37: =(J55*$C$19) | L37: =(K55*$C$19) | M37: =(L55*$C$19) | N37: =(M55*$C$19) | O37: =(N55*$C$19) | ... Q37: =(P55*$C$19)
A38: Other non-operating | B38: other_nonop | D38: 7761 | E38: 10520 | F38: 11120 | G38: 10702 | H38: =H21 | I38: =I21 | J38: =J21 | K38: =K21 | L38: =L21 | M38: =M21 | N38: =N21 | O38: =O21 | ... Q38: =Q21
A39: Profit before tax | B39: pbt | D39: 50390 | E39: 54729 | F39: 53001 | G39: 49288 | H39: =(((H33-H36)+H37)+H38) | I39: =(((I33-I36)+I37)+I38) | J39: =(((J33-J36)+J37)+J38) | K39: =(((K33-K36)+K37)+K38) | L39: =(((L33-L36)+L37)+L38) | M39: =(((M33-M36)+M37)+M38) | N39: =(((N33-N36)+N37)+N38) | O39: =(((O33-O36)+O37)+O38) | ... Q39: =(((Q33-Q36)+Q37)+Q38)
A40: Tax | B40: tax | D40: 9970 | E40: 10228 | F40: 9728 | G40: 9083 | H40: =(MAX(H39,0)*H17) | I40: =(MAX(I39,0)*I17) | J40: =(MAX(J39,0)*J17) | K40: =(MAX(K39,0)*K17) | L40: =(MAX(L39,0)*L17) | M40: =(MAX(M39,0)*M17) | N40: =(MAX(N39,0)*N17) | O40: =(MAX(O39,0)*O17) | ... Q40: =(MAX(Q39,0)*Q17)
A41: Net profit (incl. minorities) | B41: np | D41: 40420 | E41: 44501 | F41: 43273 | G41: 40205 | H41: =(H39-H40) | I41: =(I39-I40) | J41: =(J39-J40) | K41: =(K39-K40) | L41: =(L39-L40) | M41: =(M39-M40) | N41: =(N39-N40) | O41: =(O39-O40) | ... Q41: =(Q39-Q40)
A42: Minority interests | B42: minority | D42: 11476 | E42: 10662 | F42: 9372 | G42: 7436 | H42: =(H41*H22) | I42: =(I41*I22) | J42: =(J41*J22) | K42: =(K41*K22) | L42: =(L41*L22) | M42: =(M41*M22) | N42: =(N41*N22) | O42: =(O41*O22) | ... Q42: =(Q41*Q22)
A43: Net profit to parent | B43: np_parent | D43: 28944 | E43: 33839 | F43: 33901 | G43: 32769 | H43: =(H41-H42) | I43: =(I41-I42) | J43: =(J41-J42) | K43: =(K41-K42) | L43: =(L41-L42) | M43: =(M41-M42) | N43: =(N41-N42) | O43: =(O41-O42) | ... Q43: =(Q41-Q42)
A44: Shares outstanding (m) | B44: shares | D44: 40483.553 | E44: 40483.553 | F44: 40483.553 | G44: 40213.715 | H44: =(G44*(1+H24)) | I44: =(H44*(1+I24)) | J44: =(I44*(1+J24)) | K44: =(J44*(1+K24)) | L44: =(K44*(1+L24)) | M44: =(L44*(1+M24)) | N44: =(M44*(1+N24)) | O44: =(N44*(1+O24)) | ... Q44: =(P44*(1+Q24))
...

Sheet BHIT
A1: PT MNC Asia Holding Tbk (BHIT.JK) — Conglomerates & multi-sector holdings
A2: Units: IDR bn; per-share in IDR unless marked IDR. Model asof 2026-10-29 · data 2026-10-27
A4: Line | C4: Scalar | D4: FY2022A | E4: FY2023A | F4: FY2024A | G4: FY2025A | H4: FY2026E | I4: FY2027E | J4: FY2028E | K4: FY2029E | L4: FY2030E | M4: FY2031E | N4: FY2032E | O4: FY2033E | P4: FY2034E | Q4: FY2035E
A6: PARAMETERS
A7: ps_factor | C7: 1000
A8: vp_factor | C8: 1
A10: INPUTS (company assumptions)
A11: Revenue growth | B11: a.revenue_growth | H11: -0.042023 | I11: 0 | J11: 0.0328 | K11: 0.0328 | L11: 0.0328 | M11: 0.0328 | N11: 0.0328 | O11: 0.0328 | P11: 0.0328 | Q11: 0.0328
A12: Gross margin at base input costs | B12: a.gross_margin | H12: 0.37572 | I12: 0.37572 | J12: 0.37572 | K12: 0.37572 | L12: 0.37572 | M12: 0.37572 | N12: 0.37572 | O12: 0.37572 | P12: 0.37572 | Q12: 0.37572
A13: SG&A / revenue | B13: a.opex_pct | H13: 0.2178 | I13: 0.2178 | J13: 0.2178 | K13: 0.2178 | L13: 0.2178 | M13: 0.2178 | N13: 0.2178 | O13: 0.2178 | P13: 0.2178 | Q13: 0.2178
A14: D&A / revenue | B14: a.da_pct | H14: 0.08946 | I14: 0.08946 | J14: 0.08946 | K14: 0.08946 | L14: 0.08946 | M14: 0.08946 | N14: 0.08946 | O14: 0.08946 | P14: 0.08946 | Q14: 0.08946
A15: Capex / revenue | B15: a.capex_pct | H15: 0.06242 | I15: 0.06242 | J15: 0.06242 | K15: 0.06242 | L15: 0.06242 | M15: 0.06242 | N15: 0.06242 | O15: 0.06242 | P15: 0.06242 | Q15: 0.06242
A16: Operating working capital / revenue | B16: a.nwc_pct | H16: -0.067516 | I16: -0.067516 | J16: -0.067516 | K16: -0.067516 | L16: -0.067516 | M16: -0.067516 | N16: -0.067516 | O16: -0.067516 | P16: -0.067516 | Q16: -0.067516
A17: Effective tax rate | B17: a.tax_rate | H17: 0.15229 | I17: 0.15229 | J17: 0.15229 | K17: 0.15229 | L17: 0.15229 | M17: 0.15229 | N17: 0.15229 | O17: 0.15229 | P17: 0.15229 | Q17: 0.15229
A18: Cost of debt (on opening debt) | B18: a.cost_of_debt | C18: 0.092545
A19: Yield on opening cash | B19: a.cash_yield | C19: 0.004067
A20: Net new borrowing | B20: a.net_borrowing | H20: 0 | I20: 0 | J20: 0 | K20: 0 | L20: 0 | M20: 0 | N20: 0 | O20: 0 | P20: 0 | Q20: 0
A21: Other non-operating items | B21: a.other_nonop | H21: -292.851 | I21: -292.851 | J21: -292.851 | K21: -292.851 | L21: -292.851 | M21: -300.17228 | N21: -307.67658 | O21: -315.3685 | P21: -323.25271 | Q21: -331.33403
A22: Minorities' share of net profit | B22: a.minority_pct | H22: 0.78118 | I22: 0.78118 | J22: 0.78118 | K22: 0.78118 | L22: 0.78118 | M22: 0.78118 | N22: 0.78118 | O22: 0.78118 | P22: 0.78118 | Q22: 0.78118
A23: Dividend payout | B23: a.payout | H23: 0 | I23: 0 | J23: 0 | K23: 0 | L23: 0 | M23: 0 | N23: 0 | O23: 0 | P23: 0 | Q23: 0
A24: Change in share count | B24: a.share_change | H24: 0 | I24: 0 | J24: 0 | K24: 0 | L24: 0 | M24: 0 | N24: 0 | O24: 0 | P24: 0 | Q24: 0
A25: Terminal growth (DCF) | B25: a.terminal_growth | C25: 0.0328
A26: Holding-company discount to SOTP | B26: a.holdco_discount | C26: 0.4
A28: MODEL
A29: Revenue | B29: revenue | D29: 18083.695 | E29: 15660.503 | F29: 15139.665 | G29: 14490.421 | H29: =(G29*(1+H11)) | I29: =(H29*(1+I11)) | J29: =(I29*(1+J11)) | K29: =(J29*(1+K11)) | L29: =(K29*(1+L11)) | M29: =(L29*(1+M11)) | N29: =(M29*(1+N11)) | O29: =(N29*(1+O11)) | ... Q29: =(P29*(1+Q11))
A30: Cost of revenue | B30: cogs | D30: 9275.283 | E30: 9357.258 | F30: 9166.35 | G30: 8732.33 | H30: =(H29*(1-H12)) | I30: =(I29*(1-I12)) | J30: =(J29*(1-J12)) | K30: =(K29*(1-K12)) | L30: =(L29*(1-L12)) | M30: =(M29*(1-M12)) | N30: =(N29*(1-N12)) | O30: =(O29*(1-O12)) | ... Q30: =(Q29*(1-Q12))
A31: Gross profit | B31: gross_profit | D31: 8808.412 | E31: 6303.245 | F31: 5973.315 | G31: 5758.091 | H31: =(H29-H30) | I31: =(I29-I30) | J31: =(J29-J30) | K31: =(K29-K30) | L31: =(L29-L30) | M31: =(M29-M30) | N31: =(N29-N30) | O31: =(O29-O30) | ... Q31: =(Q29-Q30)
A32: SG&A and other opex | B32: opex | D32: 3849.835 | E32: 3757.646 | F32: 3264.232 | G32: 3221.662 | H32: =(H29*H13) | I32: =(I29*I13) | J32: =(J29*J13) | K32: =(K29*K13) | L32: =(L29*L13) | M32: =(M29*M13) | N32: =(N29*N13) | O32: =(O29*O13) | ... Q32: =(Q29*Q13)
A33: EBIT | B33: ebit | D33: 4958.577 | E33: 2545.599 | F33: 2709.083 | G33: 2536.429 | H33: =(H31-H32) | I33: =(I31-I32) | J33: =(J31-J32) | K33: =(K31-K32) | L33: =(L31-L32) | M33: =(M31-M32) | N33: =(N31-N32) | O33: =(O31-O32) | ... Q33: =(Q31-Q32)
A34: Depreciation & amortisation | B34: da | D34: 524.315 | E34: 527.977 | F34: 1340.84 | G34: 1360.403 | H34: =(H29*H14) | I34: =(I29*I14) | J34: =(J29*J14) | K34: =(K29*K14) | L34: =(L29*L14) | M34: =(M29*M14) | N34: =(N29*N14) | O34: =(O29*O14) | ... Q34: =(Q29*Q14)
A35: EBITDA | B35: ebitda | D35: 5482.892 | E35: 3073.576 | F35: 4049.923 | G35: 3896.832 | H35: =(H33+H34) | I35: =(I33+I34) | J35: =(J33+J34) | K35: =(K33+K34) | L35: =(L33+L34) | M35: =(M33+M34) | N35: =(N33+N34) | O35: =(O33+O34) | ... Q35: =(Q33+Q34)
A36: Interest expense | B36: interest_expense | D36: 830.93 | E36: 985.193 | F36: 1189.784 | G36: 1115.351 | H36: =(G56*$C$18) | I36: =(H56*$C$18) | J36: =(I56*$C$18) | K36: =(J56*$C$18) | L36: =(K56*$C$18) | M36: =(L56*$C$18) | N36: =(M56*$C$18) | O36: =(N56*$C$18) | ... Q36: =(P56*$C$18)
A37: Interest income | B37: interest_income | D37: 40.071 | E37: 52.074 | F37: 39.978 | G37: 32.14 | H37: =(G55*$C$19) | I37: =(H55*$C$19) | J37: =(I55*$C$19) | K37: =(J55*$C$19) | L37: =(K55*$C$19) | M37: =(L55*$C$19) | N37: =(M55*$C$19) | O37: =(N55*$C$19) | ... Q37: =(P55*$C$19)
A38: Other non-operating | B38: other_nonop | D38: -653.738 | E38: -213.387 | F38: -320.118 | G38: 206.094 | H38: =H21 | I38: =I21 | J38: =J21 | K38: =K21 | L38: =L21 | M38: =M21 | N38: =N21 | O38: =O21 | ... Q38: =Q21
A39: Profit before tax | B39: pbt | D39: 3513.98 | E39: 1399.093 | F39: 1239.159 | G39: 1659.312 | H39: =(((H33-H36)+H37)+H38) | I39: =(((I33-I36)+I37)+I38) | J39: =(((J33-J36)+J37)+J38) | K39: =(((K33-K36)+K37)+K38) | L39: =(((L33-L36)+L37)+L38) | M39: =(((M33-M36)+M37)+M38) | N39: =(((N33-N36)+N37)+N38) | O39: =(((O33-O36)+O37)+O38) | ... Q39: =(((Q33-Q36)+Q37)+Q38)
A40: Tax | B40: tax | D40: 831.76 | E40: 165.62 | F40: 295.4 | G40: 252.687 | H40: =(MAX(H39,0)*H17) | I40: =(MAX(I39,0)*I17) | J40: =(MAX(J39,0)*J17) | K40: =(MAX(K39,0)*K17) | L40: =(MAX(L39,0)*L17) | M40: =(MAX(M39,0)*M17) | N40: =(MAX(N39,0)*N17) | O40: =(MAX(O39,0)*O17) | ... Q40: =(MAX(Q39,0)*Q17)
A41: Net profit (incl. minorities) | B41: np | D41: 2682.22 | E41: 1233.473 | F41: 943.759 | G41: 1406.625 | H41: =(H39-H40) | I41: =(I39-I40) | J41: =(J39-J40) | K41: =(K39-K40) | L41: =(L39-L40) | M41: =(M39-M40) | N41: =(N39-N40) | O41: =(O39-O40) | ... Q41: =(Q39-Q40)
A42: Minority interests | B42: minority | D42: 1951.941 | E42: 926.881 | F42: 753.739 | G42: 928.085 | H42: =(H41*H22) | I42: =(I41*I22) | J42: =(J41*J22) | K42: =(K41*K22) | L42: =(L41*L22) | M42: =(M41*M22) | N42: =(N41*N22) | O42: =(O41*O22) | ... Q42: =(Q41*Q22)
A43: Net profit to parent | B43: np_parent | D43: 730.279 | E43: 306.592 | F43: 190.02 | G43: 478.54 | H43: =(H41-H42) | I43: =(I41-I42) | J43: =(J41-J42) | K43: =(K41-K42) | L43: =(L41-L42) | M43: =(M41-M42) | N43: =(N41-N42) | O43: =(O41-O42) | ... Q43: =(Q41-Q42)
A44: Shares outstanding (m) | B44: shares | D44: 83542.742 | E44: 83542.742 | F44: 83542.742 | G44: 83542.742 | H44: =(G44*(1+H24)) | I44: =(H44*(1+I24)) | J44: =(I44*(1+J24)) | K44: =(J44*(1+K24)) | L44: =(K44*(1+L24)) | M44: =(L44*(1+M24)) | N44: =(M44*(1+N24)) | O44: =(N44*(1+O24)) | ... Q44: =(P44*(1+Q24))
...

Sheet BNBR
A1: PT Bakrie & Brothers Tbk (BNBR.JK) — Conglomerates & multi-sector holdings
A2: Units: IDR bn; per-share in IDR unless marked IDR. Model asof 2026-10-29 · data 2026-10-27
A4: Line | C4: Scalar | D4: FY2022A | E4: FY2023A | F4: FY2024A | G4: FY2025A | H4: FY2026E | I4: FY2027E | J4: FY2028E | K4: FY2029E | L4: FY2030E | M4: FY2031E | N4: FY2032E | O4: FY2033E | P4: FY2034E | Q4: FY2035E
A6: PARAMETERS
A7: ps_factor | C7: 1000
A8: vp_factor | C8: 1
A10: INPUTS (company assumptions)
A11: Revenue growth | B11: a.revenue_growth | H11: 0.38 | I11: 0.08 | J11: 0.06 | K11: 0.05 | L11: 0.04 | M11: 0.04 | N11: 0.04 | O11: 0.04 | P11: 0.04 | Q11: 0.04
A12: Gross margin at base input costs | B12: a.gross_margin | H12: 0.251 | I12: 0.251 | J12: 0.251 | K12: 0.251 | L12: 0.251 | M12: 0.251 | N12: 0.251 | O12: 0.251 | P12: 0.251 | Q12: 0.251
A13: SG&A / revenue | B13: a.opex_pct | H13: 0.142 | I13: 0.142 | J13: 0.142 | K13: 0.142 | L13: 0.142 | M13: 0.142 | N13: 0.142 | O13: 0.142 | P13: 0.142 | Q13: 0.142
A14: D&A / revenue | B14: a.da_pct | H14: 0.05 | I14: 0.05 | J14: 0.05 | K14: 0.05 | L14: 0.05 | M14: 0.05 | N14: 0.05 | O14: 0.05 | P14: 0.05 | Q14: 0.05
A15: Capex / revenue | B15: a.capex_pct | H15: 0.055 | I15: 0.055 | J15: 0.055 | K15: 0.055 | L15: 0.055 | M15: 0.055 | N15: 0.055 | O15: 0.055 | P15: 0.055 | Q15: 0.055
A16: Operating working capital / revenue | B16: a.nwc_pct | H16: 0.388 | I16: 0.388 | J16: 0.388 | K16: 0.388 | L16: 0.388 | M16: 0.388 | N16: 0.388 | O16: 0.388 | P16: 0.388 | Q16: 0.388
A17: Effective tax rate | B17: a.tax_rate | H17: 0.12 | I17: 0.12 | J17: 0.12 | K17: 0.12 | L17: 0.12 | M17: 0.12 | N17: 0.12 | O17: 0.12 | P17: 0.12 | Q17: 0.12
A18: Cost of debt (on opening debt) | B18: a.cost_of_debt | C18: 0.065
A19: Yield on opening cash | B19: a.cash_yield | C19: 0.055
A20: Net new borrowing | B20: a.net_borrowing | H20: 1000 | I20: 700 | J20: 650 | K20: 640 | L20: 630 | M20: 635.5 | N20: 651.3875 | O20: 667.67219 | P20: 684.36399 | Q20: 701.47309
A21: Other non-operating items | B21: a.other_nonop | H21: 0 | I21: 0 | J21: 0 | K21: 0 | L21: 0 | M21: 0 | N21: 0 | O21: 0 | P21: 0 | Q21: 0
A22: Minorities' share of net profit | B22: a.minority_pct | H22: 0.02 | I22: 0.02 | J22: 0.02 | K22: 0.02 | L22: 0.02 | M22: 0.02 | N22: 0.02 | O22: 0.02 | P22: 0.02 | Q22: 0.02
A23: Dividend payout | B23: a.payout | H23: 0 | I23: 0 | J23: 0 | K23: 0 | L23: 0 | M23: 0 | N23: 0 | O23: 0 | P23: 0 | Q23: 0
A24: Change in share count | B24: a.share_change | H24: 0.51851852 | I24: 0 | J24: 0 | K24: 0 | L24: 0 | M24: 0 | N24: 0 | O24: 0 | P24: 0 | Q24: 0
A25: Terminal growth (DCF) | B25: a.terminal_growth | C25: 0.04
A26: Holding-company discount to SOTP | B26: a.holdco_discount | C26: 0.38
A28: MODEL
A29: Revenue | B29: revenue | D29: 3626.696 | E29: 3759.484 | F29: 3869.905 | G29: 3742.973 | H29: =(G29*(1+H11)) | I29: =(H29*(1+I11)) | J29: =(I29*(1+J11)) | K29: =(J29*(1+K11)) | L29: =(K29*(1+L11)) | M29: =(L29*(1+M11)) | N29: =(M29*(1+N11)) | O29: =(N29*(1+O11)) | ... Q29: =(P29*(1+Q11))
A30: Cost of revenue | B30: cogs | D30: 2910.526 | E30: 2876.109 | F30: 3000.428 | G30: 2998.589 | H30: =(H29*(1-H12)) | I30: =(I29*(1-I12)) | J30: =(J29*(1-J12)) | K30: =(K29*(1-K12)) | L30: =(L29*(1-L12)) | M30: =(M29*(1-M12)) | N30: =(N29*(1-N12)) | O30: =(O29*(1-O12)) | ... Q30: =(Q29*(1-Q12))
A31: Gross profit | B31: gross_profit | D31: 716.17 | E31: 883.375 | F31: 869.477 | G31: 744.384 | H31: =(H29-H30) | I31: =(I29-I30) | J31: =(J29-J30) | K31: =(K29-K30) | L31: =(L29-L30) | M31: =(M29-M30) | N31: =(N29-N30) | O31: =(O29-O30) | ... Q31: =(Q29-Q30)
A32: SG&A and other opex | B32: opex | D32: 800.065 | E32: 567.174 | F32: 586.605 | G32: 627.521 | H32: =(H29*H13) | I32: =(I29*I13) | J32: =(J29*J13) | K32: =(K29*K13) | L32: =(L29*L13) | M32: =(M29*M13) | N32: =(N29*N13) | O32: =(O29*O13) | ... Q32: =(Q29*Q13)
A33: EBIT | B33: ebit | D33: -83.895 | E33: 316.201 | F33: 282.872 | G33: 116.863 | H33: =(H31-H32) | I33: =(I31-I32) | J33: =(J31-J32) | K33: =(K31-K32) | L33: =(L31-L32) | M33: =(M31-M32) | N33: =(N31-N32) | O33: =(O31-O32) | ... Q33: =(Q31-Q32)
A34: Depreciation & amortisation | B34: da | D34: 3.19 | E34: 5.514 | F34: 115.127 | G34: 171.363 | H34: =(H29*H14) | I34: =(I29*I14) | J34: =(J29*J14) | K34: =(K29*K14) | L34: =(L29*L14) | M34: =(M29*M14) | N34: =(N29*N14) | O34: =(O29*O14) | ... Q34: =(Q29*Q14)
A35: EBITDA | B35: ebitda | D35: -80.705 | E35: 321.715 | F35: 397.999 | G35: 288.226 | H35: =(H33+H34) | I35: =(I33+I34) | J35: =(J33+J34) | K35: =(K33+K34) | L35: =(L33+L34) | M35: =(M33+M34) | N35: =(N33+N34) | O35: =(O33+O34) | ... Q35: =(Q33+Q34)
A36: Interest expense | B36: interest_expense | D36: 56.361 | E36: 65.3 | F36: 54.837 | G36: 175.837 | H36: =(G56*$C$18) | I36: =(H56*$C$18) | J36: =(I56*$C$18) | K36: =(J56*$C$18) | L36: =(K56*$C$18) | M36: =(L56*$C$18) | N36: =(M56*$C$18) | O36: =(N56*$C$18) | ... Q36: =(P56*$C$18)
A37: Interest income | B37: interest_income | D37: 4.867 | E37: 12.703 | F37: 13.815 | G37: 93.544 | H37: =(G55*$C$19) | I37: =(H55*$C$19) | J37: =(I55*$C$19) | K37: =(J55*$C$19) | L37: =(K55*$C$19) | M37: =(L55*$C$19) | N37: =(M55*$C$19) | O37: =(N55*$C$19) | ... Q37: =(P55*$C$19)
A38: Other non-operating | B38: other_nonop | D38: 489.109 | E38: 54.364 | F38: 147.38 | G38: 484.262 | H38: =H21 | I38: =I21 | J38: =J21 | K38: =K21 | L38: =L21 | M38: =M21 | N38: =N21 | O38: =O21 | ... Q38: =Q21
A39: Profit before tax | B39: pbt | D39: 353.72 | E39: 317.968 | F39: 389.23 | G39: 518.832 | H39: =(((H33-H36)+H37)+H38) | I39: =(((I33-I36)+I37)+I38) | J39: =(((J33-J36)+J37)+J38) | K39: =(((K33-K36)+K37)+K38) | L39: =(((L33-L36)+L37)+L38) | M39: =(((M33-M36)+M37)+M38) | N39: =(((N33-N36)+N37)+N38) | O39: =(((O33-O36)+O37)+O38) | ... Q39: =(((Q33-Q36)+Q37)+Q38)
A40: Tax | B40: tax | D40: 47.559 | E40: 53.51 | F40: 53.182 | G40: 16.089 | H40: =(MAX(H39,0)*H17) | I40: =(MAX(I39,0)*I17) | J40: =(MAX(J39,0)*J17) | K40: =(MAX(K39,0)*K17) | L40: =(MAX(L39,0)*L17) | M40: =(MAX(M39,0)*M17) | N40: =(MAX(N39,0)*N17) | O40: =(MAX(O39,0)*O17) | ... Q40: =(MAX(Q39,0)*Q17)
A41: Net profit (incl. minorities) | B41: np | D41: 306.161 | E41: 264.458 | F41: 336.048 | G41: 502.743 | H41: =(H39-H40) | I41: =(I39-I40) | J41: =(J39-J40) | K41: =(K39-K40) | L41: =(L39-L40) | M41: =(M39-M40) | N41: =(N39-N40) | O41: =(O39-O40) | ... Q41: =(Q39-Q40)
A42: Minority interests | B42: minority | D42: 40.027 | E42: 26.99 | F42: 8.458 | G42: 8.891 | H42: =(H41*H22) | I42: =(I41*I22) | J42: =(J41*J22) | K42: =(K41*K22) | L42: =(L41*L22) | M42: =(M41*M22) | N42: =(N41*N22) | O42: =(O41*O22) | ... Q42: =(Q41*Q22)
A43: Net profit to parent | B43: np_parent | D43: 266.134 | E43: 237.468 | F43: 327.59 | G43: 493.852 | H43: =(H41-H42) | I43: =(I41-I42) | J43: =(J41-J42) | K43: =(K41-K42) | L43: =(L41-L42) | M43: =(M41-M42) | N43: =(N41-N42) | O43: =(O41-O42) | ... Q43: =(Q41-Q42)
A44: Shares outstanding (m) | B44: shares | D44: 23599.273 | E44: 185717.52 | F44: 201414.78 | G44: 173416.83 | H44: =(G44*(1+H24)) | I44: =(H44*(1+I24)) | J44: =(I44*(1+J24)) | K44: =(J44*(1+K24)) | L44: =(K44*(1+L24)) | M44: =(L44*(1+M24)) | N44: =(M44*(1+N24)) | O44: =(N44*(1+O24)) | ... Q44: =(P44*(1+Q24))
...

Sheet BRPT
A1: PT Barito Pacific Tbk (BRPT.JK) — Conglomerates & multi-sector holdings
A2: Units: USD m; per-share in USD unless marked IDR. Model asof 2026-10-29 · data 2026-10-27
A4: Line | C4: Scalar | D4: FY2022A | E4: FY2023A | F4: FY2024A | G4: FY2025A | H4: FY2026E | I4: FY2027E | J4: FY2028E | K4: FY2029E | L4: FY2030E | M4: FY2031E | N4: FY2032E | O4: FY2033E | P4: FY2034E | Q4: FY2035E
A6: PARAMETERS
A7: ps_factor | C7: 1
A8: vp_factor | C8: 1
A10: INPUTS (company assumptions)
A11: Revenue growth | B11: a.revenue_growth | H11: 0.3 | I11: 0.1 | J11: 0.07 | K11: 0.05 | L11: 0.04 | M11: 0.02 | N11: 0.02 | O11: 0.02 | P11: 0.02 | Q11: 0.02
A12: Gross margin at base input costs | B12: a.gross_margin | H12: 0.191901 | I12: 0.191901 | J12: 0.191901 | K12: 0.191901 | L12: 0.191901 | M12: 0.191901 | N12: 0.191901 | O12: 0.191901 | P12: 0.191901 | Q12: 0.191901
A13: SG&A / revenue | B13: a.opex_pct | H13: 0.111429 | I13: 0.111429 | J13: 0.111429 | K13: 0.111429 | L13: 0.111429 | M13: 0.111429 | N13: 0.111429 | O13: 0.111429 | P13: 0.111429 | Q13: 0.111429
A14: D&A / revenue | B14: a.da_pct | H14: 0.043116 | I14: 0.043116 | J14: 0.043116 | K14: 0.043116 | L14: 0.043116 | M14: 0.043116 | N14: 0.043116 | O14: 0.043116 | P14: 0.043116 | Q14: 0.043116
A15: Capex / revenue | B15: a.capex_pct | H15: 0.127661 | I15: 0.127661 | J15: 0.127661 | K15: 0.127661 | L15: 0.127661 | M15: 0.127661 | N15: 0.127661 | O15: 0.127661 | P15: 0.127661 | Q15: 0.127661
A16: Operating working capital / revenue | B16: a.nwc_pct | H16: 0.183589 | I16: 0.183589 | J16: 0.183589 | K16: 0.183589 | L16: 0.183589 | M16: 0.183589 | N16: 0.183589 | O16: 0.183589 | P16: 0.183589 | Q16: 0.183589
A17: Effective tax rate | B17: a.tax_rate | H17: 0.338994 | I17: 0.338994 | J17: 0.338994 | K17: 0.338994 | L17: 0.338994 | M17: 0.338994 | N17: 0.338994 | O17: 0.338994 | P17: 0.338994 | Q17: 0.338994
A18: Cost of debt (on opening debt) | B18: a.cost_of_debt | C18: 0.078279
A19: Yield on opening cash | B19: a.cash_yield | C19: 0.060805
A20: Net new borrowing | B20: a.net_borrowing | H20: 0 | I20: 0 | J20: 0 | K20: 0 | L20: 0 | M20: 0 | N20: 0 | O20: 0 | P20: 0 | Q20: 0
A21: Other non-operating items | B21: a.other_nonop | H21: 0 | I21: 0 | J21: 0 | K21: 0 | L21: 0 | M21: 0 | N21: 0 | O21: 0 | P21: 0 | Q21: 0
A22: Minorities' share of net profit | B22: a.minority_pct | H22: 0.658493 | I22: 0.658493 | J22: 0.658493 | K22: 0.658493 | L22: 0.658493 | M22: 0.658493 | N22: 0.658493 | O22: 0.658493 | P22: 0.658493 | Q22: 0.658493
A23: Dividend payout | B23: a.payout | H23: 1 | I23: 1 | J23: 1 | K23: 1 | L23: 1 | M23: 1 | N23: 1 | O23: 1 | P23: 1 | Q23: 1
A24: Change in share count | B24: a.share_change | H24: 0 | I24: 0 | J24: 0 | K24: 0 | L24: 0 | M24: 0 | N24: 0 | O24: 0 | P24: 0 | Q24: 0
A25: Terminal growth (DCF) | B25: a.terminal_growth | C25: 0.02
A26: Holding-company discount to SOTP | B26: a.holdco_discount | C26: 0.3
A28: MODEL
A29: Revenue | B29: revenue | D29: 2961.532 | E29: 2760.359 | F29: 2386.995 | G29: 7630.662 | H29: =(G29*(1+H11)) | I29: =(H29*(1+I11)) | J29: =(I29*(1+J11)) | K29: =(J29*(1+K11)) | L29: =(K29*(1+L11)) | M29: =(L29*(1+M11)) | N29: =(M29*(1+N11)) | O29: =(N29*(1+O11)) | ... Q29: =(P29*(1+Q11))
A30: Cost of revenue | B30: cogs | D30: 2515.859 | E30: 2202.219 | F30: 1666.836 | G30: 7082.758 | H30: =(H29*(1-H12)) | I30: =(I29*(1-I12)) | J30: =(J29*(1-J12)) | K30: =(K29*(1-K12)) | L30: =(L29*(1-L12)) | M30: =(M29*(1-M12)) | N30: =(N29*(1-N12)) | O30: =(O29*(1-O12)) | ... Q30: =(Q29*(1-Q12))
A31: Gross profit | B31: gross_profit | D31: 445.673 | E31: 558.14 | F31: 720.159 | G31: 547.904 | H31: =(H29-H30) | I31: =(I29-I30) | J31: =(J29-J30) | K31: =(K29-K30) | L31: =(L29-L30) | M31: =(M29-M30) | N31: =(N29-N30) | O31: =(O29-O30) | ... Q31: =(Q29-Q30)
A32: SG&A and other opex | B32: opex | D32: 177.859 | E32: 209.066 | F32: 381.684 | G32: 752.749 | H32: =(H29*H13) | I32: =(I29*I13) | J32: =(J29*J13) | K32: =(K29*K13) | L32: =(L29*L13) | M32: =(M29*M13) | N32: =(N29*N13) | O32: =(O29*O13) | ... Q32: =(Q29*Q13)
A33: EBIT | B33: ebit | D33: 267.814 | E33: 349.074 | F33: 338.475 | G33: -204.845 | H33: =(H31-H32) | I33: =(I31-I32) | J33: =(J31-J32) | K33: =(K31-K32) | L33: =(L31-L32) | M33: =(M31-M32) | N33: =(N31-N32) | O33: =(O31-O32) | ... Q33: =(Q31-Q32)
A34: Depreciation & amortisation | B34: da | D34: 2.533 | E34: 4.041 | F34: 208.64 | G34: 308.865 | H34: =(H29*H14) | I34: =(I29*I14) | J34: =(J29*J14) | K34: =(K29*K14) | L34: =(L29*L14) | M34: =(M29*M14) | N34: =(N29*N14) | O34: =(O29*O14) | ... Q34: =(Q29*Q14)
A35: EBITDA | B35: ebitda | D35: 270.347 | E35: 353.115 | F35: 547.115 | G35: 104.02 | H35: =(H33+H34) | I35: =(I33+I34) | J35: =(J33+J34) | K35: =(K33+K34) | L35: =(L33+L34) | M35: =(M33+M34) | N35: =(N33+N34) | O35: =(O33+O34) | ... Q35: =(Q33+Q34)
A36: Interest expense | B36: interest_expense | D36: 191.858 | E36: 300.843 | F36: 320.228 | G36: 390.532 | H36: =(G56*$C$18) | I36: =(H56*$C$18) | J36: =(I56*$C$18) | K36: =(J56*$C$18) | L36: =(K56*$C$18) | M36: =(L56*$C$18) | N36: =(M56*$C$18) | O36: =(N56*$C$18) | ... Q36: =(P56*$C$18)
A37: Interest income | B37: interest_income | D37: 30.265 | E37: 104.146 | F37: 128.811 | G37: 152.342 | H37: =(G55*$C$19) | I37: =(H55*$C$19) | J37: =(I55*$C$19) | K37: =(J55*$C$19) | L37: =(K55*$C$19) | M37: =(L55*$C$19) | N37: =(M55*$C$19) | O37: =(N55*$C$19) | ... Q37: =(P55*$C$19)
A38: Other non-operating | B38: other_nonop | D38: 49.202 | E38: 70.841 | F38: 85.638 | G38: 2046.023 | H38: =H21 | I38: =I21 | J38: =J21 | K38: =K21 | L38: =L21 | M38: =M21 | N38: =N21 | O38: =O21 | ... Q38: =Q21
A39: Profit before tax | B39: pbt | D39: 155.423 | E39: 223.218 | F39: 232.696 | G39: 1602.988 | H39: =(((H33-H36)+H37)+H38) | I39: =(((I33-I36)+I37)+I38) | J39: =(((J33-J36)+J37)+J38) | K39: =(((K33-K36)+K37)+K38) | L39: =(((L33-L36)+L37)+L38) | M39: =(((M33-M36)+M37)+M38) | N39: =(((N33-N36)+N37)+N38) | O39: =(((O33-O36)+O37)+O38) | ... Q39: =(((Q33-Q36)+Q37)+Q38)
A40: Tax | B40: tax | D40: 123.213 | E40: 123.442 | F40: 109.8 | G40: -12.646 | H40: =(MAX(H39,0)*H17) | I40: =(MAX(I39,0)*I17) | J40: =(MAX(J39,0)*J17) | K40: =(MAX(K39,0)*K17) | L40: =(MAX(L39,0)*L17) | M40: =(MAX(M39,0)*M17) | N40: =(MAX(N39,0)*N17) | O40: =(MAX(O39,0)*O17) | ... Q40: =(MAX(Q39,0)*Q17)
A41: Net profit (incl. minorities) | B41: np | D41: 32.21 | E41: 99.776 | F41: 122.896 | G41: 1615.634 | H41: =(H39-H40) | I41: =(I39-I40) | J41: =(J39-J40) | K41: =(K39-K40) | L41: =(L39-L40) | M41: =(M39-M40) | N41: =(N39-N40) | O41: =(O39-O40) | ... Q41: =(Q39-Q40)
A42: Minority interests | B42: minority | D42: 30.451 | E42: 73.66 | F42: 66.412 | G42: 1125.827 | H42: =(H41*H22) | I42: =(I41*I22) | J42: =(J41*J22) | K42: =(K41*K22) | L42: =(L41*L22) | M42: =(M41*M22) | N42: =(N41*N22) | O42: =(O41*O22) | ... Q42: =(Q41*Q22)
A43: Net profit to parent | B43: np_parent | D43: 1.759 | E43: 26.116 | F43: 56.484 | G43: 489.807 | H43: =(H41-H42) | I43: =(I41-I42) | J43: =(J41-J42) | K43: =(K41-K42) | L43: =(L41-L42) | M43: =(M41-M42) | N43: =(N41-N42) | O43: =(O41-O42) | ... Q43: =(Q41-Q42)
A44: Shares outstanding (m) | B44: shares | D44: 93711.466 | E44: 93711.466 | F44: 93708.446 | G44: 93711.741 | H44: =(G44*(1+H24)) | I44: =(H44*(1+I24)) | J44: =(I44*(1+J24)) | K44: =(J44*(1+K24)) | L44: =(K44*(1+L24)) | M44: =(L44*(1+M24)) | N44: =(M44*(1+N24)) | O44: =(N44*(1+O24)) | ... Q44: =(P44*(1+Q24))
...

Sheet CUAN
A1: PT Petrindo Jaya Kreasi Tbk (CUAN.JK) — Conglomerates & multi-sector holdings
A2: Units: USD m; per-share in USD unless marked IDR. Model asof 2026-10-29 · data 2026-10-27
A4: Line | C4: Scalar | D4: FY2022A | E4: FY2023A | F4: FY2024A | G4: FY2025A | H4: FY2026E | I4: FY2027E | J4: FY2028E | K4: FY2029E | L4: FY2030E | M4: FY2031E | N4: FY2032E | O4: FY2033E | P4: FY2034E | Q4: FY2035E
A6: PARAMETERS
A7: ps_factor | C7: 1
A8: vp_factor | C8: 1
A10: INPUTS (company assumptions)
A11: Revenue growth | B11: a.revenue_growth | H11: 0.24 | I11: 0.12 | J11: 0.1 | K11: 0.08 | L11: 0.07 | M11: 0.06 | N11: 0.06 | O11: 0.06 | P11: 0.06 | Q11: 0.06
A12: Gross margin at base input costs | B12: a.gross_margin | H12: 0.1381 | I12: 0.1381 | J12: 0.1381 | K12: 0.1381 | L12: 0.1381 | M12: 0.1381 | N12: 0.1381 | O12: 0.1381 | P12: 0.1381 | Q12: 0.1381
A13: SG&A / revenue | B13: a.opex_pct | H13: 0.057314 | I13: 0.057314 | J13: 0.057314 | K13: 0.057314 | L13: 0.057314 | M13: 0.057314 | N13: 0.057314 | O13: 0.057314 | P13: 0.057314 | Q13: 0.057314
A14: D&A / revenue | B14: a.da_pct | H14: 0.1272 | I14: 0.1272 | J14: 0.1272 | K14: 0.1272 | L14: 0.1272 | M14: 0.1272 | N14: 0.1272 | O14: 0.1272 | P14: 0.1272 | Q14: 0.1272
A15: Capex / revenue | B15: a.capex_pct | H15: 0.1 | I15: 0.1 | J15: 0.1 | K15: 0.1 | L15: 0.1 | M15: 0.1 | N15: 0.1 | O15: 0.1 | P15: 0.1 | Q15: 0.1
A16: Operating working capital / revenue | B16: a.nwc_pct | H16: 0.189128 | I16: 0.189128 | J16: 0.189128 | K16: 0.189128 | L16: 0.189128 | M16: 0.189128 | N16: 0.189128 | O16: 0.189128 | P16: 0.189128 | Q16: 0.189128
A17: Effective tax rate | B17: a.tax_rate | H17: 0.38098 | I17: 0.38098 | J17: 0.38098 | K17: 0.38098 | L17: 0.38098 | M17: 0.38098 | N17: 0.38098 | O17: 0.38098 | P17: 0.38098 | Q17: 0.38098
A18: Cost of debt (on opening debt) | B18: a.cost_of_debt | C18: 0.085
A19: Yield on opening cash | B19: a.cash_yield | C19: 0.015
A20: Net new borrowing | B20: a.net_borrowing | H20: 0 | I20: 0 | J20: 0 | K20: 0 | L20: 0 | M20: 0 | N20: 0 | O20: 0 | P20: 0 | Q20: 0
A21: Other non-operating items | B21: a.other_nonop | H21: 0 | I21: 0 | J21: 0 | K21: 0 | L21: 0 | M21: 0 | N21: 0 | O21: 0 | P21: 0 | Q21: 0
A22: Minorities' share of net profit | B22: a.minority_pct | H22: 0.456174 | I22: 0.456174 | J22: 0.456174 | K22: 0.456174 | L22: 0.456174 | M22: 0.456174 | N22: 0.456174 | O22: 0.456174 | P22: 0.456174 | Q22: 0.456174
A23: Dividend payout | B23: a.payout | H23: 0.02 | I23: 0.02 | J23: 0.02 | K23: 0.02 | L23: 0.02 | M23: 0.02 | N23: 0.02 | O23: 0.02 | P23: 0.02 | Q23: 0.02
A24: Change in share count | B24: a.share_change | H24: 0 | I24: 0 | J24: 0 | K24: 0 | L24: 0 | M24: 0 | N24: 0 | O24: 0 | P24: 0 | Q24: 0
A25: Terminal growth (DCF) | B25: a.terminal_growth | C25: 0.02
A26: Holding-company discount to SOTP | B26: a.holdco_discount | C26: 0.3
A28: MODEL
A29: Revenue | B29: revenue | D29: 97.665446 | E29: 97.943 | F29: 801.723 | G29: 1215.618 | H29: =(G29*(1+H11)) | I29: =(H29*(1+I11)) | J29: =(I29*(1+J11)) | K29: =(J29*(1+K11)) | L29: =(K29*(1+L11)) | M29: =(L29*(1+M11)) | N29: =(M29*(1+N11)) | O29: =(N29*(1+O11)) | ... Q29: =(P29*(1+Q11))
A30: Cost of revenue | B30: cogs | D30: 28.191867 | E30: 60.725 | F30: 683.857 | G30: 1055.649 | H30: =(H29*(1-H12)) | I30: =(I29*(1-I12)) | J30: =(J29*(1-J12)) | K30: =(K29*(1-K12)) | L30: =(L29*(1-L12)) | M30: =(M29*(1-M12)) | N30: =(N29*(1-N12)) | O30: =(O29*(1-O12)) | ... Q30: =(Q29*(1-Q12))
A31: Gross profit | B31: gross_profit | D31: 69.473578 | E31: 37.218 | F31: 117.866 | G31: 159.969 | H31: =(H29-H30) | I31: =(I29-I30) | J31: =(J29-J30) | K31: =(K29-K30) | L31: =(L29-L30) | M31: =(M29-M30) | N31: =(N29-N30) | O31: =(O29-O30) | ... Q31: =(Q29-Q30)
A32: SG&A and other opex | B32: opex | D32: 20.983647 | E32: 16.226 | F32: 91.255 | G32: 134.645 | H32: =(H29*H13) | I32: =(I29*I13) | J32: =(J29*J13) | K32: =(K29*K13) | L32: =(L29*L13) | M32: =(M29*M13) | N32: =(N29*N13) | O32: =(O29*O13) | ... Q32: =(Q29*Q13)
A33: EBIT | B33: ebit | D33: 48.489931 | E33: 20.992 | F33: 26.611 | G33: 25.324 | H33: =(H31-H32) | I33: =(I31-I32) | J33: =(J31-J32) | K33: =(K31-K32) | L33: =(L31-L32) | M33: =(M31-M32) | N33: =(N31-N32) | O33: =(O31-O32) | ... Q33: =(Q31-Q32)
A34: Depreciation & amortisation | B34: da | D34: 0.009312828 | E34: 0.013 | F34: 99.857 | G34: 155.318 | H34: =(H29*H14) | I34: =(I29*I14) | J34: =(J29*J14) | K34: =(K29*K14) | L34: =(L29*L14) | M34: =(M29*M14) | N34: =(N29*N14) | O34: =(O29*O14) | ... Q34: =(Q29*Q14)
A35: EBITDA | B35: ebitda | D35: 48.499244 | E35: 21.005 | F35: 126.468 | G35: 180.642 | H35: =(H33+H34) | I35: =(I33+I34) | J35: =(J33+J34) | K35: =(K33+K34) | L35: =(L33+L34) | M35: =(M33+M34) | N35: =(N33+N34) | O35: =(O33+O34) | ... Q35: =(Q33+Q34)
A36: Interest expense | B36: interest_expense | D36: 0.85684659 | E36: 0.954 | F36: 46.127 | G36: 96.072 | H36: =(G56*$C$18) | I36: =(H56*$C$18) | J36: =(I56*$C$18) | K36: =(J56*$C$18) | L36: =(K56*$C$18) | M36: =(L56*$C$18) | N36: =(M56*$C$18) | O36: =(N56*$C$18) | ... Q36: =(P56*$C$18)
A37: Interest income | B37: interest_income | D37: 0.095691848 | E37: 1.118 | F37: 3.758 | G37: 6.263 | H37: =(G55*$C$19) | I37: =(H55*$C$19) | J37: =(I55*$C$19) | K37: =(J55*$C$19) | L37: =(K55*$C$19) | M37: =(L55*$C$19) | N37: =(M55*$C$19) | O37: =(N55*$C$19) | ... Q37: =(P55*$C$19)
A38: Other non-operating | B38: other_nonop | D38: -9.0205621e-16 | E38: -1.568 | F38: 186.798 | G38: 213.755 | H38: =H21 | I38: =I21 | J38: =J21 | K38: =K21 | L38: =L21 | M38: =M21 | N38: =N21 | O38: =O21 | ... Q38: =Q21
A39: Profit before tax | B39: pbt | D39: 47.728776 | E39: 19.588 | F39: 171.04 | G39: 149.27 | H39: =(((H33-H36)+H37)+H38) | I39: =(((I33-I36)+I37)+I38) | J39: =(((J33-J36)+J37)+J38) | K39: =(((K33-K36)+K37)+K38) | L39: =(((L33-L36)+L37)+L38) | M39: =(((M33-M36)+M37)+M38) | N39: =(((N33-N36)+N37)+N38) | O39: =(((O33-O36)+O37)+O38) | ... Q39: =(((Q33-Q36)+Q37)+Q38)
A40: Tax | B40: tax | D40: 11.578737 | E40: 4.338 | F40: 1.07 | G40: -2.725 | H40: =(MAX(H39,0)*H17) | I40: =(MAX(I39,0)*I17) | J40: =(MAX(J39,0)*J17) | K40: =(MAX(K39,0)*K17) | L40: =(MAX(L39,0)*L17) | M40: =(MAX(M39,0)*M17) | N40: =(MAX(N39,0)*N17) | O40: =(MAX(O39,0)*O17) | ... Q40: =(MAX(Q39,0)*Q17)
A41: Net profit (incl. minorities) | B41: np | D41: 36.15004 | E41: 15.25 | F41: 169.97 | G41: 151.995 | H41: =(H39-H40) | I41: =(I39-I40) | J41: =(J39-J40) | K41: =(K39-K40) | L41: =(L39-L40) | M41: =(M39-M40) | N41: =(N39-N40) | O41: =(O39-O40) | ... Q41: =(Q39-Q40)
A42: Minority interests | B42: minority | D42: -0.54461043 | E42: -0.371 | F42: 9.185 | G42: 17.428 | H42: =(H41*H22) | I42: =(I41*I22) | J42: =(J41*J22) | K42: =(K41*K22) | L42: =(L41*L22) | M42: =(M41*M22) | N42: =(N41*N22) | O42: =(O41*O22) | ... Q42: =(Q41*Q22)
A43: Net profit to parent | B43: np_parent | D43: 36.69465 | E43: 15.621 | F43: 160.785 | G43: 134.567 | H43: =(H41-H42) | I43: =(I41-I42) | J43: =(J41-J42) | K43: =(K41-K42) | L43: =(L41-L42) | M43: =(M41-M42) | N43: =(N41-N42) | O43: =(O41-O42) | ... Q43: =(Q41-Q42)
A44: Shares outstanding (m) | B44: shares | D44: 112418.9 | E44: 112418.9 | F44: 112418.9 | G44: 112418.9 | H44: =(G44*(1+H24)) | I44: =(H44*(1+I24)) | J44: =(I44*(1+J24)) | K44: =(J44*(1+K24)) | L44: =(K44*(1+L24)) | M44: =(L44*(1+M24)) | N44: =(M44*(1+N24)) | O44: =(N44*(1+O24)) | ... Q44: =(P44*(1+Q24))
...

Sheet DSSA
A1: PT Dian Swastatika Sentosa Tbk (DSSA.JK) — Conglomerates & multi-sector holdings
A2: Units: USD m; per-share in USD unless marked IDR. Model asof 2026-10-29 · data 2026-10-27
A4: Line | C4: Scalar | D4: FY2022A | E4: FY2023A | F4: FY2024A | G4: FY2025A | H4: FY2026E | I4: FY2027E | J4: FY2028E | K4: FY2029E | L4: FY2030E | M4: FY2031E | N4: FY2032E | O4: FY2033E | P4: FY2034E | Q4: FY2035E
A6: PARAMETERS
A7: ps_factor | C7: 1
A8: vp_factor | C8: 1
A10: INPUTS (company assumptions)
A11: Revenue growth | B11: a.revenue_growth | H11: 0.1 | I11: -0.05 | J11: -0.06 | K11: -0.06 | L11: -0.06 | M11: -0.05 | N11: -0.05 | O11: -0.05 | P11: -0.05 | Q11: -0.05
A12: Gross margin at base input costs | B12: a.gross_margin | H12: 0.337361 | I12: 0.337361 | J12: 0.337361 | K12: 0.337361 | L12: 0.337361 | M12: 0.337361 | N12: 0.337361 | O12: 0.337361 | P12: 0.337361 | Q12: 0.337361
A13: SG&A / revenue | B13: a.opex_pct | H13: 0.193723 | I13: 0.193723 | J13: 0.193723 | K13: 0.193723 | L13: 0.193723 | M13: 0.193723 | N13: 0.193723 | O13: 0.193723 | P13: 0.193723 | Q13: 0.193723
A14: D&A / revenue | B14: a.da_pct | H14: 0.028005 | I14: 0.028005 | J14: 0.028005 | K14: 0.028005 | L14: 0.028005 | M14: 0.028005 | N14: 0.028005 | O14: 0.028005 | P14: 0.028005 | Q14: 0.028005
A15: Capex / revenue | B15: a.capex_pct | H15: 0.167325 | I15: 0.167325 | J15: 0.167325 | K15: 0.167325 | L15: 0.167325 | M15: 0.167325 | N15: 0.167325 | O15: 0.167325 | P15: 0.167325 | Q15: 0.167325
A16: Operating working capital / revenue | B16: a.nwc_pct | H16: 0.155985 | I16: 0.155985 | J16: 0.155985 | K16: 0.155985 | L16: 0.155985 | M16: 0.155985 | N16: 0.155985 | O16: 0.155985 | P16: 0.155985 | Q16: 0.155985
A17: Effective tax rate | B17: a.tax_rate | H17: 0.241607 | I17: 0.241607 | J17: 0.241607 | K17: 0.241607 | L17: 0.241607 | M17: 0.241607 | N17: 0.241607 | O17: 0.241607 | P17: 0.241607 | Q17: 0.241607
A18: Cost of debt (on opening debt) | B18: a.cost_of_debt | C18: 0.066581
A19: Yield on opening cash | B19: a.cash_yield | C19: 0.07
A20: Net new borrowing | B20: a.net_borrowing | H20: 0 | I20: 0 | J20: 0 | K20: 0 | L20: 0 | M20: 0 | N20: 0 | O20: 0 | P20: 0 | Q20: 0
A21: Other non-operating items | B21: a.other_nonop | H21: 0 | I21: 0 | J21: 0 | K21: 0 | L21: 0 | M21: 0 | N21: 0 | O21: 0 | P21: 0 | Q21: 0
A22: Minorities' share of net profit | B22: a.minority_pct | H22: 0.43326 | I22: 0.43326 | J22: 0.43326 | K22: 0.43326 | L22: 0.43326 | M22: 0.43326 | N22: 0.43326 | O22: 0.43326 | P22: 0.43326 | Q22: 0.43326
A23: Dividend payout | B23: a.payout | H23: 0 | I23: 0 | J23: 0 | K23: 0 | L23: 0 | M23: 0 | N23: 0 | O23: 0 | P23: 0 | Q23: 0
