Workbook

Sheet README
A1: Six South — Plantations (palm oil) industry model
A2: Generated 2026-10-30T01:56:00+07:00 by the coverage engine. The engine (scripts/cov_engine.py) is the source of truth; this workbook is a live rendering of it.
A3: Colour key: blue = input or hard-coded history; black = formula; green = link to another sheet.
A4: Drivers: every deck variable these models read. Change one and every ticker tab and the Comps sheet recalculate (forecasts, cash flows, DCF value, base-case value, target, rating).
A5: Scenario (bear/bull) and sensitivity tables need full model re-runs and are engine values.
A6: Paper fund — research for education and process transparency, not investment advice.
A8: Tickers:
A9: JARR.JK — PT Jhonlin Agro Raya Tbk
A10: PGUN.JK — PT Pradiksi Gunatama Tbk

Sheet Drivers
A1: Driver decks (state/drivers) — edit a blue cell to flow it through every ticker tab
A3: Variable | B3: Key | C3: Unit / status | D3: FY2022A | E3: FY2023A | F3: FY2024A | G3: FY2025A | H3: FY2026E | I3: FY2027E | J3: FY2028E | K3: FY2029E | L3: FY2030E | M3: FY2031E | N3: FY2032E | O3: FY2033E | P3: FY2034E | Q3: FY2035E
A4: Crude palm oil (benchmark) | B4: d.agri.cpo | C4: USD/t · reviewed | E4: 886 | F4: 963 | G4: 1007 | H4: 1135 | I4: 1240 | J4: 1210 | K4: 1180 | L4: 1178.75 | M4: 1208.2188 | N4: 1238.4242 | O4: 1269.3848 | P4: 1301.1194 | Q4: 1333.6474
A5: IDR per USD | B5: m.usd_idr | C5: IDR/USD · reviewed | D5: 14843.177 | E5: 15228.8 | F5: 15846.238 | G5: 16448.093 | H5: 17570 | I5: 18350 | J5: 18600 | K5: 18850 | L5: 19093.137 | M5: 19186.731 | N5: 19280.784 | O5: 19375.297 | P5: 19470.274 | Q5: 19565.717
A7: Cost-of-capital scalars (macro deck)
A8: 10-year Indonesian government bond yield (IDR) | B8: m.rf_idr | C8: 0.0745 | D8: investor.id — "Yield SUN 7,45%, Saatnya Borong atau Tunggu Lebih Tinggi?" (25 Okt 2026 20:58 WIB; deck source S3); corroborated by kalderanews S1 (10Y SUN 7.41%
A9: 10-year US Treasury yield | B9: m.rf_usd | C9: 0.05009 | D9: Yahoo Finance ^TNX (US 10-year Treasury yield)
A10: Indonesia sovereign default spread (Damodaran) | B10: m.default_spread_id | C10: 0.0162 | D10: Damodaran country risk premiums (https://pages.stern.nyu.edu/~adamodar/New_Home_Page/datafile/ctryprem.html), page dated January 5, 2026, read 2026-10-29
A11: Mature-market equity risk premium (Damodaran) | B11: m.erp_mature | C11: 0.0423 | D11: Damodaran country risk premiums (https://pages.stern.nyu.edu/~adamodar/New_Home_Page/datafile/ctryprem.html), page dated January 5, 2026, read 2026-10-29
A12: Indonesia country risk premium (Damodaran) | B12: m.crp_id | C12: 0.0246 | D12: Damodaran country risk premiums (https://pages.stern.nyu.edu/~adamodar/New_Home_Page/datafile/ctryprem.html), page dated January 5, 2026, read 2026-10-29
A13: House pre-tax corporate debt spread over the risk-free | B13: m.debt_spread_corp | C13: 0.02 | D13: SEED house assumption pending the macro desk: 200 bp over the risk-free rate for an average IDX corporate borrower
A14: Indonesia statutory corporate income tax rate | B14: m.tax_rate_id | C14: 0.22 | D14: Law 7/2021 on Harmonisation of Tax Regulations (UU HPP): 22% corporate income tax from fiscal 2022

Sheet Comps
A1: Ticker | B1: Company | C1: Rating | D1: Target (IDR) | E1: Price (IDR) | F1: Exp. 12m TR | G1: Value today | H1: P/E FY+0 | I1: EV/EBITDA FY+0 | J1: Div. yield FY+0
A2: JARR.JK | B2: PT Jhonlin Agro Raya Tbk | C2: ='JARR'!$C$173 | D2: ='JARR'!$C$171 | E2: ='JARR'!$C$102 | F2: ='JARR'!$C$172 | G2: ='JARR'!$C$152 | H2: 54.645711 | I2: 29.428938 | J2: 0.00366
A3: PGUN.JK | B3: PT Pradiksi Gunatama Tbk | C3: ='PGUN'!$C$173 | D3: ='PGUN'!$C$171 | E3: ='PGUN'!$C$102 | F3: ='PGUN'!$C$172 | G3: ='PGUN'!$C$152 | H3: 256.25777 | I3: 123.93778 | J3: 0.000976

Sheet JARR
A1: PT Jhonlin Agro Raya Tbk (JARR.JK) — Plantations (palm oil)
A2: Units: IDR bn; per-share in IDR unless marked IDR. Model asof 2026-10-29 · data 2026-10-27
A4: Line | C4: Scalar | D4: FY2022A | E4: FY2023A | F4: FY2024A | G4: FY2025A | H4: FY2026E | I4: FY2027E | J4: FY2028E | K4: FY2029E | L4: FY2030E | M4: FY2031E | N4: FY2032E | O4: FY2033E | P4: FY2034E | Q4: FY2035E
A6: PARAMETERS
A7: horizon | C7: 10
A8: ps_factor | C8: 1000
A9: reserves | C9: 0
A10: unit_factor | C10: 0.001
A11: vp_factor | C11: 1
A13: INPUTS (company assumptions)
A14: Sales volume plan | B14: a.volume | H14: 220.26923 | I14: 220.26923 | J14: 220.26923 | K14: 220.26923 | L14: 220.26923 | M14: 220.26923 | N14: 220.26923 | O14: 220.26923 | P14: 220.26923 | Q14: 220.26923
A15: Realised price / benchmark | B15: a.realisation | H15: 1.1 | I15: 1.1 | J15: 1.1 | K15: 1.1 | L15: 1.1 | M15: 1.1 | N15: 1.1 | O15: 1.1 | P15: 1.1 | Q15: 1.1
A16: Share of volume under a price cap (e.g. DMO) | B16: a.capped_share | H16: 0 | I16: 0 | J16: 0 | K16: 0 | L16: 0 | M16: 0 | N16: 0 | O16: 0 | P16: 0 | Q16: 0
A17: Strip ratio (bcm per tonne) or cost-intensity factor | B17: a.strip_ratio | H17: 1 | I17: 1 | J17: 1 | K17: 1 | L17: 1 | M17: 1 | N17: 1 | O17: 1 | P17: 1 | Q17: 1
A18: Mining cost per bcm (or per unit when intensity is 1) | B18: a.cost_per_bcm | H18: 15269332 | I18: 15269332 | J18: 15269332 | K18: 15269332 | L18: 15269332 | M18: 15651065 | N18: 16042342 | O18: 16443400 | P18: 16854485 | Q18: 17275848
A19: Fuel share of mining cost | B19: a.fuel_share | C19: 0.75
A20: Other cash cost per unit (haul, barge, process) | B20: a.other_cost_unit | H20: 0 | I20: 95433.3 | J20: 193252.5 | K20: 293517.1 | L20: 396288.4 | M20: 501628.9 | N20: 609603 | O20: 720276.4 | P20: 833716.6 | Q20: 949992.8
A21: Royalty rate (flat regimes) | B21: a.royalty_rate | H21: 0 | I21: 0 | J21: 0 | K21: 0 | L21: 0 | M21: 0 | N21: 0 | O21: 0 | P21: 0 | Q21: 0
A22: Other revenue | B22: a.other_revenue | H22: 0 | I22: 0 | J22: 0 | K22: 0 | L22: 0 | M22: 0 | N22: 0 | O22: 0 | P22: 0 | Q22: 0
A23: Gross margin on other revenue | B23: a.other_margin | C23: 0.1
A24: D&A per unit (reporting currency) | B24: a.da_unit | H24: 750132 | I24: 750132 | J24: 750132 | K24: 750132 | L24: 750132 | M24: 768885.3 | N24: 788107.43 | O24: 807810.12 | P24: 828005.37 | Q24: 848705.51
A25: Sustaining capex per unit (reporting currency) | B25: a.capex_unit | H25: 664873 | I25: 664873 | J25: 664873 | K25: 664873 | L25: 664873 | M25: 681494.82 | N25: 698532.2 | O25: 715995.5 | P25: 733895.39 | Q25: 752242.77
A26: Other capex (expansion projects) | B26: a.capex_other | H26: 0 | I26: 0 | J26: 0 | K26: 0 | L26: 0 | M26: 0 | N26: 0 | O26: 0 | P26: 0 | Q26: 0
A27: Operating working capital / revenue | B27: a.nwc_pct | H27: 0.2712 | I27: 0.2712 | J27: 0.2712 | K27: 0.2712 | L27: 0.2712 | M27: 0.2712 | N27: 0.2712 | O27: 0.2712 | P27: 0.2712 | Q27: 0.2712
A28: Effective tax rate | B28: a.tax_rate | H28: 0.2186 | I28: 0.2186 | J28: 0.2186 | K28: 0.2186 | L28: 0.2186 | M28: 0.2186 | N28: 0.2186 | O28: 0.2186 | P28: 0.2186 | Q28: 0.2186
A29: Cost of debt (on opening debt) | B29: a.cost_of_debt | C29: 0.0667
A30: Yield on opening cash | B30: a.cash_yield | C30: 0.01
A31: Net new borrowing | B31: a.net_borrowing | H31: 0 | I31: 0 | J31: 0 | K31: 0 | L31: 0 | M31: 0 | N31: 0 | O31: 0 | P31: 0 | Q31: 0
A32: Other non-operating items | B32: a.other_nonop | H32: 0 | I32: 0 | J32: 0 | K32: 0 | L32: 0 | M32: 0 | N32: 0 | O32: 0 | P32: 0 | Q32: 0
A33: Minorities' share of net profit | B33: a.minority_pct | H33: 0 | I33: 0 | J33: 0 | K33: 0 | L33: 0 | M33: 0 | N33: 0 | O33: 0 | P33: 0 | Q33: 0
A34: Dividend payout | B34: a.payout | H34: 0.2 | I34: 0.2 | J34: 0.2 | K34: 0.2 | L34: 0.2 | M34: 0.2 | N34: 0.2 | O34: 0.2 | P34: 0.2 | Q34: 0.2
A35: Change in share count | B35: a.share_change | H35: 0 | I35: 0 | J35: 0 | K35: 0 | L35: 0 | M35: 0 | N35: 0 | O35: 0 | P35: 0 | Q35: 0
A36: Terminal growth (DCF) | B36: a.terminal_growth | C36: 0.04
A37: SG&A / revenue | B37: a.opex_pct | H37: 0.069 | I37: 0.069 | J37: 0.069 | K37: 0.069 | L37: 0.069 | M37: 0.069 | N37: 0.069 | O37: 0.069 | P37: 0.069 | Q37: 0.069
A39: MODEL
A40: Reserves remaining (close) | B40: reserves | H40: =MAX((G40-H41),0) | I40: =MAX((H40-I41),0) | J40: =MAX((I40-J41),0) | K40: =MAX((J40-K41),0) | L40: =MAX((K40-L41),0) | M40: =MAX((L40-M41),0) | N40: =MAX((M40-N41),0) | O40: =MAX((N40-O41),0) | ... Q40: =MAX((P40-Q41),0)
A41: Sales volume | B41: volume | G41: 220.26923 | H41: =IF(($C$9>0),MIN(H14,MAX(G40,0)),H14) | I41: =IF(($C$9>0),MIN(I14,MAX(H40,0)),I14) | J41: =IF(($C$9>0),MIN(J14,MAX(I40,0)),J14) | K41: =IF(($C$9>0),MIN(K14,MAX(J40,0)),K14) | L41: =IF(($C$9>0),MIN(L14,MAX(K40,0)),L14) | M41: =IF(($C$9>0),MIN(M14,MAX(L40,0)),M14) | N41: =IF(($C$9>0),MIN(N14,MAX(M40,0)),N14) | O41: =IF(($C$9>0),MIN(O14,MAX(N40,0)),O14) | ... Q41: =IF(($C$9>0),MIN(Q14,MAX(P40,0)),Q14)
A42: Benchmark price | B42: benchmark | H42: =Drivers!$H$4 | I42: =Drivers!$I$4 | J42: =Drivers!$J$4 | K42: =Drivers!$K$4 | L42: =Drivers!$L$4 | M42: =Drivers!$M$4 | N42: =Drivers!$N$4 | O42: =Drivers!$O$4 | P42: =Drivers!$P$4 | Q42: =Drivers!$Q$4
A43: Average selling price | B43: asp | H43: =(H15*H42) | I43: =(I15*I42) | J43: =(J15*J42) | K43: =(K15*K42) | L43: =(L15*L42) | M43: =(M15*M42) | N43: =(N15*N42) | O43: =(O15*O42) | ... Q43: =(Q15*Q42)
A44: Realisation vs benchmark | B44: realisation_line | H44: =IF(H42=0,0,H43/H42) | I44: =IF(I42=0,0,I43/I42) | J44: =IF(J42=0,0,J43/J42) | K44: =IF(K42=0,0,K43/K42) | L44: =IF(L42=0,0,L43/L42) | M44: =IF(M42=0,0,M43/M42) | N44: =IF(N42=0,0,N43/N42) | O44: =IF(O42=0,0,O43/O42) | ... Q44: =IF(Q42=0,0,Q43/Q42)
...

Sheet PGUN
A1: PT Pradiksi Gunatama Tbk (PGUN.JK) — Plantations (palm oil)
A2: Units: IDR bn; per-share in IDR unless marked IDR. Model asof 2026-10-30 · data 2026-10-27
A4: Line | C4: Scalar | D4: FY2022A | E4: FY2023A | F4: FY2024A | G4: FY2025A | H4: FY2026E | I4: FY2027E | J4: FY2028E | K4: FY2029E | L4: FY2030E | M4: FY2031E | N4: FY2032E | O4: FY2033E
A6: PARAMETERS
A7: horizon | C7: 8
A8: ps_factor | C8: 1000
A9: reserves | C9: 0
A10: unit_factor | C10: 0.001
A11: vp_factor | C11: 1
A13: INPUTS (company assumptions)
A14: Sales volume plan | B14: a.volume | H14: 47.5 | I14: 50.5 | J14: 53.5 | K14: 56.5 | L14: 59.5 | M14: 66 | N14: 66 | O14: 66
A15: Realised price / benchmark | B15: a.realisation | H15: 0.79 | I15: 0.79 | J15: 0.79 | K15: 0.79 | L15: 0.79 | M15: 0.79 | N15: 0.79 | O15: 0.79
A16: Share of volume under a price cap (e.g. DMO) | B16: a.capped_share | H16: 0 | I16: 0 | J16: 0 | K16: 0 | L16: 0 | M16: 0 | N16: 0 | O16: 0
A17: Strip ratio (bcm per tonne) or cost-intensity factor | B17: a.strip_ratio | H17: 1 | I17: 1 | J17: 1 | K17: 1 | L17: 1 | M17: 1 | N17: 1 | O17: 1
A18: Mining cost per bcm (or per unit when intensity is 1) | B18: a.cost_per_bcm | H18: 7200000 | I18: 7380000 | J18: 7564500 | K18: 7753612.5 | L18: 7947452.8 | M18: 8610000 | N18: 8825250 | O18: 9045881.2
A19: Fuel share of mining cost | B19: a.fuel_share | C19: 0
A20: Other cash cost per unit (haul, barge, process) | B20: a.other_cost_unit | H20: 0 | I20: 0 | J20: 0 | K20: 0 | L20: 0 | M20: 0 | N20: 0 | O20: 0
A21: Royalty rate (flat regimes) | B21: a.royalty_rate | H21: 0 | I21: 0 | J21: 0 | K21: 0 | L21: 0 | M21: 0 | N21: 0 | O21: 0
A22: Other revenue | B22: a.other_revenue | H22: 88 | I22: 95 | J22: 101 | K22: 106 | L22: 110 | M22: 123 | N22: 126.075 | O22: 129.22687
A23: Gross margin on other revenue | B23: a.other_margin | C23: 0.65
A24: D&A per unit (reporting currency) | B24: a.da_unit | H24: 2600000 | I24: 2652000 | J24: 2705040 | K24: 2759140.8 | L24: 2814323.6 | M24: 3075000 | N24: 3151875 | O24: 3230671.9
A25: Sustaining capex per unit (reporting currency) | B25: a.capex_unit | H25: 2830000 | I25: 2900750 | J25: 2973268.8 | K25: 3047600.5 | L25: 3123790.5 | M25: 3280000 | N25: 3362000 | O25: 3446050
A26: Other capex (expansion projects) | B26: a.capex_other | H26: 0 | I26: 0 | J26: 0 | K26: 0 | L26: 0 | M26: 0 | N26: 0 | O26: 0
A27: Operating working capital / revenue | B27: a.nwc_pct | H27: 0.278361 | I27: 0.278361 | J27: 0.278361 | K27: 0.278361 | L27: 0.278361 | M27: 0.278361 | N27: 0.278361 | O27: 0.278361
A28: Effective tax rate | B28: a.tax_rate | H28: 0.215755 | I28: 0.215755 | J28: 0.215755 | K28: 0.215755 | L28: 0.215755 | M28: 0.215755 | N28: 0.215755 | O28: 0.215755
A29: Cost of debt (on opening debt) | B29: a.cost_of_debt | C29: 0.073861
A30: Yield on opening cash | B30: a.cash_yield | C30: 0.038322
A31: Net new borrowing | B31: a.net_borrowing | H31: -100 | I31: -20 | J31: 0 | K31: 0 | L31: 0 | M31: 0 | N31: 0 | O31: 0
A32: Other non-operating items | B32: a.other_nonop | H32: 0 | I32: 0 | J32: 0 | K32: 0 | L32: 0 | M32: 0 | N32: 0 | O32: 0
A33: Minorities' share of net profit | B33: a.minority_pct | H33: 0 | I33: 0 | J33: 0 | K33: 0 | L33: 0 | M33: 0 | N33: 0 | O33: 0
A34: Dividend payout | B34: a.payout | H34: 0.25 | I34: 0.25 | J34: 0.25 | K34: 0.25 | L34: 0.25 | M34: 0.25 | N34: 0.25 | O34: 0.25
A35: Change in share count | B35: a.share_change | H35: 0 | I35: 0 | J35: 0 | K35: 0 | L35: 0 | M35: 0 | N35: 0 | O35: 0
A36: Terminal growth (DCF) | B36: a.terminal_growth | C36: 0.04
A37: SG&A / revenue | B37: a.opex_pct | H37: 0.09 | I37: 0.09 | J37: 0.09 | K37: 0.09 | L37: 0.09 | M37: 0.09 | N37: 0.09 | O37: 0.09
A39: MODEL
A40: Reserves remaining (close) | B40: reserves | H40: =MAX((G40-H41),0) | I40: =MAX((H40-I41),0) | J40: =MAX((I40-J41),0) | K40: =MAX((J40-K41),0) | L40: =MAX((K40-L41),0) | M40: =MAX((L40-M41),0) | N40: =MAX((M40-N41),0) | O40: =MAX((N40-O41),0)
A41: Sales volume | B41: volume | F41: 53.108 | G41: 53.108 | H41: =IF(($C$9>0),MIN(H14,MAX(G40,0)),H14) | I41: =IF(($C$9>0),MIN(I14,MAX(H40,0)),I14) | J41: =IF(($C$9>0),MIN(J14,MAX(I40,0)),J14) | K41: =IF(($C$9>0),MIN(K14,MAX(J40,0)),K14) | L41: =IF(($C$9>0),MIN(L14,MAX(K40,0)),L14) | M41: =IF(($C$9>0),MIN(M14,MAX(L40,0)),M14) | N41: =IF(($C$9>0),MIN(N14,MAX(M40,0)),N14) | O41: =IF(($C$9>0),MIN(O14,MAX(N40,0)),O14)
A42: Benchmark price | B42: benchmark | H42: =Drivers!$H$4 | I42: =Drivers!$I$4 | J42: =Drivers!$J$4 | K42: =Drivers!$K$4 | L42: =Drivers!$L$4 | M42: =Drivers!$M$4 | N42: =Drivers!$N$4 | O42: =Drivers!$O$4
A43: Average selling price | B43: asp | H43: =(H15*H42) | I43: =(I15*I42) | J43: =(J15*J42) | K43: =(K15*K42) | L43: =(L15*L42) | M43: =(M15*M42) | N43: =(N15*N42) | O43: =(O15*O42)
A44: Realisation vs benchmark | B44: realisation_line | H44: =IF(H42=0,0,H43/H42) | I44: =IF(I42=0,0,I43/I42) | J44: =IF(J42=0,0,J43/J42) | K44: =IF(K42=0,0,K43/K42) | L44: =IF(L42=0,0,L43/L42) | M44: =IF(M42=0,0,M43/M42) | N44: =IF(N42=0,0,N43/N42) | O44: =IF(O42=0,0,O43/O42)
...
