Workbook

Sheet README
A1: Six South — Poultry, feed & protein industry model
A2: Generated 2026-10-27T10:28:09+07:00 by the coverage engine. The engine (scripts/cov_engine.py) is the source of truth; this workbook is a live rendering of it.
A3: Colour key: blue = input or hard-coded history; black = formula; green = link to another sheet.
A4: Drivers: every deck variable these models read. Change one and every ticker tab and the Comps sheet recalculate (forecasts, cash flows, DCF value, base-case value, target, rating).
A5: Scenario (bear/bull) and sensitivity tables need full model re-runs and are engine values.
A6: Paper fund — research for education and process transparency, not investment advice.
A8: Tickers:
A9: WMPP.JK — PT Widodo Makmur Perkasa Tbk

Sheet Drivers
A1: Driver decks (state/drivers) — edit a blue cell to flow it through every ticker tab
A3: Variable | B3: Key | C3: Unit / status | D3: FY2022A | E3: FY2023A | F3: FY2024A | G3: FY2025A | H3: FY2026E | I3: FY2027E | J3: FY2028E | K3: FY2029E | L3: FY2030E | M3: FY2031E | N3: FY2032E | O3: FY2033E | P3: FY2034E | Q3: FY2035E
A4: IDR per USD | B4: m.usd_idr | C4: IDR/USD · reviewed | D4: 14843.177 | E4: 15228.8 | F4: 15846.238 | G4: 16448.093 | H4: 17570 | I4: 18350 | J4: 18600 | K4: 18850 | L4: 19093.137 | M4: 19186.731 | N4: 19280.784 | O4: 19375.297 | P4: 19470.274 | Q4: 19565.717
A6: Cost-of-capital scalars (macro deck)
A7: 10-year Indonesian government bond yield (IDR) | B7: m.rf_idr | C7: 0.0745 | D7: investor.id — "Yield SUN 7,45%, Saatnya Borong atau Tunggu Lebih Tinggi?" (25 Okt 2026 20:58 WIB; deck source S3); corroborated by kalderanews S1 (10Y SUN 7.41%
A8: 10-year US Treasury yield | B8: m.rf_usd | C8: 0.04986 | D8: Yahoo Finance ^TNX (US 10-year Treasury yield)
A9: Indonesia sovereign default spread (Damodaran) | B9: m.default_spread_id | C9: 0.0162 | D9: Damodaran country risk premiums (https://pages.stern.nyu.edu/~adamodar/New_Home_Page/datafile/ctryprem.html), page dated January 5, 2026, read 2026-10-27
A10: Mature-market equity risk premium (Damodaran) | B10: m.erp_mature | C10: 0.0423 | D10: Damodaran country risk premiums (https://pages.stern.nyu.edu/~adamodar/New_Home_Page/datafile/ctryprem.html), page dated January 5, 2026, read 2026-10-27
A11: Indonesia country risk premium (Damodaran) | B11: m.crp_id | C11: 0.0246 | D11: Damodaran country risk premiums (https://pages.stern.nyu.edu/~adamodar/New_Home_Page/datafile/ctryprem.html), page dated January 5, 2026, read 2026-10-27
A12: House pre-tax corporate debt spread over the risk-free | B12: m.debt_spread_corp | C12: 0.02 | D12: SEED house assumption pending the macro desk: 200 bp over the risk-free rate for an average IDX corporate borrower
A13: Indonesia statutory corporate income tax rate | B13: m.tax_rate_id | C13: 0.22 | D13: Law 7/2021 on Harmonisation of Tax Regulations (UU HPP): 22% corporate income tax from fiscal 2022

Sheet Comps
A1: Ticker | B1: Company | C1: Rating | D1: Target (IDR) | E1: Price (IDR) | F1: Exp. 12m TR | G1: Value today | H1: P/E FY+0 | I1: EV/EBITDA FY+0 | J1: Div. yield FY+0
A2: WMPP.JK | B2: PT Widodo Makmur Perkasa Tbk | C2: ='WMPP'!$C$122 | D2: ='WMPP'!$C$120 | E2: ='WMPP'!$C$76 | F2: ='WMPP'!$C$121 | G2: ='WMPP'!$C$110 | I2: 316.39215 | J2: 0

Sheet WMPP
A1: PT Widodo Makmur Perkasa Tbk (WMPP.JK) — Conglomerates & multi-sector holdings
A2: Units: IDR bn; per-share in IDR unless marked IDR. Model asof 2026-10-27 · data 2026-10-26
A4: Line | C4: Scalar | D4: FY2022A | E4: FY2023A | F4: FY2024A | G4: FY2025A | H4: FY2026E | I4: FY2027E | J4: FY2028E | K4: FY2029E | L4: FY2030E | M4: FY2031E | N4: FY2032E | O4: FY2033E | P4: FY2034E | Q4: FY2035E
A6: PARAMETERS
A7: ps_factor | C7: 1000
A8: vp_factor | C8: 1
A10: INPUTS (company assumptions)
A11: Revenue growth | B11: a.revenue_growth | H11: 0.11 | I11: 0.1 | J11: 0.09 | K11: 0.085 | L11: 0.085 | M11: 0.05 | N11: 0.05 | O11: 0.05 | P11: 0.05 | Q11: 0.05
A12: Gross margin at base input costs | B12: a.gross_margin | H12: 0.011 | I12: 0.011 | J12: 0.011 | K12: 0.011 | L12: 0.011 | M12: 0.011 | N12: 0.011 | O12: 0.011 | P12: 0.011 | Q12: 0.011
A13: SG&A / revenue | B13: a.opex_pct | H13: 0.1024 | I13: 0.1024 | J13: 0.1024 | K13: 0.1024 | L13: 0.1024 | M13: 0.1024 | N13: 0.1024 | O13: 0.1024 | P13: 0.1024 | Q13: 0.1024
A14: D&A / revenue | B14: a.da_pct | H14: 0.1037 | I14: 0.1037 | J14: 0.1037 | K14: 0.1037 | L14: 0.1037 | M14: 0.1037 | N14: 0.1037 | O14: 0.1037 | P14: 0.1037 | Q14: 0.1037
A15: Capex / revenue | B15: a.capex_pct | H15: 0.006503 | I15: 0.006503 | J15: 0.006503 | K15: 0.006503 | L15: 0.006503 | M15: 0.006503 | N15: 0.006503 | O15: 0.006503 | P15: 0.006503 | Q15: 0.006503
A16: Operating working capital / revenue | B16: a.nwc_pct | H16: 0.642413 | I16: 0.642413 | J16: 0.642413 | K16: 0.642413 | L16: 0.642413 | M16: 0.642413 | N16: 0.642413 | O16: 0.642413 | P16: 0.642413 | Q16: 0.642413
A17: Effective tax rate | B17: a.tax_rate | H17: 0.1 | I17: 0.1 | J17: 0.1 | K17: 0.1 | L17: 0.1 | M17: 0.1 | N17: 0.1 | O17: 0.1 | P17: 0.1 | Q17: 0.1
A18: Cost of debt (on opening debt) | B18: a.cost_of_debt | C18: 0.063204
A19: Yield on opening cash | B19: a.cash_yield | C19: 0.005521
A20: Net new borrowing | B20: a.net_borrowing | H20: 0 | I20: 0 | J20: 0 | K20: 0 | L20: 0 | M20: 0 | N20: 0 | O20: 0 | P20: 0 | Q20: 0
A21: Other non-operating items | B21: a.other_nonop | H21: 0 | I21: 0 | J21: 0 | K21: 0 | L21: 0 | M21: 0 | N21: 0 | O21: 0 | P21: 0 | Q21: 0
A22: Minorities' share of net profit | B22: a.minority_pct | H22: 0.0501 | I22: 0.0501 | J22: 0.0501 | K22: 0.0501 | L22: 0.0501 | M22: 0.0501 | N22: 0.0501 | O22: 0.0501 | P22: 0.0501 | Q22: 0.0501
A23: Dividend payout | B23: a.payout | H23: 0 | I23: 0 | J23: 0 | K23: 0 | L23: 0 | M23: 0 | N23: 0 | O23: 0 | P23: 0 | Q23: 0
A24: Change in share count | B24: a.share_change | H24: 0 | I24: 0 | J24: 0 | K24: 0 | L24: 0 | M24: 0 | N24: 0 | O24: 0 | P24: 0 | Q24: 0
A25: Terminal growth (DCF) | B25: a.terminal_growth | C25: 0.03
A26: Holding-company discount to SOTP | B26: a.holdco_discount | C26: 0.35
A28: MODEL
A29: Revenue | B29: revenue | D29: 4390.0777 | E29: 907.22618 | F29: 572.92123 | G29: 1011.9009 | H29: =(G29*(1+H11)) | I29: =(H29*(1+I11)) | J29: =(I29*(1+J11)) | K29: =(J29*(1+K11)) | L29: =(K29*(1+L11)) | M29: =(L29*(1+M11)) | N29: =(M29*(1+N11)) | O29: =(N29*(1+O11)) | ... Q29: =(P29*(1+Q11))
A30: Cost of revenue | B30: cogs | D30: 4052.6474 | E30: 1277.5027 | F30: 668.19316 | G30: 1009.1141 | H30: =(H29*(1-H12)) | I30: =(I29*(1-I12)) | J30: =(J29*(1-J12)) | K30: =(K29*(1-K12)) | L30: =(L29*(1-L12)) | M30: =(M29*(1-M12)) | N30: =(N29*(1-N12)) | O30: =(O29*(1-O12)) | ... Q30: =(Q29*(1-Q12))
A31: Gross profit | B31: gross_profit | D31: 337.43027 | E31: -370.2765 | F31: -95.271931 | G31: 2.7868142 | H31: =(H29-H30) | I31: =(I29-I30) | J31: =(J29-J30) | K31: =(K29-K30) | L31: =(L29-L30) | M31: =(M29-M30) | N31: =(N29-N30) | O31: =(O29-O30) | ... Q31: =(Q29-Q30)
A32: SG&A and other opex | B32: opex | D32: 434.22193 | E32: 246.20884 | F32: 129.134 | G32: 103.64157 | H32: =(H29*H13) | I32: =(I29*I13) | J32: =(J29*J13) | K32: =(K29*K13) | L32: =(L29*L13) | M32: =(M29*M13) | N32: =(N29*N13) | O32: =(O29*O13) | ... Q32: =(Q29*Q13)
A33: EBIT | B33: ebit | D33: -96.791665 | E33: -616.48534 | F33: -224.40593 | G33: -100.85476 | H33: =(H31-H32) | I33: =(I31-I32) | J33: =(J31-J32) | K33: =(K31-K32) | L33: =(L31-L32) | M33: =(M31-M32) | N33: =(N31-N32) | O33: =(O31-O32) | ... Q33: =(Q31-Q32)
A34: Depreciation & amortisation | B34: da | D34: 52.144187 | E34: 62.744607 | F34: 101.47502 | G34: 104.92465 | H34: =(H29*H14) | I34: =(I29*I14) | J34: =(J29*J14) | K34: =(K29*K14) | L34: =(L29*L14) | M34: =(M29*M14) | N34: =(N29*N14) | O34: =(O29*O14) | ... Q34: =(Q29*Q14)
A35: EBITDA | B35: ebitda | D35: -44.647478 | E35: -553.74073 | F35: -122.93092 | G35: 4.0698941 | H35: =(H33+H34) | I35: =(I33+I34) | J35: =(J33+J34) | K35: =(K33+K34) | L35: =(L33+L34) | M35: =(M33+M34) | N35: =(N33+N34) | O35: =(O33+O34) | ... Q35: =(Q33+Q34)
A36: Interest expense | B36: interest_expense | D36: 262.59436 | E36: 243.81625 | F36: 198.0758 | G36: 106.90192 | H36: =(G56*$C$18) | I36: =(H56*$C$18) | J36: =(I56*$C$18) | K36: =(J56*$C$18) | L36: =(K56*$C$18) | M36: =(L56*$C$18) | N36: =(M56*$C$18) | O36: =(N56*$C$18) | ... Q36: =(P56*$C$18)
A37: Interest income | B37: interest_income | D37: 2.0556429 | E37: 0.90158414 | F37: 0.14103972 | G37: 0.044817023 | H37: =(G55*$C$19) | I37: =(H55*$C$19) | J37: =(I55*$C$19) | K37: =(J55*$C$19) | L37: =(K55*$C$19) | M37: =(L55*$C$19) | N37: =(M55*$C$19) | O37: =(N55*$C$19) | ... Q37: =(P55*$C$19)
A38: Other non-operating | B38: other_nonop | D38: -38.005425 | E38: -29.440547 | F38: -267.30452 | G38: -67.664474 | H38: =H21 | I38: =I21 | J38: =J21 | K38: =K21 | L38: =L21 | M38: =M21 | N38: =N21 | O38: =O21 | ... Q38: =Q21
A39: Profit before tax | B39: pbt | D39: -395.33581 | E39: -888.84055 | F39: -689.64522 | G39: -275.37633 | H39: =(((H33-H36)+H37)+H38) | I39: =(((I33-I36)+I37)+I38) | J39: =(((J33-J36)+J37)+J38) | K39: =(((K33-K36)+K37)+K38) | L39: =(((L33-L36)+L37)+L38) | M39: =(((M33-M36)+M37)+M38) | N39: =(((N33-N36)+N37)+N38) | O39: =(((O33-O36)+O37)+O38) | ... Q39: =(((Q33-Q36)+Q37)+Q38)
A40: Tax | B40: tax | D40: -78.264607 | E40: -7.9377804 | F40: -93.139438 | G40: -40.437581 | H40: =(MAX(H39,0)*H17) | I40: =(MAX(I39,0)*I17) | J40: =(MAX(J39,0)*J17) | K40: =(MAX(K39,0)*K17) | L40: =(MAX(L39,0)*L17) | M40: =(MAX(M39,0)*M17) | N40: =(MAX(N39,0)*N17) | O40: =(MAX(O39,0)*O17) | ... Q40: =(MAX(Q39,0)*Q17)
A41: Net profit (incl. minorities) | B41: np | D41: -317.0712 | E41: -880.90277 | F41: -596.50578 | G41: -234.93875 | H41: =(H39-H40) | I41: =(I39-I40) | J41: =(J39-J40) | K41: =(K39-K40) | L41: =(L39-L40) | M41: =(M39-M40) | N41: =(N39-N40) | O41: =(O39-O40) | ... Q41: =(Q39-Q40)
A42: Minority interests | B42: minority | D42: -9.4569728 | E42: -5.2762674 | F42: -28.72616 | G42: -22.590098 | H42: =(H41*H22) | I42: =(I41*I22) | J42: =(J41*J22) | K42: =(K41*K22) | L42: =(L41*L22) | M42: =(M41*M22) | N42: =(N41*N22) | O42: =(O41*O22) | ... Q42: =(Q41*Q22)
A43: Net profit to parent | B43: np_parent | D43: -307.61423 | E43: -875.6265 | F43: -567.77962 | G43: -212.34865 | H43: =(H41-H42) | I43: =(I41-I42) | J43: =(J41-J42) | K43: =(K41-K42) | L43: =(L41-L42) | M43: =(M41-M42) | N43: =(N41-N42) | O43: =(O41-O42) | ... Q43: =(Q41-Q42)
A44: Shares outstanding (m) | B44: shares | D44: 29419 | E44: 29419 | F44: 29419 | G44: 29419 | H44: =(G44*(1+H24)) | I44: =(H44*(1+I24)) | J44: =(I44*(1+J24)) | K44: =(J44*(1+K24)) | L44: =(K44*(1+L24)) | M44: =(L44*(1+M24)) | N44: =(M44*(1+N24)) | O44: =(N44*(1+O24)) | ... Q44: =(P44*(1+Q24))
...
