Workbook

Sheet README
A1: Six South — Power producers & utilities industry model
A2: Generated 2026-10-29T23:12:35+07:00 by the coverage engine. The engine (scripts/cov_engine.py) is the source of truth; this workbook is a live rendering of it.
A3: Colour key: blue = input or hard-coded history; black = formula; green = link to another sheet.
A4: Drivers: every deck variable these models read. Change one and every ticker tab and the Comps sheet recalculate (forecasts, cash flows, DCF value, base-case value, target, rating).
A5: Scenario (bear/bull) and sensitivity tables need full model re-runs and are engine values.
A6: Paper fund — research for education and process transparency, not investment advice.
A8: Tickers:
A9: BREN.JK — PT Barito Renewables Energy Tbk
A10: CDIA.JK — PT Chandra Daya Investasi TBK.

Sheet Drivers
A1: Driver decks (state/drivers) — edit a blue cell to flow it through every ticker tab
A3: Variable | B3: Key | C3: Unit / status | D3: FY2022A | E3: FY2023A | F3: FY2024A | G3: FY2025A | H3: FY2026E | I3: FY2027E | J3: FY2028E | K3: FY2029E | L3: FY2030E | M3: FY2031E | N3: FY2032E | O3: FY2033E | P3: FY2034E | Q3: FY2035E | R3: FY2036E | S3: FY2037E | T3: FY2038E | U3: FY2039E | V3: FY2040E | W3: FY2041E | X3: FY2042E | Y3: FY2043E | Z3: FY2044E | AA3: FY2045E | AB3: FY2046E | AC3: FY2047E | AD3: FY2048E
A4: IDR per USD | B4: m.usd_idr | C4: IDR/USD · reviewed | D4: 14843.177 | E4: 15228.8 | F4: 15846.238 | G4: 16448.093 | H4: 17570 | I4: 18350 | J4: 18600 | K4: 18850 | L4: 19093.137 | M4: 19186.731 | N4: 19280.784 | O4: 19375.297 | P4: 19470.274 | Q4: 19565.717 | R4: 19661.627 | S4: 19758.008 | T4: 19854.861 | U4: 19952.188 | V4: 20049.993 | W4: 20148.278 | X4: 20247.044 | Y4: 20346.294 | Z4: 20446.031 | AA4: 20546.256 | AB4: 20646.973 | AC4: 20748.184 | AD4: 20849.891
A6: Cost-of-capital scalars (macro deck)
A7: 10-year Indonesian government bond yield (IDR) | B7: m.rf_idr | C7: 0.0745 | D7: investor.id — "Yield SUN 7,45%, Saatnya Borong atau Tunggu Lebih Tinggi?" (25 Okt 2026 20:58 WIB; deck source S3); corroborated by kalderanews S1 (10Y SUN 7.41%
A8: 10-year US Treasury yield | B8: m.rf_usd | C8: 0.05009 | D8: Yahoo Finance ^TNX (US 10-year Treasury yield)
A9: Indonesia sovereign default spread (Damodaran) | B9: m.default_spread_id | C9: 0.0162 | D9: Damodaran country risk premiums (https://pages.stern.nyu.edu/~adamodar/New_Home_Page/datafile/ctryprem.html), page dated January 5, 2026, read 2026-10-29
A10: Mature-market equity risk premium (Damodaran) | B10: m.erp_mature | C10: 0.0423 | D10: Damodaran country risk premiums (https://pages.stern.nyu.edu/~adamodar/New_Home_Page/datafile/ctryprem.html), page dated January 5, 2026, read 2026-10-29
A11: Indonesia country risk premium (Damodaran) | B11: m.crp_id | C11: 0.0246 | D11: Damodaran country risk premiums (https://pages.stern.nyu.edu/~adamodar/New_Home_Page/datafile/ctryprem.html), page dated January 5, 2026, read 2026-10-29
A12: House pre-tax corporate debt spread over the risk-free | B12: m.debt_spread_corp | C12: 0.02 | D12: SEED house assumption pending the macro desk: 200 bp over the risk-free rate for an average IDX corporate borrower
A13: Indonesia statutory corporate income tax rate | B13: m.tax_rate_id | C13: 0.22 | D13: Law 7/2021 on Harmonisation of Tax Regulations (UU HPP): 22% corporate income tax from fiscal 2022

Sheet Comps
A1: Ticker | B1: Company | C1: Rating | D1: Target (IDR) | E1: Price (IDR) | F1: Exp. 12m TR | G1: Value today | H1: P/E FY+0 | I1: EV/EBITDA FY+0 | J1: Div. yield FY+0
A2: BREN.JK | B2: PT Barito Renewables Energy Tbk | C2: ='BREN'!$C$154 | D2: ='BREN'!$C$152 | E2: ='BREN'!$C$76 | F2: ='BREN'!$C$153 | G2: ='BREN'!$C$133 | H2: 119.7729 | I2: 34.539579 | J2: 0
A3: CDIA.JK | B3: PT Chandra Daya Investasi TBK. | C3: ='CDIA'!$C$147 | D3: ='CDIA'!$C$145 | E3: ='CDIA'!$C$76 | F3: ='CDIA'!$C$146 | G3: ='CDIA'!$C$126 | H3: 116.54385 | I3: 78.217111 | J3: 0.002145

Sheet BREN
A1: PT Barito Renewables Energy Tbk (BREN.JK) — Power producers & utilities
A2: Units: USD m; per-share in USD unless marked IDR. Model asof 2026-10-29 · data 2026-10-27
A4: Line | C4: Scalar | D4: FY2022A | E4: FY2023A | F4: FY2024A | G4: FY2025A | H4: FY2026E | I4: FY2027E | J4: FY2028E | K4: FY2029E | L4: FY2030E | M4: FY2031E | N4: FY2032E | O4: FY2033E | P4: FY2034E | Q4: FY2035E | R4: FY2036E | S4: FY2037E | T4: FY2038E | U4: FY2039E | V4: FY2040E | W4: FY2041E | X4: FY2042E | Y4: FY2043E | Z4: FY2044E | AA4: FY2045E | AB4: FY2046E | AC4: FY2047E | AD4: FY2048E
A6: PARAMETERS
A7: horizon | C7: 23
A8: ps_factor | C8: 1
A9: vp_factor | C9: 1
A11: INPUTS (company assumptions)
A12: Revenue growth | B12: a.revenue_growth | H12: 0.06 | I12: 0.04 | J12: 0.01 | K12: 0.02 | L12: 0.02 | M12: 0.02 | N12: 0.02 | O12: 0.02 | P12: 0.02 | Q12: 0.02 | R12: 0.02 | S12: 0.02 | T12: 0.02 | U12: -0.2572 | V12: -0.5529 | W12: -0.4235 | X12: 0.02 | Y12: 0.02 | Z12: 0.02 | AA12: 0.02 | AB12: 0.02 | AC12: -0.6289 | AD12: 0.02
A13: Gross margin at base input costs | B13: a.gross_margin | H13: 0.9723 | I13: 0.9723 | J13: 0.9723 | K13: 0.9723 | L13: 0.9723 | M13: 0.9723 | N13: 0.9723 | O13: 0.9723 | P13: 0.9723 | Q13: 0.9723 | R13: 0.9723 | S13: 0.9723 | T13: 0.9723 | U13: 0.9723 | V13: 0.9723 | W13: 0.9723 | X13: 0.9723 | Y13: 0.9723 | Z13: 0.9723 | AA13: 0.9723 | AB13: 0.9723 | AC13: 0.9723 | AD13: 0.9723
A14: SG&A / revenue | B14: a.opex_pct | H14: 0.2569 | I14: 0.2569 | J14: 0.2569 | K14: 0.2569 | L14: 0.2569 | M14: 0.2569 | N14: 0.2569 | O14: 0.2569 | P14: 0.2569 | Q14: 0.2569 | R14: 0.2569 | S14: 0.2569 | T14: 0.2569 | U14: 0.2569 | V14: 0.2569 | W14: 0.2569 | X14: 0.2569 | Y14: 0.2569 | Z14: 0.2569 | AA14: 0.2569 | AB14: 0.2569 | AC14: 0.2569 | AD14: 0.2569
A15: D&A / revenue | B15: a.da_pct | H15: 0.155 | I15: 0.156 | J15: 0.158 | K15: 0.16 | L15: 0.158 | M15: 0.155 | N15: 0.155 | O15: 0.155 | P15: 0.155 | Q15: 0.155 | R15: 0.155 | S15: 0.155 | T15: 0.155 | U15: 0.155 | V15: 0.155 | W15: 0.155 | X15: 0.155 | Y15: 0.155 | Z15: 0.155 | AA15: 0.155 | AB15: 0.155 | AC15: 0.155 | AD15: 0.155
A16: Capex / revenue | B16: a.capex_pct | H16: 0.3 | I16: 0.27 | J16: 0.22 | K16: 0.2 | L16: 0.18 | M16: 0.16 | N16: 0.16 | O16: 0.16 | P16: 0.16 | Q16: 0.16 | R16: 0.16 | S16: 0.16 | T16: 0.16 | U16: 0.16 | V16: 0.16 | W16: 0.16 | X16: 0.16 | Y16: 0.16 | Z16: 0.16 | AA16: 0.16 | AB16: 0.16 | AC16: 0.16 | AD16: 0.16
A17: Operating working capital / revenue | B17: a.nwc_pct | H17: 0.5467 | I17: 0.5467 | J17: 0.5467 | K17: 0.5467 | L17: 0.5467 | M17: 0.5467 | N17: 0.5467 | O17: 0.5467 | P17: 0.5467 | Q17: 0.5467 | R17: 0.5467 | S17: 0.5467 | T17: 0.5467 | U17: 0.5467 | V17: 0.5467 | W17: 0.5467 | X17: 0.5467 | Y17: 0.5467 | Z17: 0.5467 | AA17: 0.5467 | AB17: 0.5467 | AC17: 0.5467 | AD17: 0.5467
A18: Effective tax rate | B18: a.tax_rate | H18: 0.46 | I18: 0.46 | J18: 0.46 | K18: 0.46 | L18: 0.46 | M18: 0.46 | N18: 0.46 | O18: 0.46 | P18: 0.46 | Q18: 0.46 | R18: 0.46 | S18: 0.46 | T18: 0.46 | U18: 0.46 | V18: 0.46 | W18: 0.46 | X18: 0.46 | Y18: 0.46 | Z18: 0.46 | AA18: 0.46 | AB18: 0.46 | AC18: 0.46 | AD18: 0.46
A19: Cost of debt (on opening debt) | B19: a.cost_of_debt | C19: 0.0565
A20: Yield on opening cash | B20: a.cash_yield | C20: 0.0731
A21: Net new borrowing | B21: a.net_borrowing | H21: 0 | I21: 0 | J21: 0 | K21: 0 | L21: 0 | M21: 0 | N21: 0 | O21: 0 | P21: 0 | Q21: 0 | R21: 0 | S21: 0 | T21: 0 | U21: 0 | V21: 0 | W21: 0 | X21: 0 | Y21: 0 | Z21: 0 | AA21: 0 | AB21: 0 | AC21: 0 | AD21: 0
A22: Other non-operating items | B22: a.other_nonop | H22: -20.144 | I22: -20.144 | J22: -20.144 | K22: -20.144 | L22: -20.144 | M22: -20.54688 | N22: -20.957818 | O22: -21.376974 | P22: -21.804513 | Q22: -22.240604 | R22: -22.685416 | S22: -23.139124 | T22: -23.601907 | U22: -24.073945 | V22: -24.555424 | W22: -25.046532 | X22: -25.547463 | Y22: -26.058412 | Z22: -26.57958 | AA22: -27.111172 | AB22: -27.653395 | AC22: -28.206463 | AD22: -28.770592
A23: Minorities' share of net profit | B23: a.minority_pct | H23: 0.199 | I23: 0.199 | J23: 0.199 | K23: 0.199 | L23: 0.199 | M23: 0.199 | N23: 0.199 | O23: 0.199 | P23: 0.199 | Q23: 0.199 | R23: 0.199 | S23: 0.199 | T23: 0.199 | U23: 0.199 | V23: 0.199 | W23: 0.199 | X23: 0.199 | Y23: 0.199 | Z23: 0.199 | AA23: 0.199 | AB23: 0.199 | AC23: 0.199 | AD23: 0.199
A24: Dividend payout | B24: a.payout | H24: 0 | I24: 0 | J24: 0 | K24: 0.2 | L24: 0.2 | M24: 0.2 | N24: 0.2 | O24: 0.2 | P24: 0.2 | Q24: 0.2 | R24: 0.2 | S24: 0.2 | T24: 0.2 | U24: 0.2 | V24: 0.2 | W24: 0.2 | X24: 0.2 | Y24: 0.2 | Z24: 0.2 | AA24: 0.2 | AB24: 0.2 | AC24: 0.2 | AD24: 0.2
A25: Change in share count | B25: a.share_change | H25: 0 | I25: 0 | J25: 0 | K25: 0 | L25: 0 | M25: 0 | N25: 0 | O25: 0 | P25: 0 | Q25: 0 | R25: 0 | S25: 0 | T25: 0 | U25: 0 | V25: 0 | W25: 0 | X25: 0 | Y25: 0 | Z25: 0 | AA25: 0 | AB25: 0 | AC25: 0 | AD25: 0
A26: Terminal growth (DCF) | B26: a.terminal_growth | C26: 0.02
A28: MODEL
A29: Revenue | B29: revenue | D29: 569.78 | E29: 594.937 | F29: 596.823 | G29: 605.187 | H29: =(G29*(1+H12)) | I29: =(H29*(1+I12)) | J29: =(I29*(1+J12)) | K29: =(J29*(1+K12)) | L29: =(K29*(1+L12)) | M29: =(L29*(1+M12)) | N29: =(M29*(1+N12)) | O29: =(N29*(1+O12)) | ... AD29: =(AC29*(1+AD12))
A30: Cost of revenue | B30: cogs | H30: =(H29*(1-H13)) | I30: =(I29*(1-I13)) | J30: =(J29*(1-J13)) | K30: =(K29*(1-K13)) | L30: =(L29*(1-L13)) | M30: =(M29*(1-M13)) | N30: =(N29*(1-N13)) | O30: =(O29*(1-O13)) | ... AD30: =(AD29*(1-AD13))
A31: Gross profit | B31: gross_profit | H31: =(H29-H30) | I31: =(I29-I30) | J31: =(J29-J30) | K31: =(K29-K30) | L31: =(L29-L30) | M31: =(M29-M30) | N31: =(N29-N30) | O31: =(O29-O30) | ... AD31: =(AD29-AD30)
A32: SG&A and other opex | B32: opex | H32: =(H29*H14) | I32: =(I29*I14) | J32: =(J29*J14) | K32: =(K29*K14) | L32: =(L29*L14) | M32: =(M29*M14) | N32: =(N29*N14) | O32: =(O29*O14) | ... AD32: =(AD29*AD14)
A33: EBIT | B33: ebit | D33: 427.293 | E33: 442.686 | F33: 441.195 | G33: 432.968 | H33: =(H31-H32) | I33: =(I31-I32) | J33: =(J31-J32) | K33: =(K31-K32) | L33: =(L31-L32) | M33: =(M31-M32) | N33: =(N31-N32) | O33: =(O31-O32) | ... AD33: =(AD31-AD32)
A34: Depreciation & amortisation | B34: da | D34: 68.224 | E34: 73.961 | F34: 82.756 | G34: 93.449 | H34: =(H29*H15) | I34: =(I29*I15) | J34: =(J29*J15) | K34: =(K29*K15) | L34: =(L29*L15) | M34: =(M29*M15) | N34: =(N29*N15) | O34: =(O29*O15) | ... AD34: =(AD29*AD15)
A35: EBITDA | B35: ebitda | D35: 495.517 | E35: 516.647 | F35: 523.951 | G35: 526.417 | H35: =(H33+H34) | I35: =(I33+I34) | J35: =(J33+J34) | K35: =(K33+K34) | L35: =(L33+L34) | M35: =(M33+M34) | N35: =(N33+N34) | O35: =(O33+O34) | ... AD35: =(AD33+AD34)
A36: Interest expense | B36: interest_expense | D36: 82.744 | E36: 131.003 | F36: 129.932 | G36: 118.812 | H36: =(G56*$C$19) | I36: =(H56*$C$19) | J36: =(I56*$C$19) | K36: =(J56*$C$19) | L36: =(K56*$C$19) | M36: =(L56*$C$19) | N36: =(M56*$C$19) | O36: =(N56*$C$19) | ... AD36: =(AC56*$C$19)
A37: Interest income | B37: interest_income | D37: 2.886 | E37: 11.399 | F37: 15.397 | G37: 11.892 | H37: =(G55*$C$20) | I37: =(H55*$C$20) | J37: =(I55*$C$20) | K37: =(J55*$C$20) | L37: =(K55*$C$20) | M37: =(L55*$C$20) | N37: =(M55*$C$20) | O37: =(N55*$C$20) | ... AD37: =(AC55*$C$20)
A38: Other non-operating | B38: other_nonop | D38: -27.871 | E38: -31.661 | F38: -28.564 | G38: -20.294 | H38: =H22 | I38: =I22 | J38: =J22 | K38: =K22 | L38: =L22 | M38: =M22 | N38: =N22 | O38: =O22 | ... AD38: =AD22
A39: Profit before tax | B39: pbt | D39: 319.564 | E39: 291.421 | F39: 298.096 | G39: 305.754 | H39: =(((H33-H36)+H37)+H38) | I39: =(((I33-I36)+I37)+I38) | J39: =(((J33-J36)+J37)+J38) | K39: =(((K33-K36)+K37)+K38) | L39: =(((L33-L36)+L37)+L38) | M39: =(((M33-M36)+M37)+M38) | N39: =(((N33-N36)+N37)+N38) | O39: =(((O33-O36)+O37)+O38) | ... AD39: =(((AD33-AD36)+AD37)+AD38)
A40: Tax | B40: tax | D40: 147.004 | E40: 146.152 | F40: 143.013 | G40: 140.617 | H40: =(MAX(H39,0)*H18) | I40: =(MAX(I39,0)*I18) | J40: =(MAX(J39,0)*J18) | K40: =(MAX(K39,0)*K18) | L40: =(MAX(L39,0)*L18) | M40: =(MAX(M39,0)*M18) | N40: =(MAX(N39,0)*N18) | O40: =(MAX(O39,0)*O18) | ... AD40: =(MAX(AD39,0)*AD18)
A41: Net profit (incl. minorities) | B41: np | D41: 172.56 | E41: 145.269 | F41: 155.083 | G41: 165 | H41: =(H39-H40) | I41: =(I39-I40) | J41: =(J39-J40) | K41: =(K39-K40) | L41: =(L39-L40) | M41: =(M39-M40) | N41: =(N39-N40) | O41: =(O39-O40) | ... AD41: =(AD39-AD40)
A42: Minority interests | B42: minority | D42: 81.434 | E42: 37.852 | F42: 32.975 | G42: 32.939 | H42: =(H41*H23) | I42: =(I41*I23) | J42: =(J41*J23) | K42: =(K41*K23) | L42: =(L41*L23) | M42: =(M41*M23) | N42: =(N41*N23) | O42: =(O41*O23) | ... AD42: =(AD41*AD23)
A43: Net profit to parent | B43: np_parent | D43: 91.126 | E43: 107.417 | F43: 122.108 | G43: 132.198 | H43: =(H41-H42) | I43: =(I41-I42) | J43: =(J41-J42) | K43: =(K41-K42) | L43: =(L41-L42) | M43: =(M41-M42) | N43: =(N41-N42) | O43: =(O41-O42) | ... AD43: =(AD41-AD42)
A44: Shares outstanding (m) | B44: shares | D44: 133786.22 | E44: 133786.22 | F44: 133786.22 | G44: 133786.22 | H44: =(G44*(1+H25)) | I44: =(H44*(1+I25)) | J44: =(I44*(1+J25)) | K44: =(J44*(1+K25)) | L44: =(K44*(1+L25)) | M44: =(L44*(1+M25)) | N44: =(M44*(1+N25)) | O44: =(N44*(1+O25)) | ... AD44: =(AC44*(1+AD25))
...

Sheet CDIA
A1: PT Chandra Daya Investasi TBK. (CDIA.JK) — Power producers & utilities
A2: Units: USD m; per-share in USD unless marked IDR. Model asof 2026-10-29 · data 2026-10-27
A4: Line | C4: Scalar | D4: FY2023A | E4: FY2024A | F4: FY2025A | G4: FY2026E | H4: FY2027E | I4: FY2028E | J4: FY2029E | K4: FY2030E | L4: FY2031E | M4: FY2032E | N4: FY2033E | O4: FY2034E | P4: FY2035E | Q4: FY2036E | R4: FY2037E | S4: FY2038E | T4: FY2039E | U4: FY2040E | V4: FY2041E | W4: FY2042E | X4: FY2043E | Y4: FY2044E | Z4: FY2045E
A6: PARAMETERS
A7: horizon | C7: 20
A8: ps_factor | C8: 1
A9: vp_factor | C9: 1
A11: INPUTS (company assumptions)
A12: Revenue growth | B12: a.revenue_growth | G12: 0.16 | H12: 0.12 | I12: 0.1 | J12: 0.09 | K12: 0.08 | L12: 0.05 | M12: 0.05 | N12: 0.05 | O12: 0.05 | P12: 0.05 | Q12: 0.05 | R12: 0.05 | S12: 0.05 | T12: 0.05 | U12: 0.05 | V12: 0.05 | W12: 0.05 | X12: 0.05 | Y12: 0.05 | Z12: 0.05
A13: Gross margin at base input costs | B13: a.gross_margin | G13: 0.235 | H13: 0.235 | I13: 0.235 | J13: 0.235 | K13: 0.235 | L13: 0.235 | M13: 0.235 | N13: 0.235 | O13: 0.235 | P13: 0.235 | Q13: 0.235 | R13: 0.235 | S13: 0.235 | T13: 0.235 | U13: 0.235 | V13: 0.235 | W13: 0.235 | X13: 0.235 | Y13: 0.235 | Z13: 0.235
A14: SG&A / revenue | B14: a.opex_pct | G14: 0.1 | H14: 0.098 | I14: 0.095 | J14: 0.095 | K14: 0.095 | L14: 0.095 | M14: 0.095 | N14: 0.095 | O14: 0.095 | P14: 0.095 | Q14: 0.095 | R14: 0.095 | S14: 0.095 | T14: 0.095 | U14: 0.095 | V14: 0.095 | W14: 0.095 | X14: 0.095 | Y14: 0.095 | Z14: 0.095
A15: D&A / revenue | B15: a.da_pct | G15: 0.115 | H15: 0.115 | I15: 0.115 | J15: 0.115 | K15: 0.115 | L15: 0.115 | M15: 0.115 | N15: 0.115 | O15: 0.115 | P15: 0.115 | Q15: 0.115 | R15: 0.115 | S15: 0.115 | T15: 0.115 | U15: 0.115 | V15: 0.115 | W15: 0.115 | X15: 0.115 | Y15: 0.115 | Z15: 0.115
A16: Capex / revenue | B16: a.capex_pct | G16: 1.05 | H16: 0.75 | I16: 0.5 | J16: 0.35 | K16: 0.22 | L16: 0.135 | M16: 0.135 | N16: 0.135 | O16: 0.135 | P16: 0.135 | Q16: 0.135 | R16: 0.135 | S16: 0.135 | T16: 0.135 | U16: 0.135 | V16: 0.135 | W16: 0.135 | X16: 0.135 | Y16: 0.135 | Z16: 0.135
A17: Operating working capital / revenue | B17: a.nwc_pct | G17: 0.05 | H17: 0.05 | I17: 0.05 | J17: 0.05 | K17: 0.05 | L17: 0.05 | M17: 0.05 | N17: 0.05 | O17: 0.05 | P17: 0.05 | Q17: 0.05 | R17: 0.05 | S17: 0.05 | T17: 0.05 | U17: 0.05 | V17: 0.05 | W17: 0.05 | X17: 0.05 | Y17: 0.05 | Z17: 0.05
A18: Effective tax rate | B18: a.tax_rate | G18: 0.22 | H18: 0.22 | I18: 0.22 | J18: 0.22 | K18: 0.22 | L18: 0.22 | M18: 0.22 | N18: 0.22 | O18: 0.22 | P18: 0.22 | Q18: 0.22 | R18: 0.22 | S18: 0.22 | T18: 0.22 | U18: 0.22 | V18: 0.22 | W18: 0.22 | X18: 0.22 | Y18: 0.22 | Z18: 0.22
A19: Cost of debt (on opening debt) | B19: a.cost_of_debt | C19: 0.07
A20: Yield on opening cash | B20: a.cash_yield | C20: 0.045
A21: Net new borrowing | B21: a.net_borrowing | G21: 205.4 | H21: 100 | I21: 50 | J21: 0 | K21: 0 | L21: 0 | M21: 0 | N21: 0 | O21: 0 | P21: 0 | Q21: 0 | R21: 0 | S21: 0 | T21: 0 | U21: 0 | V21: 0 | W21: 0 | X21: 0 | Y21: 0 | Z21: 0
A22: Other non-operating items | B22: a.other_nonop | G22: 30 | H22: 30 | I22: 30 | J22: 30 | K22: 30 | L22: 25.5 | M22: 26.01 | N22: 26.5302 | O22: 27.060804 | P22: 27.60202 | Q22: 28.15406 | R22: 28.717142 | S22: 29.291485 | T22: 29.877314 | U22: 30.47486 | V22: 31.084358 | W22: 31.706045 | X22: 32.340166 | Y22: 32.986969 | Z22: 33.646708
A23: Minorities' share of net profit | B23: a.minority_pct | G23: 0.055 | H23: 0.055 | I23: 0.055 | J23: 0.055 | K23: 0.055 | L23: 0.055 | M23: 0.055 | N23: 0.055 | O23: 0.055 | P23: 0.055 | Q23: 0.055 | R23: 0.055 | S23: 0.055 | T23: 0.055 | U23: 0.055 | V23: 0.055 | W23: 0.055 | X23: 0.055 | Y23: 0.055 | Z23: 0.055
A24: Dividend payout | B24: a.payout | G24: 0.25 | H24: 0.25 | I24: 0.25 | J24: 0.25 | K24: 0.25 | L24: 0.25 | M24: 0.25 | N24: 0.25 | O24: 0.25 | P24: 0.25 | Q24: 0.25 | R24: 0.25 | S24: 0.25 | T24: 0.25 | U24: 0.25 | V24: 0.25 | W24: 0.25 | X24: 0.25 | Y24: 0.25 | Z24: 0.25
A25: Change in share count | B25: a.share_change | G25: 0 | H25: 0 | I25: 0 | J25: 0 | K25: 0 | L25: 0 | M25: 0 | N25: 0 | O25: 0 | P25: 0 | Q25: 0 | R25: 0 | S25: 0 | T25: 0 | U25: 0 | V25: 0 | W25: 0 | X25: 0 | Y25: 0 | Z25: 0
A26: Terminal growth (DCF) | B26: a.terminal_growth | C26: 0.02
A28: MODEL
A29: Revenue | B29: revenue | E29: 102.25477 | F29: 148.03259 | G29: =(F29*(1+G12)) | H29: =(G29*(1+H12)) | I29: =(H29*(1+I12)) | J29: =(I29*(1+J12)) | K29: =(J29*(1+K12)) | L29: =(K29*(1+L12)) | M29: =(L29*(1+M12)) | N29: =(M29*(1+N12)) | ... Z29: =(Y29*(1+Z12))
A30: Cost of revenue | B30: cogs | E30: 91.789624 | F30: 112.64047 | G30: =(G29*(1-G13)) | H30: =(H29*(1-H13)) | I30: =(I29*(1-I13)) | J30: =(J29*(1-J13)) | K30: =(K29*(1-K13)) | L30: =(L29*(1-L13)) | M30: =(M29*(1-M13)) | N30: =(N29*(1-N13)) | ... Z30: =(Z29*(1-Z13))
A31: Gross profit | B31: gross_profit | E31: 10.465141 | F31: 35.392126 | G31: =(G29-G30) | H31: =(H29-H30) | I31: =(I29-I30) | J31: =(J29-J30) | K31: =(K29-K30) | L31: =(L29-L30) | M31: =(M29-M30) | N31: =(N29-N30) | ... Z31: =(Z29-Z30)
A32: SG&A and other opex | B32: opex | E32: 8.248573 | F32: 13.087288 | G32: =(G29*G14) | H32: =(H29*H14) | I32: =(I29*I14) | J32: =(J29*J14) | K32: =(K29*K14) | L32: =(L29*L14) | M32: =(M29*M14) | N32: =(N29*N14) | ... Z32: =(Z29*Z14)
A33: EBIT | B33: ebit | E33: 2.216568 | F33: 22.304838 | G33: =(G31-G32) | H33: =(H31-H32) | I33: =(I31-I32) | J33: =(J31-J32) | K33: =(K31-K32) | L33: =(L31-L32) | M33: =(M31-M32) | N33: =(N31-N32) | ... Z33: =(Z31-Z32)
A34: Depreciation & amortisation | B34: da | E34: 8.582806 | F34: 9.618618 | G34: =(G29*G15) | H34: =(H29*H15) | I34: =(I29*I15) | J34: =(J29*J15) | K34: =(K29*K15) | L34: =(L29*L15) | M34: =(M29*M15) | N34: =(N29*N15) | ... Z34: =(Z29*Z15)
A35: EBITDA | B35: ebitda | E35: 10.799374 | F35: 31.923456 | G35: =(G33+G34) | H35: =(H33+H34) | I35: =(I33+I34) | J35: =(J33+J34) | K35: =(K33+K34) | L35: =(L33+L34) | M35: =(M33+M34) | N35: =(N33+N34) | ... Z35: =(Z33+Z34)
A36: Interest expense | B36: interest_expense | E36: 18.489132 | F36: 28.251149 | G36: =(F56*$C$19) | H36: =(G56*$C$19) | I36: =(H56*$C$19) | J36: =(I56*$C$19) | K36: =(J56*$C$19) | L36: =(K56*$C$19) | M36: =(L56*$C$19) | N36: =(M56*$C$19) | ... Z36: =(Y56*$C$19)
A37: Interest income | B37: interest_income | E37: 20.505104 | F37: 24.330789 | G37: =(F55*$C$20) | H37: =(G55*$C$20) | I37: =(H55*$C$20) | J37: =(I55*$C$20) | K37: =(J55*$C$20) | L37: =(K55*$C$20) | M37: =(L55*$C$20) | N37: =(M55*$C$20) | ... Z37: =(Y55*$C$20)
A38: Other non-operating | B38: other_nonop | E38: 29.984554 | F38: 113.67811 | G38: =G22 | H38: =H22 | I38: =I22 | J38: =J22 | K38: =K22 | L38: =L22 | M38: =M22 | N38: =N22 | ... Z38: =Z22
A39: Profit before tax | B39: pbt | E39: 34.217094 | F39: 132.06259 | G39: =(((G33-G36)+G37)+G38) | H39: =(((H33-H36)+H37)+H38) | I39: =(((I33-I36)+I37)+I38) | J39: =(((J33-J36)+J37)+J38) | K39: =(((K33-K36)+K37)+K38) | L39: =(((L33-L36)+L37)+L38) | M39: =(((M33-M36)+M37)+M38) | N39: =(((N33-N36)+N37)+N38) | ... Z39: =(((Z33-Z36)+Z37)+Z38)
A40: Tax | B40: tax | E40: 0.737715 | F40: 4.273749 | G40: =(MAX(G39,0)*G18) | H40: =(MAX(H39,0)*H18) | I40: =(MAX(I39,0)*I18) | J40: =(MAX(J39,0)*J18) | K40: =(MAX(K39,0)*K18) | L40: =(MAX(L39,0)*L18) | M40: =(MAX(M39,0)*M18) | N40: =(MAX(N39,0)*N18) | ... Z40: =(MAX(Z39,0)*Z18)
A41: Net profit (incl. minorities) | B41: np | E41: 33.479379 | F41: 127.78884 | G41: =(G39-G40) | H41: =(H39-H40) | I41: =(I39-I40) | J41: =(J39-J40) | K41: =(K39-K40) | L41: =(L39-L40) | M41: =(M39-M40) | N41: =(N39-N40) | ... Z41: =(Z39-Z40)
A42: Minority interests | B42: minority | E42: 2.056654 | F42: 6.736277 | G42: =(G41*G23) | H42: =(H41*H23) | I42: =(I41*I23) | J42: =(J41*J23) | K42: =(K41*K23) | L42: =(L41*L23) | M42: =(M41*M23) | N42: =(N41*N23) | ... Z42: =(Z41*Z23)
A43: Net profit to parent | B43: np_parent | E43: 31.422725 | F43: 121.05256 | G43: =(G41-G42) | H43: =(H41-H42) | I43: =(I41-I42) | J43: =(J41-J42) | K43: =(K41-K42) | L43: =(L41-L42) | M43: =(M41-M42) | N43: =(N41-N42) | ... Z43: =(Z41-Z42)
A44: Shares outstanding (m) | B44: shares | D44: 124829.37 | E44: 124829.37 | F44: 124829.37 | G44: =(F44*(1+G25)) | H44: =(G44*(1+H25)) | I44: =(H44*(1+I25)) | J44: =(I44*(1+J25)) | K44: =(J44*(1+K25)) | L44: =(K44*(1+L25)) | M44: =(L44*(1+M25)) | N44: =(M44*(1+N25)) | ... Z44: =(Y44*(1+Z25))
...
