Workbook

Sheet README
A1: Six South — Gold, copper & base-metal miners industry model
A2: Generated 2026-10-31T18:43:22+07:00 by the coverage engine. The engine (scripts/cov_engine.py) is the source of truth; this workbook is a live rendering of it.
A3: Colour key: blue = input or hard-coded history; black = formula; green = link to another sheet.
A4: Drivers: every deck variable these models read. Change one and every ticker tab and the Comps sheet recalculate (forecasts, cash flows, DCF value, base-case value, target, rating).
A5: Scenario (bear/bull) and sensitivity tables need full model re-runs and are engine values.
A6: Paper fund — research for education and process transparency, not investment advice.
A8: Tickers:
A9: BRMS.JK — PT Bumi Resources Minerals Tbk

Sheet Drivers
A1: Driver decks (state/drivers) — edit a blue cell to flow it through every ticker tab
A3: Variable | B3: Key | C3: Unit / status | D3: FY2022A | E3: FY2023A | F3: FY2024A | G3: FY2025A | H3: FY2026E | I3: FY2027E | J3: FY2028E | K3: FY2029E | L3: FY2030E | M3: FY2031E | N3: FY2032E | O3: FY2033E | P3: FY2034E | Q3: FY2035E | R3: FY2036E | S3: FY2037E | T3: FY2038E | U3: FY2039E | V3: FY2040E | W3: FY2041E | X3: FY2042E | Y3: FY2043E | Z3: FY2044E | AA3: FY2045E | AB3: FY2046E | AC3: FY2047E | AD3: FY2048E | AE3: FY2049E | AF3: FY2050E
A4: IDR per USD | B4: m.usd_idr | C4: IDR/USD · reviewed | D4: 14843.177 | E4: 15228.8 | F4: 15846.238 | G4: 16448.093 | H4: 17570 | I4: 18350 | J4: 18600 | K4: 18850 | L4: 19093.137 | M4: 19186.731 | N4: 19280.784 | O4: 19375.297 | P4: 19470.274 | Q4: 19565.717 | R4: 19661.627 | S4: 19758.008 | T4: 19854.861 | U4: 19952.188 | V4: 20049.993 | W4: 20148.278 | X4: 20247.044 | Y4: 20346.294 | Z4: 20446.031 | AA4: 20546.256 | AB4: 20646.973 | AC4: 20748.184 | AD4: 20849.891 | AE4: 20952.096 | AF4: 21054.802
A5: Gold | B5: d.metals.gold | C5: USD/oz · reviewed | D5: 1805.1916 | E5: 1954.5195 | F5: 2404.7131 | G5: 3466.0889 | H5: 4493.75 | I5: 4300 | J5: 4300 | K5: 4300 | L5: 4386 | M5: 4473.72 | N5: 4563.1944 | O5: 4654.4583 | P5: 4747.5475 | Q5: 4842.4984 | R5: 4939.3484 | S5: 5038.1353 | T5: 5138.898 | U5: 5241.676 | V5: 5346.5095 | W5: 5453.4397 | X5: 5562.5085 | Y5: 5673.7587 | Z5: 5787.2339 | AA5: 5902.9785 | AB5: 6021.0381 | AC5: 6141.4589 | AD5: 6264.288 | AE5: 6389.5738 | AF5: 6517.3653
A6: Brent crude | B6: d.oil.brent | C6: USD/bbl · reviewed | D6: 98.9663 | E6: 82.1904 | F6: 79.8213 | G6: 68.1015 | H6: 96 | I6: 84 | J6: 80 | K6: 78 | L6: 76.5 | M6: 78.03 | N6: 79.5906 | O6: 81.182412 | P6: 82.80606 | Q6: 84.462181 | R6: 86.151425 | S6: 87.874454 | T6: 89.631943 | U6: 91.424581 | V6: 93.253073 | W6: 95.118135 | X6: 97.020497 | Y6: 98.960907 | Z6: 100.94013 | AA6: 102.95893 | AB6: 105.01811 | AC6: 107.11847 | AD6: 109.26084 | AE6: 111.44605 | AF6: 113.67498
A8: Cost-of-capital scalars (macro deck)
A9: 10-year Indonesian government bond yield (IDR) | B9: m.rf_idr | C9: 0.0745 | D9: investor.id — "Yield SUN 7,45%, Saatnya Borong atau Tunggu Lebih Tinggi?" (25 Okt 2026 20:58 WIB; deck source S3); corroborated by kalderanews S1 (10Y SUN 7.41%
A10: 10-year US Treasury yield | B10: m.rf_usd | C10: 0.04929 | D10: Yahoo Finance ^TNX (US 10-year Treasury yield)
A11: Indonesia sovereign default spread (Damodaran) | B11: m.default_spread_id | C11: 0.0162 | D11: Damodaran country risk premiums (https://pages.stern.nyu.edu/~adamodar/New_Home_Page/datafile/ctryprem.html), page dated January 5, 2026, read 2026-10-31
A12: Mature-market equity risk premium (Damodaran) | B12: m.erp_mature | C12: 0.0423 | D12: Damodaran country risk premiums (https://pages.stern.nyu.edu/~adamodar/New_Home_Page/datafile/ctryprem.html), page dated January 5, 2026, read 2026-10-31
A13: Indonesia country risk premium (Damodaran) | B13: m.crp_id | C13: 0.0246 | D13: Damodaran country risk premiums (https://pages.stern.nyu.edu/~adamodar/New_Home_Page/datafile/ctryprem.html), page dated January 5, 2026, read 2026-10-31
A14: House pre-tax corporate debt spread over the risk-free | B14: m.debt_spread_corp | C14: 0.02 | D14: SEED house assumption pending the macro desk: 200 bp over the risk-free rate for an average IDX corporate borrower
A15: Indonesia statutory corporate income tax rate | B15: m.tax_rate_id | C15: 0.22 | D15: Law 7/2021 on Harmonisation of Tax Regulations (UU HPP): 22% corporate income tax from fiscal 2022

Sheet Comps
A1: Ticker | B1: Company | C1: Rating | D1: Target (IDR) | E1: Price (IDR) | F1: Exp. 12m TR | G1: Value today | H1: P/E FY+0 | I1: EV/EBITDA FY+0 | J1: Div. yield FY+0
A2: BRMS.JK | B2: PT Bumi Resources Minerals Tbk | C2: ='BRMS'!$C$160 | D2: ='BRMS'!$C$158 | E2: ='BRMS'!$C$102 | F2: ='BRMS'!$C$159 | G2: ='BRMS'!$C$139 | H2: 45.126904 | I2: 23.790173 | J2: 0

Sheet BRMS
A1: PT Bumi Resources Minerals Tbk (BRMS.JK) — Gold, copper & base-metal miners
A2: Units: USD m; per-share in USD unless marked IDR. Model asof 2026-10-31 · data 2026-10-30
A4: Line | C4: Scalar | D4: FY2022A | E4: FY2023A | F4: FY2024A | G4: FY2025A | H4: FY2026E | I4: FY2027E | J4: FY2028E | K4: FY2029E | L4: FY2030E | M4: FY2031E | N4: FY2032E | O4: FY2033E | P4: FY2034E | Q4: FY2035E | R4: FY2036E | S4: FY2037E | T4: FY2038E | U4: FY2039E | V4: FY2040E | W4: FY2041E | X4: FY2042E | Y4: FY2043E | Z4: FY2044E | AA4: FY2045E | AB4: FY2046E | AC4: FY2047E | AD4: FY2048E | AE4: FY2049E | AF4: FY2050E
A6: PARAMETERS
A7: horizon | C7: 25
A8: ps_factor | C8: 1
A9: reserves | C9: 3500
A10: unit_factor | C10: 0.001
A11: vp_factor | C11: 1
A13: INPUTS (company assumptions)
A14: Sales volume plan | B14: a.volume | H14: 54.6 | I14: 80 | J14: 140 | K14: 165 | L14: 165 | M14: 165 | N14: 165 | O14: 165 | P14: 165 | Q14: 165 | R14: 165 | S14: 165 | T14: 165 | U14: 165 | V14: 165 | W14: 165 | X14: 165 | Y14: 165 | Z14: 165 | AA14: 165 | AB14: 165 | AC14: 165 | AD14: 165 | AE14: 165 | AF14: 165
A15: Realised price / benchmark | B15: a.realisation | H15: 0.9726 | I15: 0.9726 | J15: 0.9726 | K15: 0.9726 | L15: 0.9726 | M15: 0.9726 | N15: 0.9726 | O15: 0.9726 | P15: 0.9726 | Q15: 0.9726 | R15: 0.9726 | S15: 0.9726 | T15: 0.9726 | U15: 0.9726 | V15: 0.9726 | W15: 0.9726 | X15: 0.9726 | Y15: 0.9726 | Z15: 0.9726 | AA15: 0.9726 | AB15: 0.9726 | AC15: 0.9726 | AD15: 0.9726 | AE15: 0.9726 | AF15: 0.9726
A16: Share of volume under a price cap (e.g. DMO) | B16: a.capped_share | H16: 0 | I16: 0 | J16: 0 | K16: 0 | L16: 0 | M16: 0 | N16: 0 | O16: 0 | P16: 0 | Q16: 0 | R16: 0 | S16: 0 | T16: 0 | U16: 0 | V16: 0 | W16: 0 | X16: 0 | Y16: 0 | Z16: 0 | AA16: 0 | AB16: 0 | AC16: 0 | AD16: 0 | AE16: 0 | AF16: 0
A17: Strip ratio (bcm per tonne) or cost-intensity factor | B17: a.strip_ratio | H17: 1 | I17: 1 | J17: 1 | K17: 1 | L17: 1 | M17: 1 | N17: 1 | O17: 1 | P17: 1 | Q17: 1 | R17: 1 | S17: 1 | T17: 1 | U17: 1 | V17: 1 | W17: 1 | X17: 1 | Y17: 1 | Z17: 1 | AA17: 1 | AB17: 1 | AC17: 1 | AD17: 1 | AE17: 1 | AF17: 1
A18: Mining cost per bcm (or per unit when intensity is 1) | B18: a.cost_per_bcm | H18: 503.4 | I18: 503.4 | J18: 503.4 | K18: 503.4 | L18: 503.4 | M18: 513.468 | N18: 523.73736 | O18: 534.21211 | P18: 544.89635 | Q18: 555.79428 | R18: 566.91016 | S18: 578.24837 | T18: 589.81333 | U18: 601.6096 | V18: 613.64179 | W18: 625.91463 | X18: 638.43292 | Y18: 651.20158 | Z18: 664.22561 | AA18: 677.51012 | AB18: 691.06032 | AC18: 704.88153 | AD18: 718.97916 | AE18: 733.35874 | AF18: 748.02592
A19: Fuel share of mining cost | B19: a.fuel_share | C19: 0.3
A20: Other cash cost per unit (haul, barge, process) | B20: a.other_cost_unit | H20: 425.8 | I20: 425.8 | J20: 425.8 | K20: 425.8 | L20: 425.8 | M20: 434.316 | N20: 443.00232 | O20: 451.86237 | P20: 460.89961 | Q20: 470.11761 | R20: 479.51996 | S20: 489.11036 | T20: 498.89256 | U20: 508.87042 | V20: 519.04782 | W20: 529.42878 | X20: 540.01736 | Y20: 550.8177 | Z20: 561.83406 | AA20: 573.07074 | AB20: 584.53215 | AC20: 596.2228 | AD20: 608.14725 | AE20: 620.3102 | AF20: 632.7164
A21: Royalty rate (flat regimes) | B21: a.royalty_rate | H21: 0.16 | I21: 0.16 | J21: 0.16 | K21: 0.16 | L21: 0.16 | M21: 0.16 | N21: 0.16 | O21: 0.16 | P21: 0.16 | Q21: 0.16 | R21: 0.16 | S21: 0.16 | T21: 0.16 | U21: 0.16 | V21: 0.16 | W21: 0.16 | X21: 0.16 | Y21: 0.16 | Z21: 0.16 | AA21: 0.16 | AB21: 0.16 | AC21: 0.16 | AD21: 0.16 | AE21: 0.16 | AF21: 0.16
A22: Other revenue | B22: a.other_revenue | H22: 7 | I22: 7 | J22: 7 | K22: 7 | L22: 7 | M22: 7.14 | N22: 7.2828 | O22: 7.428456 | P22: 7.5770251 | Q22: 7.7285656 | R22: 7.8831369 | S22: 8.0407997 | T22: 8.2016157 | U22: 8.365648 | V22: 8.5329609 | W22: 8.7036202 | X22: 8.8776926 | Y22: 9.0552464 | Z22: 9.2363513 | AA22: 9.4210784 | AB22: 9.6094999 | AC22: 9.8016899 | AD22: 9.9977237 | AE22: 10.197678 | AF22: 10.401632
A23: Gross margin on other revenue | B23: a.other_margin | C23: 1
A24: D&A per unit (reporting currency) | B24: a.da_unit | H24: 126.1 | I24: 126.1 | J24: 126.1 | K24: 126.1 | L24: 126.1 | M24: 128.622 | N24: 131.19444 | O24: 133.81833 | P24: 136.4947 | Q24: 139.22459 | R24: 142.00908 | S24: 144.84926 | T24: 147.74625 | U24: 150.70117 | V24: 153.7152 | W24: 156.7895 | X24: 159.92529 | Y24: 163.1238 | Z24: 166.38627 | AA24: 169.714 | AB24: 173.10828 | AC24: 176.57044 | AD24: 180.10185 | AE24: 183.70389 | AF24: 187.37797
A25: Sustaining capex per unit (reporting currency) | B25: a.capex_unit | H25: 130 | I25: 130 | J25: 130 | K25: 130 | L25: 130 | M25: 132.6 | N25: 135.252 | O25: 137.95704 | P25: 140.71618 | Q25: 143.5305 | R25: 146.40111 | S25: 149.32914 | T25: 152.31572 | U25: 155.36203 | V25: 158.46927 | W25: 161.63866 | X25: 164.87143 | Y25: 168.16886 | Z25: 171.53224 | AA25: 174.96288 | AB25: 178.46214 | AC25: 182.03138 | AD25: 185.67201 | AE25: 189.38545 | AF25: 193.17316
A26: Other capex (expansion projects) | B26: a.capex_other | H26: 150 | I26: 200 | J26: 75 | K26: 0 | L26: 0 | M26: 0 | N26: 0 | O26: 0 | P26: 0 | Q26: 0 | R26: 0 | S26: 0 | T26: 0 | U26: 0 | V26: 0 | W26: 0 | X26: 0 | Y26: 0 | Z26: 0 | AA26: 0 | AB26: 0 | AC26: 0 | AD26: 0 | AE26: 0 | AF26: 0
A27: Operating working capital / revenue | B27: a.nwc_pct | H27: 0.04 | I27: 0.04 | J27: 0.04 | K27: 0.04 | L27: 0.04 | M27: 0.04 | N27: 0.04 | O27: 0.04 | P27: 0.04 | Q27: 0.04 | R27: 0.04 | S27: 0.04 | T27: 0.04 | U27: 0.04 | V27: 0.04 | W27: 0.04 | X27: 0.04 | Y27: 0.04 | Z27: 0.04 | AA27: 0.04 | AB27: 0.04 | AC27: 0.04 | AD27: 0.04 | AE27: 0.04 | AF27: 0.04
A28: Effective tax rate | B28: a.tax_rate | H28: 0.244 | I28: 0.244 | J28: 0.244 | K28: 0.244 | L28: 0.244 | M28: 0.244 | N28: 0.244 | O28: 0.244 | P28: 0.244 | Q28: 0.244 | R28: 0.244 | S28: 0.244 | T28: 0.244 | U28: 0.244 | V28: 0.244 | W28: 0.244 | X28: 0.244 | Y28: 0.244 | Z28: 0.244 | AA28: 0.244 | AB28: 0.244 | AC28: 0.244 | AD28: 0.244 | AE28: 0.244 | AF28: 0.244
A29: Cost of debt (on opening debt) | B29: a.cost_of_debt | C29: 0.12
A30: Yield on opening cash | B30: a.cash_yield | C30: 0.05
A31: Net new borrowing | B31: a.net_borrowing | H31: 117 | I31: 80 | J31: 30 | K31: 0 | L31: 0 | M31: 0 | N31: 0 | O31: 0 | P31: 0 | Q31: 0 | R31: 0 | S31: 0 | T31: 0 | U31: 0 | V31: 0 | W31: 0 | X31: 0 | Y31: 0 | Z31: 0 | AA31: 0 | AB31: 0 | AC31: 0 | AD31: 0 | AE31: 0 | AF31: 0
A32: Other non-operating items | B32: a.other_nonop | H32: 0 | I32: 0 | J32: 0 | K32: 0 | L32: 0 | M32: 0 | N32: 0 | O32: 0 | P32: 0 | Q32: 0 | R32: 0 | S32: 0 | T32: 0 | U32: 0 | V32: 0 | W32: 0 | X32: 0 | Y32: 0 | Z32: 0 | AA32: 0 | AB32: 0 | AC32: 0 | AD32: 0 | AE32: 0 | AF32: 0
A33: Minorities' share of net profit | B33: a.minority_pct | H33: 0.0164 | I33: 0.0164 | J33: 0.0164 | K33: 0.0164 | L33: 0.0164 | M33: 0.0164 | N33: 0.0164 | O33: 0.0164 | P33: 0.0164 | Q33: 0.0164 | R33: 0.0164 | S33: 0.0164 | T33: 0.0164 | U33: 0.0164 | V33: 0.0164 | W33: 0.0164 | X33: 0.0164 | Y33: 0.0164 | Z33: 0.0164 | AA33: 0.0164 | AB33: 0.0164 | AC33: 0.0164 | AD33: 0.0164 | AE33: 0.0164 | AF33: 0.0164
A34: Dividend payout | B34: a.payout | H34: 0 | I34: 0 | J34: 0 | K34: 0 | L34: 0 | M34: 0 | N34: 0 | O34: 0 | P34: 0 | Q34: 0 | R34: 0 | S34: 0 | T34: 0 | U34: 0 | V34: 0 | W34: 0 | X34: 0 | Y34: 0 | Z34: 0 | AA34: 0 | AB34: 0 | AC34: 0 | AD34: 0 | AE34: 0 | AF34: 0
A35: Change in share count | B35: a.share_change | H35: 0 | I35: 0 | J35: 0 | K35: 0 | L35: 0 | M35: 0 | N35: 0 | O35: 0 | P35: 0 | Q35: 0 | R35: 0 | S35: 0 | T35: 0 | U35: 0 | V35: 0 | W35: 0 | X35: 0 | Y35: 0 | Z35: 0 | AA35: 0 | AB35: 0 | AC35: 0 | AD35: 0 | AE35: 0 | AF35: 0
A36: Terminal growth (DCF) | B36: a.terminal_growth | C36: 0.02
A37: SG&A / revenue | B37: a.opex_pct | H37: 0.189 | I37: 0.189 | J37: 0.189 | K37: 0.189 | L37: 0.189 | M37: 0.189 | N37: 0.189 | O37: 0.189 | P37: 0.189 | Q37: 0.189 | R37: 0.189 | S37: 0.189 | T37: 0.189 | U37: 0.189 | V37: 0.189 | W37: 0.189 | X37: 0.189 | Y37: 0.189 | Z37: 0.189 | AA37: 0.189 | AB37: 0.189 | AC37: 0.189 | AD37: 0.189 | AE37: 0.189 | AF37: 0.189
A39: MODEL
A40: Reserves remaining (close) | B40: reserves | G40: 3500 | H40: =MAX((G40-H41),0) | I40: =MAX((H40-I41),0) | J40: =MAX((I40-J41),0) | K40: =MAX((J40-K41),0) | L40: =MAX((K40-L41),0) | M40: =MAX((L40-M41),0) | N40: =MAX((M40-N41),0) | O40: =MAX((N40-O41),0) | ... AF40: =MAX((AE40-AF41),0)
A41: Sales volume | B41: volume | F41: 64.983 | G41: 71.886 | H41: =IF(($C$9>0),MIN(H14,MAX(G40,0)),H14) | I41: =IF(($C$9>0),MIN(I14,MAX(H40,0)),I14) | J41: =IF(($C$9>0),MIN(J14,MAX(I40,0)),J14) | K41: =IF(($C$9>0),MIN(K14,MAX(J40,0)),K14) | L41: =IF(($C$9>0),MIN(L14,MAX(K40,0)),L14) | M41: =IF(($C$9>0),MIN(M14,MAX(L40,0)),M14) | N41: =IF(($C$9>0),MIN(N14,MAX(M40,0)),N14) | O41: =IF(($C$9>0),MIN(O14,MAX(N40,0)),O14) | ... AF41: =IF(($C$9>0),MIN(AF14,MAX(AE40,0)),AF14)
A42: Benchmark price | B42: benchmark | H42: =Drivers!$H$5 | I42: =Drivers!$I$5 | J42: =Drivers!$J$5 | K42: =Drivers!$K$5 | L42: =Drivers!$L$5 | M42: =Drivers!$M$5 | N42: =Drivers!$N$5 | O42: =Drivers!$O$5 | P42: =Drivers!$P$5 | Q42: =Drivers!$Q$5 | R42: =Drivers!$R$5 | S42: =Drivers!$S$5 | T42: =Drivers!$T$5 | U42: =Drivers!$U$5 | V42: =Drivers!$V$5 | W42: =Drivers!$W$5 | X42: =Drivers!$X$5 | Y42: =Drivers!$Y$5 | Z42: =Drivers!$Z$5 | AA42: =Drivers!$AA$5 | AB42: =Drivers!$AB$5 | AC42: =Drivers!$AC$5 | AD42: =Drivers!$AD$5 | AE42: =Drivers!$AE$5 | AF42: =Drivers!$AF$5
A43: Average selling price | B43: asp | F43: 2442 | G43: 3371 | H43: =(H15*H42) | I43: =(I15*I42) | J43: =(J15*J42) | K43: =(K15*K42) | L43: =(L15*L42) | M43: =(M15*M42) | N43: =(N15*N42) | O43: =(O15*O42) | ... AF43: =(AF15*AF42)
A44: Realisation vs benchmark | B44: realisation_line | H44: =IF(H42=0,0,H43/H42) | I44: =IF(I42=0,0,I43/I42) | J44: =IF(J42=0,0,J43/J42) | K44: =IF(K42=0,0,K43/K42) | L44: =IF(L42=0,0,L43/L42) | M44: =IF(M42=0,0,M43/M42) | N44: =IF(N42=0,0,N43/N42) | O44: =IF(O42=0,0,O43/O42) | ... AF44: =IF(AF42=0,0,AF43/AF42)
...
